Workbook
Name FirmaName: '01_Stammdaten'!$B$5
Name FirmaStrasse: '01_Stammdaten'!$B$6
Name FirmaPLZ: '01_Stammdaten'!$B$7
Name FirmaOrt: '01_Stammdaten'!$B$8
Name FirmaTel: '01_Stammdaten'!$B$9
Name FirmaMail: '01_Stammdaten'!$B$10
Name FirmaUStId: '01_Stammdaten'!$B$11
Name FirmaStNr: '01_Stammdaten'!$B$12
Name FirmaHRB: '01_Stammdaten'!$B$13
Name FirmaGF: '01_Stammdaten'!$B$14
Name FirmaIBAN: '01_Stammdaten'!$B$15
Name FirmaBIC: '01_Stammdaten'!$B$16
Name FirmaBank: '01_Stammdaten'!$B$17
Name GJ: '01_Stammdaten'!$F$5
Name UStSatz: '01_Stammdaten'!$F$6
Name SkontoPct: '01_Stammdaten'!$F$7
Name SkontoTage: '01_Stammdaten'!$F$8
Name Zahlungsziel: '01_Stammdaten'!$F$9
Name EinbehaltPct: '01_Stammdaten'!$F$10
Name GewaehrJahre: '01_Stammdaten'!$F$11
Name MindestLiq: '01_Stammdaten'!$F$12
Name AnfangsBank: '01_Stammdaten'!$F$13
Name Kreditlinie: '01_Stammdaten'!$F$14
Name SollStunden: '01_Stammdaten'!$F$15
Name VSSatz: '01_Stammdaten'!$F$16
Name AGKPct: '01_Stammdaten'!$F$17
Name WuGPct: '01_Stammdaten'!$F$18
Name BuHaName: '01_Stammdaten'!$F$19
Name lstProjektStatus: '01_Stammdaten'!$A$22:$A$28
Name lstBelegStatus: '01_Stammdaten'!$B$22:$B$27
Name lstAngebotStatus: '01_Stammdaten'!$C$22:$C$26
Name lstProjektArt: '01_Stammdaten'!$D$22:$D$27
Name lstVertrag: '01_Stammdaten'!$E$22:$E$26
Name lstARTyp: '01_Stammdaten'!$F$22:$F$26
Name lstERTyp: '01_Stammdaten'!$G$22:$G$26
Name lstZahlungArt: '01_Stammdaten'!$H$22:$H$23
Name KostenartenGruppe: '01_Stammdaten'!$C$34:$C$43
Name KundenNr: '02_Kunden'!$A$4:$A$400
Name KundenName: '02_Kunden'!$B$4:$B$400
Name LiefNr: '03_Lieferanten'!$A$4:$A$400
Name LiefName: '03_Lieferanten'!$B$4:$B$400
Name PersNr: '04_Personal'!$A$4:$A$400
Name PersName: '04_Personal'!$B$4:$B$400
Name ProjektNr: '05_Projekte'!$A$4:$A$400
Name ProjektName: '05_Projekte'!$B$4:$B$400
Name AngebotNr: '08_Angebote'!$A$4:$A$400
Name StundenKosten: '10_Stunden'!$K$4:$K$400
Name ARNr: '13_Ausgangsrechnungen'!$A$4:$A$400
Name ERNr: '14_Eingangsrechnungen'!$A$4:$A$400
Name MahnungNr: '17_Mahnwesen'!$A$4:$A$400

Sheet 24_Dashboard
A1: KPI-Dashboard Bau · Geschäftsleitung
A2: Live aus Bewegungsdaten · Bergmann Hoch- und Tiefbau GmbH · GJ 2026
A4: Umsatz Ist GJ | C4: Forecast Umsatz | E4: Auftragsbestand | G4: EBIT Forecast | I4: Rohertragsmarge | K4: EBIT-Marge Ist
A5: ='22_BWA'!B4 | C5: ='21_Forecast'!N20 | E5: =SUMIF('05_Projekte'!F:F,"in Bau",'05_Projekte'!AF:AF)+SUMIF('05_Projekte'!F:F,"beauftragt",'05_Projekte'!AF:AF)+SUMIF('05_Projekte'!F:F,"geplant",'05_Projekte'!AF:AF) | G5: ='22_BWA'!C11 | I5: ='22_BWA'!B12 | K5: ='22_BWA'!B13
A8: OP Debitoren | C8: OP Kreditoren | E8: Einbehalte | G8: Liquidität 13W | I8: Überfällige AR | K8: Hit-Rate Angebote
A9: ='22_BWA'!B14 | C9: ='22_BWA'!B15 | E9: ='22_BWA'!B16 | G9: ='20_Liquiditaet'!B14 | I9: =COUNTIFS('13_Ausgangsrechnungen'!T:T,">0",'13_Ausgangsrechnungen'!S:S,">0") | K9: =IF(COUNTA('08_Angebote'!A4:A400)=0,0,COUNTIF('08_Angebote'!I:I,"angenommen")/COUNTA('08_Angebote'!A4:A400))
A12: Frühwarnung
A13: Liquiditätsengpass in 13 Wochen | B13: =IF(COUNTIF('20_Liquiditaet'!B16:N16,"ENGPASS")>0,"JA — Disposition prüfen","nein")
A14: Mahnungen offen | B14: =COUNTIF('17_Mahnwesen'!H:H,"offen")&" offene Mahnfälle"
A15: Nachträge in Prüfung | B15: =COUNTIF('07_Nachtraege'!F:F,"in Prüfung")&" Claims ohne Freigabe"
A16: Projekte Ampel PRÜFEN | B16: =COUNTIF('23_SollIst'!N:N,"PRÜFEN")&" Projekte unter Marge / über Budget / hohe OP"
A17: Bindefrist Angebote | B17: =COUNTIF('08_Angebote'!M:M,"Bindefrist!")&" Angebote über Bindefrist"
A19: Monatswerte Umsatz / EBIT Forecast
A20: Monat | B20: ='21_Forecast'!B3 | C20: ='21_Forecast'!C3 | D20: ='21_Forecast'!D3 | E20: ='21_Forecast'!E3 | F20: ='21_Forecast'!F3 | G20: ='21_Forecast'!G3 | H20: ='21_Forecast'!H3 | I20: ='21_Forecast'!I3 | ... M20: ='21_Forecast'!M3
A21: Umsatz FC | B21: ='21_Forecast'!B20 | C21: ='21_Forecast'!C20 | D21: ='21_Forecast'!D20 | E21: ='21_Forecast'!E20 | F21: ='21_Forecast'!F20 | G21: ='21_Forecast'!G20 | H21: ='21_Forecast'!H20 | I21: ='21_Forecast'!I20 | ... M21: ='21_Forecast'!M20
A22: EBIT FC | B22: ='21_Forecast'!B26 | C22: ='21_Forecast'!C26 | D22: ='21_Forecast'!D26 | E22: ='21_Forecast'!E26 | F22: ='21_Forecast'!F26 | G22: ='21_Forecast'!G26 | H22: ='21_Forecast'!H26 | I22: ='21_Forecast'!I26 | ... M22: ='21_Forecast'!M26
A40: Top-Projekte nach Auftragswert | J40: Liquiditätsstatus
A41: Projekt | B41: Name | C41: Auftrag aktuell | D41: Fertigstellung | E41: Marge | F41: OP | J41: ='20_Liquiditaet'!B16
A42: =IF('05_Projekte'!A4="","",'05_Projekte'!A4) | B42: =IF(A42="","",'05_Projekte'!B4) | C42: =IF(A42="","",'05_Projekte'!V4) | D42: =IF(A42="","",'05_Projekte'!AE4) | E42: =IF(A42="","",'05_Projekte'!AD4) | F42: =IF(A42="","",'05_Projekte'!AG4) | J42: Kreditlinie | K42: =Kreditlinie
A43: =IF('05_Projekte'!A5="","",'05_Projekte'!A5) | B43: =IF(A43="","",'05_Projekte'!B5) | C43: =IF(A43="","",'05_Projekte'!V5) | D43: =IF(A43="","",'05_Projekte'!AE5) | E43: =IF(A43="","",'05_Projekte'!AD5) | F43: =IF(A43="","",'05_Projekte'!AG5) | J43: Mindestliquidität | K43: =MindestLiq
A44: =IF('05_Projekte'!A6="","",'05_Projekte'!A6) | B44: =IF(A44="","",'05_Projekte'!B6) | C44: =IF(A44="","",'05_Projekte'!V6) | D44: =IF(A44="","",'05_Projekte'!AE6) | E44: =IF(A44="","",'05_Projekte'!AD6) | F44: =IF(A44="","",'05_Projekte'!AG6)
A45: =IF('05_Projekte'!A7="","",'05_Projekte'!A7) | B45: =IF(A45="","",'05_Projekte'!B7) | C45: =IF(A45="","",'05_Projekte'!V7) | D45: =IF(A45="","",'05_Projekte'!AE7) | E45: =IF(A45="","",'05_Projekte'!AD7) | F45: =IF(A45="","",'05_Projekte'!AG7)
A46: =IF('05_Projekte'!A8="","",'05_Projekte'!A8) | B46: =IF(A46="","",'05_Projekte'!B8) | C46: =IF(A46="","",'05_Projekte'!V8) | D46: =IF(A46="","",'05_Projekte'!AE8) | E46: =IF(A46="","",'05_Projekte'!AD8) | F46: =IF(A46="","",'05_Projekte'!AG8)
A47: =IF('05_Projekte'!A9="","",'05_Projekte'!A9) | B47: =IF(A47="","",'05_Projekte'!B9) | C47: =IF(A47="","",'05_Projekte'!V9) | D47: =IF(A47="","",'05_Projekte'!AE9) | E47: =IF(A47="","",'05_Projekte'!AD9) | F47: =IF(A47="","",'05_Projekte'!AG9)

Sheet 00_Navi
A1: Bergmann Bau · Kaufmannsmappe
A2: Alle kaufmännischen Steuerungsblätter für das Baugewerbe · Geschäftsjahr 2026
A4: So arbeiten Sie mit der Mappe
A5: 1. Gelbe bzw. weiße Zellen sind Eingaben. Blaue Zellen sind Formeln — nicht überschreiben.
A6: 2. Neue Zeilen immer innerhalb der Tabelle einfügen (Tab-Taste am Tabellenende), dann bleiben SUMIFS erhalten.
A7: 3. Formulare: oben die Beleg- oder Projektnummer wählen, der Druckbereich füllt sich automatisch.
A8: 4. Importe: Blatt 30_Import und Skript scripts/import_csv.py. DATEV-, Bank- und Stunden-CSV möglich.
A9: 5. Dashboard, Liquidität, Cashflow, Forecast und BWA rechnen aus den Bewegungsdaten — keine Doppelpflege.
A11: Blatt | B11: Inhalt | D11: Kennzahlen-Sprung
A12: 00_Navi | B12: Start und Blattübersicht | D12: KPI-Dashboard
A13: 01_Stammdaten | B13: Firma, Steuern, Parameter | D13: Liquidität 13 Wochen
A14: 02_Kunden | B14: Auftraggeber | D14: Cashflow
A15: 03_Lieferanten | B15: Lieferanten und Nachunternehmer | D15: Forecast / Plan
A16: 04_Personal | B16: Mitarbeiter und Stundensätze | D16: Offene Posten
A17: 05_Projekte | B17: Bauvorhaben und Deckungsbeitrag | D17: Projekt-Soll-Ist
A18: 06_LV | B18: Leistungsverzeichnis
A19: 07_Nachtraege | B19: Nachträge / Claim
A20: 08_Angebote | B20: Angebotsverfolgung
A21: 09_Auftraege | B21: Beauftragte Verträge
A22: 10_Stunden | B22: Zeiterfassung
A23: 11_Material | B23: Material und Baustoffe
A24: 12_Geraete | B24: Geräte und Fuhrpark
A25: 13_Ausgangsrechnungen | B25: Abschlag, Schluss, Anzahlung
A26: 14_Eingangsrechnungen | B26: Kreditoren
A27: 15_Zahlungen | B27: Bank- und Kassenbewegungen
A28: 16_OPOS | B28: Offene Posten Debitor / Kreditor
A29: 17_Mahnwesen | B29: Mahnstufen und Fristen
... A43: 31_Anleitung | B43: Bedienung für die Buchhaltung

Sheet 01_Stammdaten
A1: Stammdaten und Steuerungsparameter
A2: Einmal pflegen — alle Formulare, USt-Berechnungen und Liquiditätsgrenzen greifen hierauf zu
A4: Firma | E4: Parameter (wirken auf alle Blätter)
A5: Firmenname | B5: Bergmann Hoch- und Tiefbau GmbH | E5: Geschäftsjahr | F5: 2026
A6: Straße | B6: Industriestraße 18 | E6: USt-Satz | F6: 0.19
A7: PLZ | B7: 85356 | E7: Skonto % | F7: 0.02
A8: Ort | B8: Freising | E8: Skonto Tage | F8: 10
A9: Telefon | B9: +49 8161 4900-0 | E9: Zahlungsziel Kunden (Tage) | F9: 30
A10: E-Mail | B10: buchhaltung@bergmann-bau.de | E10: Sicherheitseinbehalt % | F10: 0.05
A11: USt-IdNr. | B11: DE129847331 | E11: Gewährleistung Jahre | F11: 5
A12: Steuernummer | B12: 115/215/30817 | E12: Mindestliquidität | F12: 180000
A13: Handelsregister | B13: HRB 18442 Amtsgericht München | E13: Anfangsbestand Bank 01.01. | F13: 285400
A14: Geschäftsführer | B14: Andreas Bergmann | E14: Kreditlinie | F14: 250000
A15: IBAN | B15: DE89 7005 0000 0000 1844 21 | E15: Sollstunden / Monat | F15: 160
A16: BIC | B16: BYLADEM1FSI | E16: Mittl. Verrechnungssatz | F16: 68.5
A17: Bank | B17: Sparkasse Freising | E17: AGK-Zuschlag Angebot | F17: 0.12
E18: Wagnis + Gewinn | F18: 0.05
E19: Buchhaltung | F19: Claudia Meier
A20: Auswahl-Listen (Dropdown-Quellen)
A21: status_projekt | B21: status_beleg | C21: status_angebot | D21: art_projekt | E21: vertrag | F21: ar_typ | G21: er_typ | H21: zahlung_art
A22: geplant | B22: offen | C22: offen | D22: Hochbau | E22: VOB/B | F22: Abschlag | G22: Material | H22: Eingang
A23: beauftragt | B23: teilbezahlt | C23: verhandelt | D23: Tiefbau | E23: BGB | F23: Anzahlung | G23: Nachunternehmer | H23: Ausgang
A24: in Bau | B24: bezahlt | C24: angenommen | D24: Sanierung | E24: Einheitspreis | F24: Schluss | G24: Gerät
A25: abgenommen | B25: gemahnt | C25: abgelehnt | D25: Industrie | E25: Pauschal | F25: Gutschrift | G25: Dienstleistung
A26: abgeschlossen | B26: überfällig | C26: zurückgezogen | D26: Wohnungsbau | E26: GMP | F26: Nachtrag | G26: Allgemein
A27: stopp | B27: storniert | D27: Schlüsselfertig
A28: Gewährleistung
A32: Kostenarten (BWA / Soll-Ist)
A33: Nr | B33: Bezeichnung | C33: Gruppe | D33: SKR-Konto
A34: KA-10 | B34: Fertigungslöhne | C34: Personal | D34: 4100
A35: KA-11 | B35: Gehältersatz | C35: Personal | D35: 4120
A36: KA-20 | B36: Baustoffe | C36: Material | D36: 5000
A37: KA-21 | B37: Hilfsstoffe | C37: Material | D37: 5010
A38: KA-30 | B38: Nachunternehmer | C38: Fremdleistung | D38: 5900
A39: KA-40 | B39: Gerätemiete | C39: Gerät | D39: 5700
A40: KA-41 | B40: Abschreibung Geräte | C40: Gerät | D40: 4830
A41: KA-50 | B41: Baustellengemeinkosten | C41: Gemeinkosten | D41: 4760
A42: KA-60 | B42: Verwaltungsgemeinkosten | C42: Gemeinkosten | D42: 4900
A43: KA-70 | B43: Zinsen / Aval | C43: Finanz | D43: 7300

Sheet 05_Projekte
A1: Projektstamm und Deckungsbeitrag
A2: Auftrag, Nachträge, Ist-Leistung und Kosten werden automatisch verdichtet — Ampel über Marge und OP
A3: Nr | B3: Name | C3: Kunde | D3: Art | E3: Vertrag | F3: Status | G3: Start | H3: Ende Plan | I3: Ende Ist | J3: Auftrag netto | K3: Budget Material | L3: Budget NU | M3: Budget Lohn | N3: Budget Gerät | O3: Budget GK | P3: Einbehalt % | Q3: Bauleiter | R3: Polier | S3: Ort | T3: Notiz | U3: Nachträge beauftr. | V3: Auftrag aktuell | W3: Ist Leistung | X3: Ist Material | Y3: Ist NU | Z3: Ist Lohn | AA3: Ist Kosten | AB3: DB Ist | AC3: Marge % | AD3: Fertigstellung | AE3: Restumsatz | AF3: OP Debitor
A4: P-2026-001 | B4: Wohnquartier Am Park | C4: K-1001 | D4: Hochbau | E4: VOB/B | F4: in Bau | G4: 46035 | H4: 46356 | J4: 2400000 | K4: 720000 | L4: 380000 | M4: 510000 | N4: 95000 | O4: 145000 | P4: 0.05 | Q4: MA-07 | R4: MA-03 | S4: München | T4: 6 Mehrfamilienhäuser, 48 WE | U4: =IF(A4="","",SUMIFS('07_Nachtraege'!$E:$E,'07_Nachtraege'!$B:$B,A4,'07_Nachtraege'!$F:$F,"beauftragt")) | V4: =IF(A4="","",J4+U4) | W4: =IF(A4="","",SUMIFS('13_Ausgangsrechnungen'!$G:$G,'13_Ausgangsrechnungen'!$C:$C,A4)) | X4: =IF(A4="","",SUMIFS('11_Material'!$L:$L,'11_Material'!$C:$C,A4)) | Y4: =IF(A4="","",SUMIFS('14_Eingangsrechnungen'!$F:$F,'14_Eingangsrechnungen'!$C:$C,A4,'14_Eingangsrechnungen'!$E:$E,"Nachunternehmer")) | Z4: =IF(A4="","",SUMIFS('10_Stunden'!$K:$K,'10_Stunden'!$C:$C,A4)) | AA4: =IF(A4="","",X4+Y4+Z4+SUMIFS('14_Eingangsrechnungen'!$F:$F,'14_Eingangsrechnungen'!$C:$C,A4,'14_Eingangsrechnungen'!$E:$E,"Gerät")+SUMIFS('14_Eingangsrechnungen'!$F:$F,'14_Eingangsrechnungen'!$C:$C,A4,'14_Eingangsrechnungen'!$E:$E,"Dienstleistung")) | AB4: =IF(A4="","",W4-AA4) | AC4: =IF(OR(A4="",W4=0),"",AB4/W4) | AD4: =IF(OR(A4="",V4=0),"",W4/V4) | AE4: =IF(A4="","",MAX(0,V4-W4)) | AF4: =IF(A4="","",SUMIFS('13_Ausgangsrechnungen'!$R:$R,'13_Ausgangsrechnungen'!$C:$C,A4))
A5: P-2026-002 | B5: Kita Sonnenweg | C5: K-1003 | D5: Hochbau | E5: VOB/B | F5: in Bau | G5: 46083 | H5: 46310 | J5: 890000 | K5: 250000 | L5: 145000 | M5: 210000 | N5: 38000 | O5: 52000 | P5: 0.05 | Q5: MA-07 | R5: MA-03 | S5: Freising | T5: Neubau 4-gruppige Kita | U5: =IF(A5="","",SUMIFS('07_Nachtraege'!$E:$E,'07_Nachtraege'!$B:$B,A5,'07_Nachtraege'!$F:$F,"beauftragt")) | V5: =IF(A5="","",J5+U5) | W5: =IF(A5="","",SUMIFS('13_Ausgangsrechnungen'!$G:$G,'13_Ausgangsrechnungen'!$C:$C,A5)) | X5: =IF(A5="","",SUMIFS('11_Material'!$L:$L,'11_Material'!$C:$C,A5)) | Y5: =IF(A5="","",SUMIFS('14_Eingangsrechnungen'!$F:$F,'14_Eingangsrechnungen'!$C:$C,A5,'14_Eingangsrechnungen'!$E:$E,"Nachunternehmer")) | Z5: =IF(A5="","",SUMIFS('10_Stunden'!$K:$K,'10_Stunden'!$C:$C,A5)) | AA5: =IF(A5="","",X5+Y5+Z5+SUMIFS('14_Eingangsrechnungen'!$F:$F,'14_Eingangsrechnungen'!$C:$C,A5,'14_Eingangsrechnungen'!$E:$E,"Gerät")+SUMIFS('14_Eingangsrechnungen'!$F:$F,'14_Eingangsrechnungen'!$C:$C,A5,'14_Eingangsrechnungen'!$E:$E,"Dienstleistung")) | AB5: =IF(A5="","",W5-AA5) | AC5: =IF(OR(A5="",W5=0),"",AB5/W5) | AD5: =IF(OR(A5="",V5=0),"",W5/V5) | AE5: =IF(A5="","",MAX(0,V5-W5)) | AF5: =IF(A5="","",SUMIFS('13_Ausgangsrechnungen'!$R:$R,'13_Ausgangsrechnungen'!$C:$C,A5))
A6: P-2026-003 | B6: Sanierung Rathaus | C6: K-1002 | D6: Sanierung | E6: VOB/B | F6: in Bau | G6: 46069 | H6: 46374 | J6: 1100000 | K6: 210000 | L6: 320000 | M6: 245000 | N6: 42000 | O6: 68000 | P6: 0.05 | Q6: MA-07 | R6: MA-04 | S6: Freising | T6: Denkmalschutz, Nachträge wahrscheinlich | U6: =IF(A6="","",SUMIFS('07_Nachtraege'!$E:$E,'07_Nachtraege'!$B:$B,A6,'07_Nachtraege'!$F:$F,"beauftragt")) | V6: =IF(A6="","",J6+U6) | W6: =IF(A6="","",SUMIFS('13_Ausgangsrechnungen'!$G:$G,'13_Ausgangsrechnungen'!$C:$C,A6)) | X6: =IF(A6="","",SUMIFS('11_Material'!$L:$L,'11_Material'!$C:$C,A6)) | Y6: =IF(A6="","",SUMIFS('14_Eingangsrechnungen'!$F:$F,'14_Eingangsrechnungen'!$C:$C,A6,'14_Eingangsrechnungen'!$E:$E,"Nachunternehmer")) | Z6: =IF(A6="","",SUMIFS('10_Stunden'!$K:$K,'10_Stunden'!$C:$C,A6)) | AA6: =IF(A6="","",X6+Y6+Z6+SUMIFS('14_Eingangsrechnungen'!$F:$F,'14_Eingangsrechnungen'!$C:$C,A6,'14_Eingangsrechnungen'!$E:$E,"Gerät")+SUMIFS('14_Eingangsrechnungen'!$F:$F,'14_Eingangsrechnungen'!$C:$C,A6,'14_Eingangsrechnungen'!$E:$E,"Dienstleistung")) | AB6: =IF(A6="","",W6-AA6) | AC6: =IF(OR(A6="",W6=0),"",AB6/W6) | AD6: =IF(OR(A6="",V6=0),"",W6/V6) | AE6: =IF(A6="","",MAX(0,V6-W6)) | AF6: =IF(A6="","",SUMIFS('13_Ausgangsrechnungen'!$R:$R,'13_Ausgangsrechnungen'!$C:$C,A6))
A7: P-2026-004 | B7: Gewerbehalle Nord | C7: K-1004 | D7: Industrie | E7: BGB | F7: in Bau | G7: 46118 | H7: 46444 | J7: 3200000 | K7: 980000 | L7: 540000 | M7: 610000 | N7: 145000 | O7: 190000 | P7: 0.05 | Q7: MA-07 | R7: MA-03 | S7: Dachau | T7: Stahlhalle 4.200 m² + Büro | U7: =IF(A7="","",SUMIFS('07_Nachtraege'!$E:$E,'07_Nachtraege'!$B:$B,A7,'07_Nachtraege'!$F:$F,"beauftragt")) | V7: =IF(A7="","",J7+U7) | W7: =IF(A7="","",SUMIFS('13_Ausgangsrechnungen'!$G:$G,'13_Ausgangsrechnungen'!$C:$C,A7)) | X7: =IF(A7="","",SUMIFS('11_Material'!$L:$L,'11_Material'!$C:$C,A7)) | Y7: =IF(A7="","",SUMIFS('14_Eingangsrechnungen'!$F:$F,'14_Eingangsrechnungen'!$C:$C,A7,'14_Eingangsrechnungen'!$E:$E,"Nachunternehmer")) | Z7: =IF(A7="","",SUMIFS('10_Stunden'!$K:$K,'10_Stunden'!$C:$C,A7)) | AA7: =IF(A7="","",X7+Y7+Z7+SUMIFS('14_Eingangsrechnungen'!$F:$F,'14_Eingangsrechnungen'!$C:$C,A7,'14_Eingangsrechnungen'!$E:$E,"Gerät")+SUMIFS('14_Eingangsrechnungen'!$F:$F,'14_Eingangsrechnungen'!$C:$C,A7,'14_Eingangsrechnungen'!$E:$E,"Dienstleistung")) | AB7: =IF(A7="","",W7-AA7) | AC7: =IF(OR(A7="",W7=0),"",AB7/W7) | AD7: =IF(OR(A7="",V7=0),"",W7/V7) | AE7: =IF(A7="","",MAX(0,V7-W7)) | AF7: =IF(A7="","",SUMIFS('13_Ausgangsrechnungen'!$R:$R,'13_Ausgangsrechnungen'!$C:$C,A7))
A8: P-2026-005 | B8: EFH Familie Huber | C8: K-1005 | D8: Wohnungsbau | E8: BGB | F8: abgeschlossen | G8: 45908 | H8: 46142 | I8: 46134 | J8: 420000 | K8: 145000 | L8: 38000 | M8: 98000 | N8: 18000 | O8: 24000 | P8: 0.05 | Q8: MA-07 | R8: MA-04 | S8: Erding | T8: Schlussrechnung gestellt | U8: =IF(A8="","",SUMIFS('07_Nachtraege'!$E:$E,'07_Nachtraege'!$B:$B,A8,'07_Nachtraege'!$F:$F,"beauftragt")) | V8: =IF(A8="","",J8+U8) | W8: =IF(A8="","",SUMIFS('13_Ausgangsrechnungen'!$G:$G,'13_Ausgangsrechnungen'!$C:$C,A8)) | X8: =IF(A8="","",SUMIFS('11_Material'!$L:$L,'11_Material'!$C:$C,A8)) | Y8: =IF(A8="","",SUMIFS('14_Eingangsrechnungen'!$F:$F,'14_Eingangsrechnungen'!$C:$C,A8,'14_Eingangsrechnungen'!$E:$E,"Nachunternehmer")) | Z8: =IF(A8="","",SUMIFS('10_Stunden'!$K:$K,'10_Stunden'!$C:$C,A8)) | AA8: =IF(A8="","",X8+Y8+Z8+SUMIFS('14_Eingangsrechnungen'!$F:$F,'14_Eingangsrechnungen'!$C:$C,A8,'14_Eingangsrechnungen'!$E:$E,"Gerät")+SUMIFS('14_Eingangsrechnungen'!$F:$F,'14_Eingangsrechnungen'!$C:$C,A8,'14_Eingangsrechnungen'!$E:$E,"Dienstleistung")) | AB8: =IF(A8="","",W8-AA8) | AC8: =IF(OR(A8="",W8=0),"",AB8/W8) | AD8: =IF(OR(A8="",V8=0),"",W8/V8) | AE8: =IF(A8="","",MAX(0,V8-W8)) | AF8: =IF(A8="","",SUMIFS('13_Ausgangsrechnungen'!$R:$R,'13_Ausgangsrechnungen'!$C:$C,A8))
A9: P-2026-006 | B9: Straßenbau B13 Abschnitt | C9: K-1006 | D9: Tiefbau | E9: VOB/B | F9: geplant | G9: 46266 | H9: 46568 | J9: 1800000 | K9: 620000 | L9: 210000 | M9: 430000 | N9: 165000 | O9: 98000 | P9: 0.05 | Q9: MA-07 | R9: MA-06 | S9: Freising Land | T9: Zuschlag 12.08.2026, Baubeginn Sept. | U9: =IF(A9="","",SUMIFS('07_Nachtraege'!$E:$E,'07_Nachtraege'!$B:$B,A9,'07_Nachtraege'!$F:$F,"beauftragt")) | V9: =IF(A9="","",J9+U9) | W9: =IF(A9="","",SUMIFS('13_Ausgangsrechnungen'!$G:$G,'13_Ausgangsrechnungen'!$C:$C,A9)) | X9: =IF(A9="","",SUMIFS('11_Material'!$L:$L,'11_Material'!$C:$C,A9)) | Y9: =IF(A9="","",SUMIFS('14_Eingangsrechnungen'!$F:$F,'14_Eingangsrechnungen'!$C:$C,A9,'14_Eingangsrechnungen'!$E:$E,"Nachunternehmer")) | Z9: =IF(A9="","",SUMIFS('10_Stunden'!$K:$K,'10_Stunden'!$C:$C,A9)) | AA9: =IF(A9="","",X9+Y9+Z9+SUMIFS('14_Eingangsrechnungen'!$F:$F,'14_Eingangsrechnungen'!$C:$C,A9,'14_Eingangsrechnungen'!$E:$E,"Gerät")+SUMIFS('14_Eingangsrechnungen'!$F:$F,'14_Eingangsrechnungen'!$C:$C,A9,'14_Eingangsrechnungen'!$E:$E,"Dienstleistung")) | AB9: =IF(A9="","",W9-AA9) | AC9: =IF(OR(A9="",W9=0),"",AB9/W9) | AD9: =IF(OR(A9="",V9=0),"",W9/V9) | AE9: =IF(A9="","",MAX(0,V9-W9)) | AF9: =IF(A9="","",SUMIFS('13_Ausgangsrechnungen'!$R:$R,'13_Ausgangsrechnungen'!$C:$C,A9))
U10: =IF(A10="","",SUMIFS('07_Nachtraege'!$E:$E,'07_Nachtraege'!$B:$B,A10,'07_Nachtraege'!$F:$F,"beauftragt")) | V10: =IF(A10="","",J10+U10) | W10: =IF(A10="","",SUMIFS('13_Ausgangsrechnungen'!$G:$G,'13_Ausgangsrechnungen'!$C:$C,A10)) | X10: =IF(A10="","",SUMIFS('11_Material'!$L:$L,'11_Material'!$C:$C,A10)) | Y10: =IF(A10="","",SUMIFS('14_Eingangsrechnungen'!$F:$F,'14_Eingangsrechnungen'!$C:$C,A10,'14_Eingangsrechnungen'!$E:$E,"Nachunternehmer")) | Z10: =IF(A10="","",SUMIFS('10_Stunden'!$K:$K,'10_Stunden'!$C:$C,A10)) | AA10: =IF(A10="","",X10+Y10+Z10+SUMIFS('14_Eingangsrechnungen'!$F:$F,'14_Eingangsrechnungen'!$C:$C,A10,'14_Eingangsrechnungen'!$E:$E,"Gerät")+SUMIFS('14_Eingangsrechnungen'!$F:$F,'14_Eingangsrechnungen'!$C:$C,A10,'14_Eingangsrechnungen'!$E:$E,"Dienstleistung")) | AB10: =IF(A10="","",W10-AA10) | AC10: =IF(OR(A10="",W10=0),"",AB10/W10) | AD10: =IF(OR(A10="",V10=0),"",W10/V10) | AE10: =IF(A10="","",MAX(0,V10-W10)) | AF10: =IF(A10="","",SUMIFS('13_Ausgangsrechnungen'!$R:$R,'13_Ausgangsrechnungen'!$C:$C,A10))
U11: =IF(A11="","",SUMIFS('07_Nachtraege'!$E:$E,'07_Nachtraege'!$B:$B,A11,'07_Nachtraege'!$F:$F,"beauftragt")) | V11: =IF(A11="","",J11+U11) | W11: =IF(A11="","",SUMIFS('13_Ausgangsrechnungen'!$G:$G,'13_Ausgangsrechnungen'!$C:$C,A11)) | X11: =IF(A11="","",SUMIFS('11_Material'!$L:$L,'11_Material'!$C:$C,A11)) | Y11: =IF(A11="","",SUMIFS('14_Eingangsrechnungen'!$F:$F,'14_Eingangsrechnungen'!$C:$C,A11,'14_Eingangsrechnungen'!$E:$E,"Nachunternehmer")) | Z11: =IF(A11="","",SUMIFS('10_Stunden'!$K:$K,'10_Stunden'!$C:$C,A11)) | AA11: =IF(A11="","",X11+Y11+Z11+SUMIFS('14_Eingangsrechnungen'!$F:$F,'14_Eingangsrechnungen'!$C:$C,A11,'14_Eingangsrechnungen'!$E:$E,"Gerät")+SUMIFS('14_Eingangsrechnungen'!$F:$F,'14_Eingangsrechnungen'!$C:$C,A11,'14_Eingangsrechnungen'!$E:$E,"Dienstleistung")) | AB11: =IF(A11="","",W11-AA11) | AC11: =IF(OR(A11="",W11=0),"",AB11/W11) | AD11: =IF(OR(A11="",V11=0),"",W11/V11) | AE11: =IF(A11="","",MAX(0,V11-W11)) | AF11: =IF(A11="","",SUMIFS('13_Ausgangsrechnungen'!$R:$R,'13_Ausgangsrechnungen'!$C:$C,A11))
U12: =IF(A12="","",SUMIFS('07_Nachtraege'!$E:$E,'07_Nachtraege'!$B:$B,A12,'07_Nachtraege'!$F:$F,"beauftragt")) | V12: =IF(A12="","",J12+U12) | W12: =IF(A12="","",SUMIFS('13_Ausgangsrechnungen'!$G:$G,'13_Ausgangsrechnungen'!$C:$C,A12)) | X12: =IF(A12="","",SUMIFS('11_Material'!$L:$L,'11_Material'!$C:$C,A12)) | Y12: =IF(A12="","",SUMIFS('14_Eingangsrechnungen'!$F:$F,'14_Eingangsrechnungen'!$C:$C,A12,'14_Eingangsrechnungen'!$E:$E,"Nachunternehmer")) | Z12: =IF(A12="","",SUMIFS('10_Stunden'!$K:$K,'10_Stunden'!$C:$C,A12)) | AA12: =IF(A12="","",X12+Y12+Z12+SUMIFS('14_Eingangsrechnungen'!$F:$F,'14_Eingangsrechnungen'!$C:$C,A12,'14_Eingangsrechnungen'!$E:$E,"Gerät")+SUMIFS('14_Eingangsrechnungen'!$F:$F,'14_Eingangsrechnungen'!$C:$C,A12,'14_Eingangsrechnungen'!$E:$E,"Dienstleistung")) | AB12: =IF(A12="","",W12-AA12) | AC12: =IF(OR(A12="",W12=0),"",AB12/W12) | AD12: =IF(OR(A12="",V12=0),"",W12/V12) | AE12: =IF(A12="","",MAX(0,V12-W12)) | AF12: =IF(A12="","",SUMIFS('13_Ausgangsrechnungen'!$R:$R,'13_Ausgangsrechnungen'!$C:$C,A12))
U13: =IF(A13="","",SUMIFS('07_Nachtraege'!$E:$E,'07_Nachtraege'!$B:$B,A13,'07_Nachtraege'!$F:$F,"beauftragt")) | V13: =IF(A13="","",J13+U13) | W13: =IF(A13="","",SUMIFS('13_Ausgangsrechnungen'!$G:$G,'13_Ausgangsrechnungen'!$C:$C,A13)) | X13: =IF(A13="","",SUMIFS('11_Material'!$L:$L,'11_Material'!$C:$C,A13)) | Y13: =IF(A13="","",SUMIFS('14_Eingangsrechnungen'!$F:$F,'14_Eingangsrechnungen'!$C:$C,A13,'14_Eingangsrechnungen'!$E:$E,"Nachunternehmer")) | Z13: =IF(A13="","",SUMIFS('10_Stunden'!$K:$K,'10_Stunden'!$C:$C,A13)) | AA13: =IF(A13="","",X13+Y13+Z13+SUMIFS('14_Eingangsrechnungen'!$F:$F,'14_Eingangsrechnungen'!$C:$C,A13,'14_Eingangsrechnungen'!$E:$E,"Gerät")+SUMIFS('14_Eingangsrechnungen'!$F:$F,'14_Eingangsrechnungen'!$C:$C,A13,'14_Eingangsrechnungen'!$E:$E,"Dienstleistung")) | AB13: =IF(A13="","",W13-AA13) | AC13: =IF(OR(A13="",W13=0),"",AB13/W13) | AD13: =IF(OR(A13="",V13=0),"",W13/V13) | AE13: =IF(A13="","",MAX(0,V13-W13)) | AF13: =IF(A13="","",SUMIFS('13_Ausgangsrechnungen'!$R:$R,'13_Ausgangsrechnungen'!$C:$C,A13))
U14: =IF(A14="","",SUMIFS('07_Nachtraege'!$E:$E,'07_Nachtraege'!$B:$B,A14,'07_Nachtraege'!$F:$F,"beauftragt")) | V14: =IF(A14="","",J14+U14) | W14: =IF(A14="","",SUMIFS('13_Ausgangsrechnungen'!$G:$G,'13_Ausgangsrechnungen'!$C:$C,A14)) | X14: =IF(A14="","",SUMIFS('11_Material'!$L:$L,'11_Material'!$C:$C,A14)) | Y14: =IF(A14="","",SUMIFS('14_Eingangsrechnungen'!$F:$F,'14_Eingangsrechnungen'!$C:$C,A14,'14_Eingangsrechnungen'!$E:$E,"Nachunternehmer")) | Z14: =IF(A14="","",SUMIFS('10_Stunden'!$K:$K,'10_Stunden'!$C:$C,A14)) | AA14: =IF(A14="","",X14+Y14+Z14+SUMIFS('14_Eingangsrechnungen'!$F:$F,'14_Eingangsrechnungen'!$C:$C,A14,'14_Eingangsrechnungen'!$E:$E,"Gerät")+SUMIFS('14_Eingangsrechnungen'!$F:$F,'14_Eingangsrechnungen'!$C:$C,A14,'14_Eingangsrechnungen'!$E:$E,"Dienstleistung")) | AB14: =IF(A14="","",W14-AA14) | AC14: =IF(OR(A14="",W14=0),"",AB14/W14) | AD14: =IF(OR(A14="",V14=0),"",W14/V14) | AE14: =IF(A14="","",MAX(0,V14-W14)) | AF14: =IF(A14="","",SUMIFS('13_Ausgangsrechnungen'!$R:$R,'13_Ausgangsrechnungen'!$C:$C,A14))
U15: =IF(A15="","",SUMIFS('07_Nachtraege'!$E:$E,'07_Nachtraege'!$B:$B,A15,'07_Nachtraege'!$F:$F,"beauftragt")) | V15: =IF(A15="","",J15+U15) | W15: =IF(A15="","",SUMIFS('13_Ausgangsrechnungen'!$G:$G,'13_Ausgangsrechnungen'!$C:$C,A15)) | X15: =IF(A15="","",SUMIFS('11_Material'!$L:$L,'11_Material'!$C:$C,A15)) | Y15: =IF(A15="","",SUMIFS('14_Eingangsrechnungen'!$F:$F,'14_Eingangsrechnungen'!$C:$C,A15,'14_Eingangsrechnungen'!$E:$E,"Nachunternehmer")) | Z15: =IF(A15="","",SUMIFS('10_Stunden'!$K:$K,'10_Stunden'!$C:$C,A15)) | AA15: =IF(A15="","",X15+Y15+Z15+SUMIFS('14_Eingangsrechnungen'!$F:$F,'14_Eingangsrechnungen'!$C:$C,A15,'14_Eingangsrechnungen'!$E:$E,"Gerät")+SUMIFS('14_Eingangsrechnungen'!$F:$F,'14_Eingangsrechnungen'!$C:$C,A15,'14_Eingangsrechnungen'!$E:$E,"Dienstleistung")) | AB15: =IF(A15="","",W15-AA15) | AC15: =IF(OR(A15="",W15=0),"",AB15/W15) | AD15: =IF(OR(A15="",V15=0),"",W15/V15) | AE15: =IF(A15="","",MAX(0,V15-W15)) | AF15: =IF(A15="","",SUMIFS('13_Ausgangsrechnungen'!$R:$R,'13_Ausgangsrechnungen'!$C:$C,A15))
U16: =IF(A16="","",SUMIFS('07_Nachtraege'!$E:$E,'07_Nachtraege'!$B:$B,A16,'07_Nachtraege'!$F:$F,"beauftragt")) | V16: =IF(A16="","",J16+U16) | W16: =IF(A16="","",SUMIFS('13_Ausgangsrechnungen'!$G:$G,'13_Ausgangsrechnungen'!$C:$C,A16)) | X16: =IF(A16="","",SUMIFS('11_Material'!$L:$L,'11_Material'!$C:$C,A16)) | Y16: =IF(A16="","",SUMIFS('14_Eingangsrechnungen'!$F:$F,'14_Eingangsrechnungen'!$C:$C,A16,'14_Eingangsrechnungen'!$E:$E,"Nachunternehmer")) | Z16: =IF(A16="","",SUMIFS('10_Stunden'!$K:$K,'10_Stunden'!$C:$C,A16)) | AA16: =IF(A16="","",X16+Y16+Z16+SUMIFS('14_Eingangsrechnungen'!$F:$F,'14_Eingangsrechnungen'!$C:$C,A16,'14_Eingangsrechnungen'!$E:$E,"Gerät")+SUMIFS('14_Eingangsrechnungen'!$F:$F,'14_Eingangsrechnungen'!$C:$C,A16,'14_Eingangsrechnungen'!$E:$E,"Dienstleistung")) | AB16: =IF(A16="","",W16-AA16) | AC16: =IF(OR(A16="",W16=0),"",AB16/W16) | AD16: =IF(OR(A16="",V16=0),"",W16/V16) | AE16: =IF(A16="","",MAX(0,V16-W16)) | AF16: =IF(A16="","",SUMIFS('13_Ausgangsrechnungen'!$R:$R,'13_Ausgangsrechnungen'!$C:$C,A16))
U17: =IF(A17="","",SUMIFS('07_Nachtraege'!$E:$E,'07_Nachtraege'!$B:$B,A17,'07_Nachtraege'!$F:$F,"beauftragt")) | V17: =IF(A17="","",J17+U17) | W17: =IF(A17="","",SUMIFS('13_Ausgangsrechnungen'!$G:$G,'13_Ausgangsrechnungen'!$C:$C,A17)) | X17: =IF(A17="","",SUMIFS('11_Material'!$L:$L,'11_Material'!$C:$C,A17)) | Y17: =IF(A17="","",SUMIFS('14_Eingangsrechnungen'!$F:$F,'14_Eingangsrechnungen'!$C:$C,A17,'14_Eingangsrechnungen'!$E:$E,"Nachunternehmer")) | Z17: =IF(A17="","",SUMIFS('10_Stunden'!$K:$K,'10_Stunden'!$C:$C,A17)) | AA17: =IF(A17="","",X17+Y17+Z17+SUMIFS('14_Eingangsrechnungen'!$F:$F,'14_Eingangsrechnungen'!$C:$C,A17,'14_Eingangsrechnungen'!$E:$E,"Gerät")+SUMIFS('14_Eingangsrechnungen'!$F:$F,'14_Eingangsrechnungen'!$C:$C,A17,'14_Eingangsrechnungen'!$E:$E,"Dienstleistung")) | AB17: =IF(A17="","",W17-AA17) | AC17: =IF(OR(A17="",W17=0),"",AB17/W17) | AD17: =IF(OR(A17="",V17=0),"",W17/V17) | AE17: =IF(A17="","",MAX(0,V17-W17)) | AF17: =IF(A17="","",SUMIFS('13_Ausgangsrechnungen'!$R:$R,'13_Ausgangsrechnungen'!$C:$C,A17))
U18: =IF(A18="","",SUMIFS('07_Nachtraege'!$E:$E,'07_Nachtraege'!$B:$B,A18,'07_Nachtraege'!$F:$F,"beauftragt")) | V18: =IF(A18="","",J18+U18) | W18: =IF(A18="","",SUMIFS('13_Ausgangsrechnungen'!$G:$G,'13_Ausgangsrechnungen'!$C:$C,A18)) | X18: =IF(A18="","",SUMIFS('11_Material'!$L:$L,'11_Material'!$C:$C,A18)) | Y18: =IF(A18="","",SUMIFS('14_Eingangsrechnungen'!$F:$F,'14_Eingangsrechnungen'!$C:$C,A18,'14_Eingangsrechnungen'!$E:$E,"Nachunternehmer")) | Z18: =IF(A18="","",SUMIFS('10_Stunden'!$K:$K,'10_Stunden'!$C:$C,A18)) | AA18: =IF(A18="","",X18+Y18+Z18+SUMIFS('14_Eingangsrechnungen'!$F:$F,'14_Eingangsrechnungen'!$C:$C,A18,'14_Eingangsrechnungen'!$E:$E,"Gerät")+SUMIFS('14_Eingangsrechnungen'!$F:$F,'14_Eingangsrechnungen'!$C:$C,A18,'14_Eingangsrechnungen'!$E:$E,"Dienstleistung")) | AB18: =IF(A18="","",W18-AA18) | AC18: =IF(OR(A18="",W18=0),"",AB18/W18) | AD18: =IF(OR(A18="",V18=0),"",W18/V18) | AE18: =IF(A18="","",MAX(0,V18-W18)) | AF18: =IF(A18="","",SUMIFS('13_Ausgangsrechnungen'!$R:$R,'13_Ausgangsrechnungen'!$C:$C,A18))
U19: =IF(A19="","",SUMIFS('07_Nachtraege'!$E:$E,'07_Nachtraege'!$B:$B,A19,'07_Nachtraege'!$F:$F,"beauftragt")) | V19: =IF(A19="","",J19+U19) | W19: =IF(A19="","",SUMIFS('13_Ausgangsrechnungen'!$G:$G,'13_Ausgangsrechnungen'!$C:$C,A19)) | X19: =IF(A19="","",SUMIFS('11_Material'!$L:$L,'11_Material'!$C:$C,A19)) | Y19: =IF(A19="","",SUMIFS('14_Eingangsrechnungen'!$F:$F,'14_Eingangsrechnungen'!$C:$C,A19,'14_Eingangsrechnungen'!$E:$E,"Nachunternehmer")) | Z19: =IF(A19="","",SUMIFS('10_Stunden'!$K:$K,'10_Stunden'!$C:$C,A19)) | AA19: =IF(A19="","",X19+Y19+Z19+SUMIFS('14_Eingangsrechnungen'!$F:$F,'14_Eingangsrechnungen'!$C:$C,A19,'14_Eingangsrechnungen'!$E:$E,"Gerät")+SUMIFS('14_Eingangsrechnungen'!$F:$F,'14_Eingangsrechnungen'!$C:$C,A19,'14_Eingangsrechnungen'!$E:$E,"Dienstleistung")) | AB19: =IF(A19="","",W19-AA19) | AC19: =IF(OR(A19="",W19=0),"",AB19/W19) | AD19: =IF(OR(A19="",V19=0),"",W19/V19) | AE19: =IF(A19="","",MAX(0,V19-W19)) | AF19: =IF(A19="","",SUMIFS('13_Ausgangsrechnungen'!$R:$R,'13_Ausgangsrechnungen'!$C:$C,A19))
U20: =IF(A20="","",SUMIFS('07_Nachtraege'!$E:$E,'07_Nachtraege'!$B:$B,A20,'07_Nachtraege'!$F:$F,"beauftragt")) | V20: =IF(A20="","",J20+U20) | W20: =IF(A20="","",SUMIFS('13_Ausgangsrechnungen'!$G:$G,'13_Ausgangsrechnungen'!$C:$C,A20)) | X20: =IF(A20="","",SUMIFS('11_Material'!$L:$L,'11_Material'!$C:$C,A20)) | Y20: =IF(A20="","",SUMIFS('14_Eingangsrechnungen'!$F:$F,'14_Eingangsrechnungen'!$C:$C,A20,'14_Eingangsrechnungen'!$E:$E,"Nachunternehmer")) | Z20: =IF(A20="","",SUMIFS('10_Stunden'!$K:$K,'10_Stunden'!$C:$C,A20)) | AA20: =IF(A20="","",X20+Y20+Z20+SUMIFS('14_Eingangsrechnungen'!$F:$F,'14_Eingangsrechnungen'!$C:$C,A20,'14_Eingangsrechnungen'!$E:$E,"Gerät")+SUMIFS('14_Eingangsrechnungen'!$F:$F,'14_Eingangsrechnungen'!$C:$C,A20,'14_Eingangsrechnungen'!$E:$E,"Dienstleistung")) | AB20: =IF(A20="","",W20-AA20) | AC20: =IF(OR(A20="",W20=0),"",AB20/W20) | AD20: =IF(OR(A20="",V20=0),"",W20/V20) | AE20: =IF(A20="","",MAX(0,V20-W20)) | AF20: =IF(A20="","",SUMIFS('13_Ausgangsrechnungen'!$R:$R,'13_Ausgangsrechnungen'!$C:$C,A20))
U21: =IF(A21="","",SUMIFS('07_Nachtraege'!$E:$E,'07_Nachtraege'!$B:$B,A21,'07_Nachtraege'!$F:$F,"beauftragt")) | V21: =IF(A21="","",J21+U21) | W21: =IF(A21="","",SUMIFS('13_Ausgangsrechnungen'!$G:$G,'13_Ausgangsrechnungen'!$C:$C,A21)) | X21: =IF(A21="","",SUMIFS('11_Material'!$L:$L,'11_Material'!$C:$C,A21)) | Y21: =IF(A21="","",SUMIFS('14_Eingangsrechnungen'!$F:$F,'14_Eingangsrechnungen'!$C:$C,A21,'14_Eingangsrechnungen'!$E:$E,"Nachunternehmer")) | Z21: =IF(A21="","",SUMIFS('10_Stunden'!$K:$K,'10_Stunden'!$C:$C,A21)) | AA21: =IF(A21="","",X21+Y21+Z21+SUMIFS('14_Eingangsrechnungen'!$F:$F,'14_Eingangsrechnungen'!$C:$C,A21,'14_Eingangsrechnungen'!$E:$E,"Gerät")+SUMIFS('14_Eingangsrechnungen'!$F:$F,'14_Eingangsrechnungen'!$C:$C,A21,'14_Eingangsrechnungen'!$E:$E,"Dienstleistung")) | AB21: =IF(A21="","",W21-AA21) | AC21: =IF(OR(A21="",W21=0),"",AB21/W21) | AD21: =IF(OR(A21="",V21=0),"",W21/V21) | AE21: =IF(A21="","",MAX(0,V21-W21)) | AF21: =IF(A21="","",SUMIFS('13_Ausgangsrechnungen'!$R:$R,'13_Ausgangsrechnungen'!$C:$C,A21))
... U400: =IF(A400="","",SUMIFS('07_Nachtraege'!$E:$E,'07_Nachtraege'!$B:$B,A400,'07_Nachtraege'!$F:$F,"beauftragt")) | V400: =IF(A400="","",J400+U400) | W400: =IF(A400="","",SUMIFS('13_Ausgangsrechnungen'!$G:$G,'13_Ausgangsrechnungen'!$C:$C,A400)) | X400: =IF(A400="","",SUMIFS('11_Material'!$L:$L,'11_Material'!$C:$C,A400)) | Y400: =IF(A400="","",SUMIFS('14_Eingangsrechnungen'!$F:$F,'14_Eingangsrechnungen'!$C:$C,A400,'14_Eingangsrechnungen'!$E:$E,"Nachunternehmer")) | Z400: =IF(A400="","",SUMIFS('10_Stunden'!$K:$K,'10_Stunden'!$C:$C,A400)) | AA400: =IF(A400="","",X400+Y400+Z400+SUMIFS('14_Eingangsrechnungen'!$F:$F,'14_Eingangsrechnungen'!$C:$C,A400,'14_Eingangsrechnungen'!$E:$E,"Gerät")+SUMIFS('14_Eingangsrechnungen'!$F:$F,'14_Eingangsrechnungen'!$C:$C,A400,'14_Eingangsrechnungen'!$E:$E,"Dienstleistung")) | AB400: =IF(A400="","",W400-AA400) | AC400: =IF(OR(A400="",W400=0),"",AB400/W400) | AD400: =IF(OR(A400="",V400=0),"",W400/V400) | AE400: =IF(A400="","",MAX(0,V400-W400)) | AF400: =IF(A400="","",SUMIFS('13_Ausgangsrechnungen'!$R:$R,'13_Ausgangsrechnungen'!$C:$C,A400))

Sheet 23_SollIst
A1: Projekt-Soll-Ist
A2: Eine Zeile je Projekt — Werte kommen aus dem Projektstamm, Nachträgen und Ist-Kosten
A3: Projekt | B3: Name | C3: Auftrag aktuell | D3: Ist Leistung | E3: Budget Kosten | F3: Ist Kosten | G3: Δ Kosten | H3: DB Soll | I3: DB Ist | J3: Marge Ist | K3: Fertigstellung | L3: Restleistung | M3: OP Debitor | N3: Ampel
A4: =IF('05_Projekte'!A4="","",'05_Projekte'!A4) | B4: =IF(A4="","",'05_Projekte'!B4) | C4: =IF(A4="","",'05_Projekte'!V4) | D4: =IF(A4="","",'05_Projekte'!W4) | E4: =IF(A4="","",'05_Projekte'!K4+'05_Projekte'!L4+'05_Projekte'!M4+'05_Projekte'!N4+'05_Projekte'!O4) | F4: =IF(A4="","",'05_Projekte'!AA4) | G4: =IF(A4="","",F4-E4) | H4: =IF(A4="","",C4-E4) | I4: =IF(A4="","",'05_Projekte'!AB4) | J4: =IF(A4="","",'05_Projekte'!AD4) | K4: =IF(A4="","",'05_Projekte'!AE4) | L4: =IF(A4="","",'05_Projekte'!AF4) | M4: =IF(A4="","",'05_Projekte'!AG4) | N4: =IF(A4="","",IF(OR(J4<0.08,G4>0,M4>50000),"PRÜFEN","OK"))
A5: =IF('05_Projekte'!A5="","",'05_Projekte'!A5) | B5: =IF(A5="","",'05_Projekte'!B5) | C5: =IF(A5="","",'05_Projekte'!V5) | D5: =IF(A5="","",'05_Projekte'!W5) | E5: =IF(A5="","",'05_Projekte'!K5+'05_Projekte'!L5+'05_Projekte'!M5+'05_Projekte'!N5+'05_Projekte'!O5) | F5: =IF(A5="","",'05_Projekte'!AA5) | G5: =IF(A5="","",F5-E5) | H5: =IF(A5="","",C5-E5) | I5: =IF(A5="","",'05_Projekte'!AB5) | J5: =IF(A5="","",'05_Projekte'!AD5) | K5: =IF(A5="","",'05_Projekte'!AE5) | L5: =IF(A5="","",'05_Projekte'!AF5) | M5: =IF(A5="","",'05_Projekte'!AG5) | N5: =IF(A5="","",IF(OR(J5<0.08,G5>0,M5>50000),"PRÜFEN","OK"))
A6: =IF('05_Projekte'!A6="","",'05_Projekte'!A6) | B6: =IF(A6="","",'05_Projekte'!B6) | C6: =IF(A6="","",'05_Projekte'!V6) | D6: =IF(A6="","",'05_Projekte'!W6) | E6: =IF(A6="","",'05_Projekte'!K6+'05_Projekte'!L6+'05_Projekte'!M6+'05_Projekte'!N6+'05_Projekte'!O6) | F6: =IF(A6="","",'05_Projekte'!AA6) | G6: =IF(A6="","",F6-E6) | H6: =IF(A6="","",C6-E6) | I6: =IF(A6="","",'05_Projekte'!AB6) | J6: =IF(A6="","",'05_Projekte'!AD6) | K6: =IF(A6="","",'05_Projekte'!AE6) | L6: =IF(A6="","",'05_Projekte'!AF6) | M6: =IF(A6="","",'05_Projekte'!AG6) | N6: =IF(A6="","",IF(OR(J6<0.08,G6>0,M6>50000),"PRÜFEN","OK"))
A7: =IF('05_Projekte'!A7="","",'05_Projekte'!A7) | B7: =IF(A7="","",'05_Projekte'!B7) | C7: =IF(A7="","",'05_Projekte'!V7) | D7: =IF(A7="","",'05_Projekte'!W7) | E7: =IF(A7="","",'05_Projekte'!K7+'05_Projekte'!L7+'05_Projekte'!M7+'05_Projekte'!N7+'05_Projekte'!O7) | F7: =IF(A7="","",'05_Projekte'!AA7) | G7: =IF(A7="","",F7-E7) | H7: =IF(A7="","",C7-E7) | I7: =IF(A7="","",'05_Projekte'!AB7) | J7: =IF(A7="","",'05_Projekte'!AD7) | K7: =IF(A7="","",'05_Projekte'!AE7) | L7: =IF(A7="","",'05_Projekte'!AF7) | M7: =IF(A7="","",'05_Projekte'!AG7) | N7: =IF(A7="","",IF(OR(J7<0.08,G7>0,M7>50000),"PRÜFEN","OK"))
A8: =IF('05_Projekte'!A8="","",'05_Projekte'!A8) | B8: =IF(A8="","",'05_Projekte'!B8) | C8: =IF(A8="","",'05_Projekte'!V8) | D8: =IF(A8="","",'05_Projekte'!W8) | E8: =IF(A8="","",'05_Projekte'!K8+'05_Projekte'!L8+'05_Projekte'!M8+'05_Projekte'!N8+'05_Projekte'!O8) | F8: =IF(A8="","",'05_Projekte'!AA8) | G8: =IF(A8="","",F8-E8) | H8: =IF(A8="","",C8-E8) | I8: =IF(A8="","",'05_Projekte'!AB8) | J8: =IF(A8="","",'05_Projekte'!AD8) | K8: =IF(A8="","",'05_Projekte'!AE8) | L8: =IF(A8="","",'05_Projekte'!AF8) | M8: =IF(A8="","",'05_Projekte'!AG8) | N8: =IF(A8="","",IF(OR(J8<0.08,G8>0,M8>50000),"PRÜFEN","OK"))
A9: =IF('05_Projekte'!A9="","",'05_Projekte'!A9) | B9: =IF(A9="","",'05_Projekte'!B9) | C9: =IF(A9="","",'05_Projekte'!V9) | D9: =IF(A9="","",'05_Projekte'!W9) | E9: =IF(A9="","",'05_Projekte'!K9+'05_Projekte'!L9+'05_Projekte'!M9+'05_Projekte'!N9+'05_Projekte'!O9) | F9: =IF(A9="","",'05_Projekte'!AA9) | G9: =IF(A9="","",F9-E9) | H9: =IF(A9="","",C9-E9) | I9: =IF(A9="","",'05_Projekte'!AB9) | J9: =IF(A9="","",'05_Projekte'!AD9) | K9: =IF(A9="","",'05_Projekte'!AE9) | L9: =IF(A9="","",'05_Projekte'!AF9) | M9: =IF(A9="","",'05_Projekte'!AG9) | N9: =IF(A9="","",IF(OR(J9<0.08,G9>0,M9>50000),"PRÜFEN","OK"))
A10: =IF('05_Projekte'!A10="","",'05_Projekte'!A10) | B10: =IF(A10="","",'05_Projekte'!B10) | C10: =IF(A10="","",'05_Projekte'!V10) | D10: =IF(A10="","",'05_Projekte'!W10) | E10: =IF(A10="","",'05_Projekte'!K10+'05_Projekte'!L10+'05_Projekte'!M10+'05_Projekte'!N10+'05_Projekte'!O10) | F10: =IF(A10="","",'05_Projekte'!AA10) | G10: =IF(A10="","",F10-E10) | H10: =IF(A10="","",C10-E10) | I10: =IF(A10="","",'05_Projekte'!AB10) | J10: =IF(A10="","",'05_Projekte'!AD10) | K10: =IF(A10="","",'05_Projekte'!AE10) | L10: =IF(A10="","",'05_Projekte'!AF10) | M10: =IF(A10="","",'05_Projekte'!AG10) | N10: =IF(A10="","",IF(OR(J10<0.08,G10>0,M10>50000),"PRÜFEN","OK"))
A11: =IF('05_Projekte'!A11="","",'05_Projekte'!A11) | B11: =IF(A11="","",'05_Projekte'!B11) | C11: =IF(A11="","",'05_Projekte'!V11) | D11: =IF(A11="","",'05_Projekte'!W11) | E11: =IF(A11="","",'05_Projekte'!K11+'05_Projekte'!L11+'05_Projekte'!M11+'05_Projekte'!N11+'05_Projekte'!O11) | F11: =IF(A11="","",'05_Projekte'!AA11) | G11: =IF(A11="","",F11-E11) | H11: =IF(A11="","",C11-E11) | I11: =IF(A11="","",'05_Projekte'!AB11) | J11: =IF(A11="","",'05_Projekte'!AD11) | K11: =IF(A11="","",'05_Projekte'!AE11) | L11: =IF(A11="","",'05_Projekte'!AF11) | M11: =IF(A11="","",'05_Projekte'!AG11) | N11: =IF(A11="","",IF(OR(J11<0.08,G11>0,M11>50000),"PRÜFEN","OK"))
A12: =IF('05_Projekte'!A12="","",'05_Projekte'!A12) | B12: =IF(A12="","",'05_Projekte'!B12) | C12: =IF(A12="","",'05_Projekte'!V12) | D12: =IF(A12="","",'05_Projekte'!W12) | E12: =IF(A12="","",'05_Projekte'!K12+'05_Projekte'!L12+'05_Projekte'!M12+'05_Projekte'!N12+'05_Projekte'!O12) | F12: =IF(A12="","",'05_Projekte'!AA12) | G12: =IF(A12="","",F12-E12) | H12: =IF(A12="","",C12-E12) | I12: =IF(A12="","",'05_Projekte'!AB12) | J12: =IF(A12="","",'05_Projekte'!AD12) | K12: =IF(A12="","",'05_Projekte'!AE12) | L12: =IF(A12="","",'05_Projekte'!AF12) | M12: =IF(A12="","",'05_Projekte'!AG12) | N12: =IF(A12="","",IF(OR(J12<0.08,G12>0,M12>50000),"PRÜFEN","OK"))
A13: =IF('05_Projekte'!A13="","",'05_Projekte'!A13) | B13: =IF(A13="","",'05_Projekte'!B13) | C13: =IF(A13="","",'05_Projekte'!V13) | D13: =IF(A13="","",'05_Projekte'!W13) | E13: =IF(A13="","",'05_Projekte'!K13+'05_Projekte'!L13+'05_Projekte'!M13+'05_Projekte'!N13+'05_Projekte'!O13) | F13: =IF(A13="","",'05_Projekte'!AA13) | G13: =IF(A13="","",F13-E13) | H13: =IF(A13="","",C13-E13) | I13: =IF(A13="","",'05_Projekte'!AB13) | J13: =IF(A13="","",'05_Projekte'!AD13) | K13: =IF(A13="","",'05_Projekte'!AE13) | L13: =IF(A13="","",'05_Projekte'!AF13) | M13: =IF(A13="","",'05_Projekte'!AG13) | N13: =IF(A13="","",IF(OR(J13<0.08,G13>0,M13>50000),"PRÜFEN","OK"))
A14: =IF('05_Projekte'!A14="","",'05_Projekte'!A14) | B14: =IF(A14="","",'05_Projekte'!B14) | C14: =IF(A14="","",'05_Projekte'!V14) | D14: =IF(A14="","",'05_Projekte'!W14) | E14: =IF(A14="","",'05_Projekte'!K14+'05_Projekte'!L14+'05_Projekte'!M14+'05_Projekte'!N14+'05_Projekte'!O14) | F14: =IF(A14="","",'05_Projekte'!AA14) | G14: =IF(A14="","",F14-E14) | H14: =IF(A14="","",C14-E14) | I14: =IF(A14="","",'05_Projekte'!AB14) | J14: =IF(A14="","",'05_Projekte'!AD14) | K14: =IF(A14="","",'05_Projekte'!AE14) | L14: =IF(A14="","",'05_Projekte'!AF14) | M14: =IF(A14="","",'05_Projekte'!AG14) | N14: =IF(A14="","",IF(OR(J14<0.08,G14>0,M14>50000),"PRÜFEN","OK"))
A15: =IF('05_Projekte'!A15="","",'05_Projekte'!A15) | B15: =IF(A15="","",'05_Projekte'!B15) | C15: =IF(A15="","",'05_Projekte'!V15) | D15: =IF(A15="","",'05_Projekte'!W15) | E15: =IF(A15="","",'05_Projekte'!K15+'05_Projekte'!L15+'05_Projekte'!M15+'05_Projekte'!N15+'05_Projekte'!O15) | F15: =IF(A15="","",'05_Projekte'!AA15) | G15: =IF(A15="","",F15-E15) | H15: =IF(A15="","",C15-E15) | I15: =IF(A15="","",'05_Projekte'!AB15) | J15: =IF(A15="","",'05_Projekte'!AD15) | K15: =IF(A15="","",'05_Projekte'!AE15) | L15: =IF(A15="","",'05_Projekte'!AF15) | M15: =IF(A15="","",'05_Projekte'!AG15) | N15: =IF(A15="","",IF(OR(J15<0.08,G15>0,M15>50000),"PRÜFEN","OK"))
... A53: =IF('05_Projekte'!A53="","",'05_Projekte'!A53) | B53: =IF(A53="","",'05_Projekte'!B53) | C53: =IF(A53="","",'05_Projekte'!V53) | D53: =IF(A53="","",'05_Projekte'!W53) | E53: =IF(A53="","",'05_Projekte'!K53+'05_Projekte'!L53+'05_Projekte'!M53+'05_Projekte'!N53+'05_Projekte'!O53) | F53: =IF(A53="","",'05_Projekte'!AA53) | G53: =IF(A53="","",F53-E53) | H53: =IF(A53="","",C53-E53) | I53: =IF(A53="","",'05_Projekte'!AB53) | J53: =IF(A53="","",'05_Projekte'!AD53) | K53: =IF(A53="","",'05_Projekte'!AE53) | L53: =IF(A53="","",'05_Projekte'!AF53) | M53: =IF(A53="","",'05_Projekte'!AG53) | N53: =IF(A53="","",IF(OR(J53<0.08,G53>0,M53>50000),"PRÜFEN","OK"))

Sheet 20_Liquiditaet
A1: Liquiditätsplanung 13 Wochen + 12 Monate
A2: Gelbe Zellen = Disposition ( savis, bekannte Zahlungen, Lohnlauf ). Ampel gegen Mindestliquidität aus den Stammdaten.
A4: 13-Wochen-Liquidität (rollierend)
A5: Woche ab | B5: 46301 | C5: 46308 | D5: 46315 | E5: 46322 | F5: 46329 | G5: 46336 | H5: 46343 | I5: 46350 | J5: 46357 | K5: 46364 | L5: 46371 | M5: 46378 | N5: 46385
A6: Einzahlungen Kunden erwartet | B6: 142000 | C6: 185000 | D6: 0 | E6: 420000 | F6: 62000 | G6: 0 | H6: 248000 | I6: 0 | J6: 310000 | K6: 95000 | L6: 0 | M6: 180000 | N6: 220000 | O6: =SUM(B6:N6)
A7: Löhne / Soka / SV | B7: 0 | C7: 0 | D7: 0 | E7: 69110 | F7: 0 | G7: 0 | H7: 0 | I7: 69800 | J7: 0 | K7: 0 | L7: 0 | M7: 70500 | N7: 0 | O7: =SUM(B7:N7)
A8: Nachunternehmer / Kreditoren | B8: 23000 | C8: 18000 | D8: 45000 | E8: 28600 | F8: 15800 | G8: 12000 | H8: 34000 | I8: 22000 | J8: 41000 | K8: 19000 | L8: 15000 | M8: 28000 | N8: 21000 | O8: =SUM(B8:N8)
A9: Material / Baustoffe | B9: 14500 | C9: 26400 | D9: 8000 | E9: 6200 | F9: 18000 | G9: 22000 | H9: 31000 | I9: 16000 | J9: 27000 | K9: 14000 | L9: 9000 | M9: 24000 | N9: 17000 | O9: =SUM(B9:N9)
A10: Steuer / USt | B10: 0 | C10: 18640 | D10: 0 | E10: 0 | F10: 0 | G10: 21400 | H10: 0 | I10: 0 | J10: 0 | K10: 19800 | L10: 0 | M10: 0 | N10: 24000 | O10: =SUM(B10:N10)
A11: Miete, Leasing, Sonstiges | B11: 8200 | C11: 4500 | D11: 6200 | E11: 4800 | F11: 5100 | G11: 4300 | H11: 8900 | I11: 4700 | J11: 5200 | K11: 6100 | L11: 4400 | M11: 7800 | N11: 5000 | O11: =SUM(B11:N11)
A13: Anfangsbestand | B13: =AnfangsBank+'19_Cashflow'!I18 | C13: =B14 | D13: =C14 | E13: =D14 | F13: =E14 | G13: =F14 | H13: =G14 | I13: =H14 | J13: =I14 | ... N13: =M14
A14: Endbestand | B14: =B13+B6-B7-B8-B9-B10-B11 | C14: =C13+C6-C7-C8-C9-C10-C11 | D14: =D13+D6-D7-D8-D9-D10-D11 | E14: =E13+E6-E7-E8-E9-E10-E11 | F14: =F13+F6-F7-F8-F9-F10-F11 | G14: =G13+G6-G7-G8-G9-G10-G11 | H14: =H13+H6-H7-H8-H9-H10-H11 | I14: =I13+I6-I7-I8-I9-I10-I11 | ... N14: =N13+N6-N7-N8-N9-N10-N11
A15: vs. Mindestliquidität | B15: =B14-MindestLiq | C15: =C14-MindestLiq | D15: =D14-MindestLiq | E15: =E14-MindestLiq | F15: =F14-MindestLiq | G15: =G14-MindestLiq | H15: =H14-MindestLiq | I15: =I14-MindestLiq | ... N15: =N14-MindestLiq
A16: Status | B16: =IF(B14<MindestLiq,"ENGPASS",IF(B14<MindestLiq*1.25,"ENG","OK")) | C16: =IF(C14<MindestLiq,"ENGPASS",IF(C14<MindestLiq*1.25,"ENG","OK")) | D16: =IF(D14<MindestLiq,"ENGPASS",IF(D14<MindestLiq*1.25,"ENG","OK")) | E16: =IF(E14<MindestLiq,"ENGPASS",IF(E14<MindestLiq*1.25,"ENG","OK")) | F16: =IF(F14<MindestLiq,"ENGPASS",IF(F14<MindestLiq*1.25,"ENG","OK")) | G16: =IF(G14<MindestLiq,"ENGPASS",IF(G14<MindestLiq*1.25,"ENG","OK")) | H16: =IF(H14<MindestLiq,"ENGPASS",IF(H14<MindestLiq*1.25,"ENG","OK")) | I16: =IF(I14<MindestLiq,"ENGPASS",IF(I14<MindestLiq*1.25,"ENG","OK")) | ... N16: =IF(N14<MindestLiq,"ENGPASS",IF(N14<MindestLiq*1.25,"ENG","OK"))
A18: 12-Monats-Liquidität
A19: Monat | B19: Jan | C19: Feb | D19: Mrz | E19: Apr | F19: Mai | G19: Jun | H19: Jul | I19: Aug | J19: Sep | K19: Okt | L19: Nov | M19: Dez
A20: Einzahlungen (Forecast brutto ca.) | B20: ='21_Forecast'!B20*1.19 | C20: ='21_Forecast'!C20*1.19 | D20: ='21_Forecast'!D20*1.19 | E20: ='21_Forecast'!E20*1.19 | F20: ='21_Forecast'!F20*1.19 | G20: ='21_Forecast'!G20*1.19 | H20: ='21_Forecast'!H20*1.19 | I20: ='21_Forecast'!I20*1.19 | ... M20: ='21_Forecast'!M20*1.19
A21: Auszahlungen gesamt | B21: ='21_Forecast'!B21+'21_Forecast'!B22+'21_Forecast'!B23+'21_Forecast'!B24+'21_Forecast'!B25 | C21: ='21_Forecast'!C21+'21_Forecast'!C22+'21_Forecast'!C23+'21_Forecast'!C24+'21_Forecast'!C25 | D21: ='21_Forecast'!D21+'21_Forecast'!D22+'21_Forecast'!D23+'21_Forecast'!D24+'21_Forecast'!D25 | E21: ='21_Forecast'!E21+'21_Forecast'!E22+'21_Forecast'!E23+'21_Forecast'!E24+'21_Forecast'!E25 | F21: ='21_Forecast'!F21+'21_Forecast'!F22+'21_Forecast'!F23+'21_Forecast'!F24+'21_Forecast'!F25 | G21: ='21_Forecast'!G21+'21_Forecast'!G22+'21_Forecast'!G23+'21_Forecast'!G24+'21_Forecast'!G25 | H21: ='21_Forecast'!H21+'21_Forecast'!H22+'21_Forecast'!H23+'21_Forecast'!H24+'21_Forecast'!H25 | I21: ='21_Forecast'!I21+'21_Forecast'!I22+'21_Forecast'!I23+'21_Forecast'!I24+'21_Forecast'!I25 | ... M21: ='21_Forecast'!M21+'21_Forecast'!M22+'21_Forecast'!M23+'21_Forecast'!M24+'21_Forecast'!M25
A22: Saldo Monat | B22: =B20-B21 | C22: =C20-C21 | D22: =D20-D21 | E22: =E20-E21 | F22: =F20-F21 | G22: =G20-G21 | H22: =H20-H21 | I22: =I20-I21 | ... M22: =M20-M21
A23: Bestand kumuliert | B23: =AnfangsBank+B22 | C23: =B23+C22 | D23: =C23+D22 | E23: =D23+E22 | F23: =E23+F22 | G23: =F23+G22 | H23: =G23+H22 | I23: =H23+I22 | J23: =I23+J22 | ... M23: =L23+M22

Sheet 19_Cashflow
A1: Cashflow-Rechnung
A2: Operativer, investiver und finanzieller Cashflow aus Zahlungen — Monatsscheiben für das Geschäftsjahr
A4: Position | B4: Jan | C4: Feb | D4: Mrz | E4: Apr | F4: Mai | G4: Jun | H4: Jul | I4: Aug | J4: Sep | K4: Okt | L4: Nov | M4: Dez | N4: GJ 2026
A5: Einzahlungen Kunden | B5: =SUMIFS('15_Zahlungen'!$F:$F,'15_Zahlungen'!$C:$C,"Eingang",'15_Zahlungen'!$I:$I,1,'15_Zahlungen'!$J:$J,GJ) | C5: =SUMIFS('15_Zahlungen'!$F:$F,'15_Zahlungen'!$C:$C,"Eingang",'15_Zahlungen'!$I:$I,2,'15_Zahlungen'!$J:$J,GJ) | D5: =SUMIFS('15_Zahlungen'!$F:$F,'15_Zahlungen'!$C:$C,"Eingang",'15_Zahlungen'!$I:$I,3,'15_Zahlungen'!$J:$J,GJ) | E5: =SUMIFS('15_Zahlungen'!$F:$F,'15_Zahlungen'!$C:$C,"Eingang",'15_Zahlungen'!$I:$I,4,'15_Zahlungen'!$J:$J,GJ) | F5: =SUMIFS('15_Zahlungen'!$F:$F,'15_Zahlungen'!$C:$C,"Eingang",'15_Zahlungen'!$I:$I,5,'15_Zahlungen'!$J:$J,GJ) | G5: =SUMIFS('15_Zahlungen'!$F:$F,'15_Zahlungen'!$C:$C,"Eingang",'15_Zahlungen'!$I:$I,6,'15_Zahlungen'!$J:$J,GJ) | H5: =SUMIFS('15_Zahlungen'!$F:$F,'15_Zahlungen'!$C:$C,"Eingang",'15_Zahlungen'!$I:$I,7,'15_Zahlungen'!$J:$J,GJ) | I5: =SUMIFS('15_Zahlungen'!$F:$F,'15_Zahlungen'!$C:$C,"Eingang",'15_Zahlungen'!$I:$I,8,'15_Zahlungen'!$J:$J,GJ) | J5: =SUMIFS('15_Zahlungen'!$F:$F,'15_Zahlungen'!$C:$C,"Eingang",'15_Zahlungen'!$I:$I,9,'15_Zahlungen'!$J:$J,GJ) | K5: =SUMIFS('15_Zahlungen'!$F:$F,'15_Zahlungen'!$C:$C,"Eingang",'15_Zahlungen'!$I:$I,10,'15_Zahlungen'!$J:$J,GJ) | L5: =SUMIFS('15_Zahlungen'!$F:$F,'15_Zahlungen'!$C:$C,"Eingang",'15_Zahlungen'!$I:$I,11,'15_Zahlungen'!$J:$J,GJ) | M5: =SUMIFS('15_Zahlungen'!$F:$F,'15_Zahlungen'!$C:$C,"Eingang",'15_Zahlungen'!$I:$I,12,'15_Zahlungen'!$J:$J,GJ) | N5: =SUM(B5:M5)
A6: sonstige Einzahlungen | B6: =SUMIFS('15_Zahlungen'!$F:$F,'15_Zahlungen'!$C:$C,"Eingang",'15_Zahlungen'!$I:$I,1,'15_Zahlungen'!$J:$J,GJ,'15_Zahlungen'!$D:$D,"") | C6: =SUMIFS('15_Zahlungen'!$F:$F,'15_Zahlungen'!$C:$C,"Eingang",'15_Zahlungen'!$I:$I,2,'15_Zahlungen'!$J:$J,GJ,'15_Zahlungen'!$D:$D,"") | D6: =SUMIFS('15_Zahlungen'!$F:$F,'15_Zahlungen'!$C:$C,"Eingang",'15_Zahlungen'!$I:$I,3,'15_Zahlungen'!$J:$J,GJ,'15_Zahlungen'!$D:$D,"") | E6: =SUMIFS('15_Zahlungen'!$F:$F,'15_Zahlungen'!$C:$C,"Eingang",'15_Zahlungen'!$I:$I,4,'15_Zahlungen'!$J:$J,GJ,'15_Zahlungen'!$D:$D,"") | F6: =SUMIFS('15_Zahlungen'!$F:$F,'15_Zahlungen'!$C:$C,"Eingang",'15_Zahlungen'!$I:$I,5,'15_Zahlungen'!$J:$J,GJ,'15_Zahlungen'!$D:$D,"") | G6: =SUMIFS('15_Zahlungen'!$F:$F,'15_Zahlungen'!$C:$C,"Eingang",'15_Zahlungen'!$I:$I,6,'15_Zahlungen'!$J:$J,GJ,'15_Zahlungen'!$D:$D,"") | H6: =SUMIFS('15_Zahlungen'!$F:$F,'15_Zahlungen'!$C:$C,"Eingang",'15_Zahlungen'!$I:$I,7,'15_Zahlungen'!$J:$J,GJ,'15_Zahlungen'!$D:$D,"") | I6: =SUMIFS('15_Zahlungen'!$F:$F,'15_Zahlungen'!$C:$C,"Eingang",'15_Zahlungen'!$I:$I,8,'15_Zahlungen'!$J:$J,GJ,'15_Zahlungen'!$D:$D,"") | J6: =SUMIFS('15_Zahlungen'!$F:$F,'15_Zahlungen'!$C:$C,"Eingang",'15_Zahlungen'!$I:$I,9,'15_Zahlungen'!$J:$J,GJ,'15_Zahlungen'!$D:$D,"") | K6: =SUMIFS('15_Zahlungen'!$F:$F,'15_Zahlungen'!$C:$C,"Eingang",'15_Zahlungen'!$I:$I,10,'15_Zahlungen'!$J:$J,GJ,'15_Zahlungen'!$D:$D,"") | L6: =SUMIFS('15_Zahlungen'!$F:$F,'15_Zahlungen'!$C:$C,"Eingang",'15_Zahlungen'!$I:$I,11,'15_Zahlungen'!$J:$J,GJ,'15_Zahlungen'!$D:$D,"") | M6: =SUMIFS('15_Zahlungen'!$F:$F,'15_Zahlungen'!$C:$C,"Eingang",'15_Zahlungen'!$I:$I,12,'15_Zahlungen'!$J:$J,GJ,'15_Zahlungen'!$D:$D,"") | N6: =SUM(B6:M6)
A7: Auszahlungen Lieferanten / NU | B7: =SUMIFS('15_Zahlungen'!$F:$F,'15_Zahlungen'!$C:$C,"Ausgang",'15_Zahlungen'!$I:$I,1,'15_Zahlungen'!$J:$J,GJ)-SUMIFS('15_Zahlungen'!$F:$F,'15_Zahlungen'!$C:$C,"Ausgang",'15_Zahlungen'!$I:$I,1,'15_Zahlungen'!$J:$J,GJ,'15_Zahlungen'!$E:$E,"Personal")-SUMIFS('15_Zahlungen'!$F:$F,'15_Zahlungen'!$C:$C,"Ausgang",'15_Zahlungen'!$I:$I,1,'15_Zahlungen'!$J:$J,GJ,'15_Zahlungen'!$E:$E,"Finanzamt")-SUMIFS('15_Zahlungen'!$F:$F,'15_Zahlungen'!$C:$C,"Ausgang",'15_Zahlungen'!$I:$I,1,'15_Zahlungen'!$J:$J,GJ,'15_Zahlungen'!$E:$E,"Sozialkasse") | C7: =SUMIFS('15_Zahlungen'!$F:$F,'15_Zahlungen'!$C:$C,"Ausgang",'15_Zahlungen'!$I:$I,2,'15_Zahlungen'!$J:$J,GJ)-SUMIFS('15_Zahlungen'!$F:$F,'15_Zahlungen'!$C:$C,"Ausgang",'15_Zahlungen'!$I:$I,2,'15_Zahlungen'!$J:$J,GJ,'15_Zahlungen'!$E:$E,"Personal")-SUMIFS('15_Zahlungen'!$F:$F,'15_Zahlungen'!$C:$C,"Ausgang",'15_Zahlungen'!$I:$I,2,'15_Zahlungen'!$J:$J,GJ,'15_Zahlungen'!$E:$E,"Finanzamt")-SUMIFS('15_Zahlungen'!$F:$F,'15_Zahlungen'!$C:$C,"Ausgang",'15_Zahlungen'!$I:$I,2,'15_Zahlungen'!$J:$J,GJ,'15_Zahlungen'!$E:$E,"Sozialkasse") | D7: =SUMIFS('15_Zahlungen'!$F:$F,'15_Zahlungen'!$C:$C,"Ausgang",'15_Zahlungen'!$I:$I,3,'15_Zahlungen'!$J:$J,GJ)-SUMIFS('15_Zahlungen'!$F:$F,'15_Zahlungen'!$C:$C,"Ausgang",'15_Zahlungen'!$I:$I,3,'15_Zahlungen'!$J:$J,GJ,'15_Zahlungen'!$E:$E,"Personal")-SUMIFS('15_Zahlungen'!$F:$F,'15_Zahlungen'!$C:$C,"Ausgang",'15_Zahlungen'!$I:$I,3,'15_Zahlungen'!$J:$J,GJ,'15_Zahlungen'!$E:$E,"Finanzamt")-SUMIFS('15_Zahlungen'!$F:$F,'15_Zahlungen'!$C:$C,"Ausgang",'15_Zahlungen'!$I:$I,3,'15_Zahlungen'!$J:$J,GJ,'15_Zahlungen'!$E:$E,"Sozialkasse") | E7: =SUMIFS('15_Zahlungen'!$F:$F,'15_Zahlungen'!$C:$C,"Ausgang",'15_Zahlungen'!$I:$I,4,'15_Zahlungen'!$J:$J,GJ)-SUMIFS('15_Zahlungen'!$F:$F,'15_Zahlungen'!$C:$C,"Ausgang",'15_Zahlungen'!$I:$I,4,'15_Zahlungen'!$J:$J,GJ,'15_Zahlungen'!$E:$E,"Personal")-SUMIFS('15_Zahlungen'!$F:$F,'15_Zahlungen'!$C:$C,"Ausgang",'15_Zahlungen'!$I:$I,4,'15_Zahlungen'!$J:$J,GJ,'15_Zahlungen'!$E:$E,"Finanzamt")-SUMIFS('15_Zahlungen'!$F:$F,'15_Zahlungen'!$C:$C,"Ausgang",'15_Zahlungen'!$I:$I,4,'15_Zahlungen'!$J:$J,GJ,'15_Zahlungen'!$E:$E,"Sozialkasse") | F7: =SUMIFS('15_Zahlungen'!$F:$F,'15_Zahlungen'!$C:$C,"Ausgang",'15_Zahlungen'!$I:$I,5,'15_Zahlungen'!$J:$J,GJ)-SUMIFS('15_Zahlungen'!$F:$F,'15_Zahlungen'!$C:$C,"Ausgang",'15_Zahlungen'!$I:$I,5,'15_Zahlungen'!$J:$J,GJ,'15_Zahlungen'!$E:$E,"Personal")-SUMIFS('15_Zahlungen'!$F:$F,'15_Zahlungen'!$C:$C,"Ausgang",'15_Zahlungen'!$I:$I,5,'15_Zahlungen'!$J:$J,GJ,'15_Zahlungen'!$E:$E,"Finanzamt")-SUMIFS('15_Zahlungen'!$F:$F,'15_Zahlungen'!$C:$C,"Ausgang",'15_Zahlungen'!$I:$I,5,'15_Zahlungen'!$J:$J,GJ,'15_Zahlungen'!$E:$E,"Sozialkasse") | G7: =SUMIFS('15_Zahlungen'!$F:$F,'15_Zahlungen'!$C:$C,"Ausgang",'15_Zahlungen'!$I:$I,6,'15_Zahlungen'!$J:$J,GJ)-SUMIFS('15_Zahlungen'!$F:$F,'15_Zahlungen'!$C:$C,"Ausgang",'15_Zahlungen'!$I:$I,6,'15_Zahlungen'!$J:$J,GJ,'15_Zahlungen'!$E:$E,"Personal")-SUMIFS('15_Zahlungen'!$F:$F,'15_Zahlungen'!$C:$C,"Ausgang",'15_Zahlungen'!$I:$I,6,'15_Zahlungen'!$J:$J,GJ,'15_Zahlungen'!$E:$E,"Finanzamt")-SUMIFS('15_Zahlungen'!$F:$F,'15_Zahlungen'!$C:$C,"Ausgang",'15_Zahlungen'!$I:$I,6,'15_Zahlungen'!$J:$J,GJ,'15_Zahlungen'!$E:$E,"Sozialkasse") | H7: =SUMIFS('15_Zahlungen'!$F:$F,'15_Zahlungen'!$C:$C,"Ausgang",'15_Zahlungen'!$I:$I,7,'15_Zahlungen'!$J:$J,GJ)-SUMIFS('15_Zahlungen'!$F:$F,'15_Zahlungen'!$C:$C,"Ausgang",'15_Zahlungen'!$I:$I,7,'15_Zahlungen'!$J:$J,GJ,'15_Zahlungen'!$E:$E,"Personal")-SUMIFS('15_Zahlungen'!$F:$F,'15_Zahlungen'!$C:$C,"Ausgang",'15_Zahlungen'!$I:$I,7,'15_Zahlungen'!$J:$J,GJ,'15_Zahlungen'!$E:$E,"Finanzamt")-SUMIFS('15_Zahlungen'!$F:$F,'15_Zahlungen'!$C:$C,"Ausgang",'15_Zahlungen'!$I:$I,7,'15_Zahlungen'!$J:$J,GJ,'15_Zahlungen'!$E:$E,"Sozialkasse") | I7: =SUMIFS('15_Zahlungen'!$F:$F,'15_Zahlungen'!$C:$C,"Ausgang",'15_Zahlungen'!$I:$I,8,'15_Zahlungen'!$J:$J,GJ)-SUMIFS('15_Zahlungen'!$F:$F,'15_Zahlungen'!$C:$C,"Ausgang",'15_Zahlungen'!$I:$I,8,'15_Zahlungen'!$J:$J,GJ,'15_Zahlungen'!$E:$E,"Personal")-SUMIFS('15_Zahlungen'!$F:$F,'15_Zahlungen'!$C:$C,"Ausgang",'15_Zahlungen'!$I:$I,8,'15_Zahlungen'!$J:$J,GJ,'15_Zahlungen'!$E:$E,"Finanzamt")-SUMIFS('15_Zahlungen'!$F:$F,'15_Zahlungen'!$C:$C,"Ausgang",'15_Zahlungen'!$I:$I,8,'15_Zahlungen'!$J:$J,GJ,'15_Zahlungen'!$E:$E,"Sozialkasse") | J7: =SUMIFS('15_Zahlungen'!$F:$F,'15_Zahlungen'!$C:$C,"Ausgang",'15_Zahlungen'!$I:$I,9,'15_Zahlungen'!$J:$J,GJ)-SUMIFS('15_Zahlungen'!$F:$F,'15_Zahlungen'!$C:$C,"Ausgang",'15_Zahlungen'!$I:$I,9,'15_Zahlungen'!$J:$J,GJ,'15_Zahlungen'!$E:$E,"Personal")-SUMIFS('15_Zahlungen'!$F:$F,'15_Zahlungen'!$C:$C,"Ausgang",'15_Zahlungen'!$I:$I,9,'15_Zahlungen'!$J:$J,GJ,'15_Zahlungen'!$E:$E,"Finanzamt")-SUMIFS('15_Zahlungen'!$F:$F,'15_Zahlungen'!$C:$C,"Ausgang",'15_Zahlungen'!$I:$I,9,'15_Zahlungen'!$J:$J,GJ,'15_Zahlungen'!$E:$E,"Sozialkasse") | K7: =SUMIFS('15_Zahlungen'!$F:$F,'15_Zahlungen'!$C:$C,"Ausgang",'15_Zahlungen'!$I:$I,10,'15_Zahlungen'!$J:$J,GJ)-SUMIFS('15_Zahlungen'!$F:$F,'15_Zahlungen'!$C:$C,"Ausgang",'15_Zahlungen'!$I:$I,10,'15_Zahlungen'!$J:$J,GJ,'15_Zahlungen'!$E:$E,"Personal")-SUMIFS('15_Zahlungen'!$F:$F,'15_Zahlungen'!$C:$C,"Ausgang",'15_Zahlungen'!$I:$I,10,'15_Zahlungen'!$J:$J,GJ,'15_Zahlungen'!$E:$E,"Finanzamt")-SUMIFS('15_Zahlungen'!$F:$F,'15_Zahlungen'!$C:$C,"Ausgang",'15_Zahlungen'!$I:$I,10,'15_Zahlungen'!$J:$J,GJ,'15_Zahlungen'!$E:$E,"Sozialkasse") | L7: =SUMIFS('15_Zahlungen'!$F:$F,'15_Zahlungen'!$C:$C,"Ausgang",'15_Zahlungen'!$I:$I,11,'15_Zahlungen'!$J:$J,GJ)-SUMIFS('15_Zahlungen'!$F:$F,'15_Zahlungen'!$C:$C,"Ausgang",'15_Zahlungen'!$I:$I,11,'15_Zahlungen'!$J:$J,GJ,'15_Zahlungen'!$E:$E,"Personal")-SUMIFS('15_Zahlungen'!$F:$F,'15_Zahlungen'!$C:$C,"Ausgang",'15_Zahlungen'!$I:$I,11,'15_Zahlungen'!$J:$J,GJ,'15_Zahlungen'!$E:$E,"Finanzamt")-SUMIFS('15_Zahlungen'!$F:$F,'15_Zahlungen'!$C:$C,"Ausgang",'15_Zahlungen'!$I:$I,11,'15_Zahlungen'!$J:$J,GJ,'15_Zahlungen'!$E:$E,"Sozialkasse") | M7: =SUMIFS('15_Zahlungen'!$F:$F,'15_Zahlungen'!$C:$C,"Ausgang",'15_Zahlungen'!$I:$I,12,'15_Zahlungen'!$J:$J,GJ)-SUMIFS('15_Zahlungen'!$F:$F,'15_Zahlungen'!$C:$C,"Ausgang",'15_Zahlungen'!$I:$I,12,'15_Zahlungen'!$J:$J,GJ,'15_Zahlungen'!$E:$E,"Personal")-SUMIFS('15_Zahlungen'!$F:$F,'15_Zahlungen'!$C:$C,"Ausgang",'15_Zahlungen'!$I:$I,12,'15_Zahlungen'!$J:$J,GJ,'15_Zahlungen'!$E:$E,"Finanzamt")-SUMIFS('15_Zahlungen'!$F:$F,'15_Zahlungen'!$C:$C,"Ausgang",'15_Zahlungen'!$I:$I,12,'15_Zahlungen'!$J:$J,GJ,'15_Zahlungen'!$E:$E,"Sozialkasse") | N7: =SUM(B7:M7)
A8: Löhne / Gehälter | B8: =SUMIFS('15_Zahlungen'!$F:$F,'15_Zahlungen'!$C:$C,"Ausgang",'15_Zahlungen'!$I:$I,1,'15_Zahlungen'!$J:$J,GJ,'15_Zahlungen'!$E:$E,"Personal") | C8: =SUMIFS('15_Zahlungen'!$F:$F,'15_Zahlungen'!$C:$C,"Ausgang",'15_Zahlungen'!$I:$I,2,'15_Zahlungen'!$J:$J,GJ,'15_Zahlungen'!$E:$E,"Personal") | D8: =SUMIFS('15_Zahlungen'!$F:$F,'15_Zahlungen'!$C:$C,"Ausgang",'15_Zahlungen'!$I:$I,3,'15_Zahlungen'!$J:$J,GJ,'15_Zahlungen'!$E:$E,"Personal") | E8: =SUMIFS('15_Zahlungen'!$F:$F,'15_Zahlungen'!$C:$C,"Ausgang",'15_Zahlungen'!$I:$I,4,'15_Zahlungen'!$J:$J,GJ,'15_Zahlungen'!$E:$E,"Personal") | F8: =SUMIFS('15_Zahlungen'!$F:$F,'15_Zahlungen'!$C:$C,"Ausgang",'15_Zahlungen'!$I:$I,5,'15_Zahlungen'!$J:$J,GJ,'15_Zahlungen'!$E:$E,"Personal") | G8: =SUMIFS('15_Zahlungen'!$F:$F,'15_Zahlungen'!$C:$C,"Ausgang",'15_Zahlungen'!$I:$I,6,'15_Zahlungen'!$J:$J,GJ,'15_Zahlungen'!$E:$E,"Personal") | H8: =SUMIFS('15_Zahlungen'!$F:$F,'15_Zahlungen'!$C:$C,"Ausgang",'15_Zahlungen'!$I:$I,7,'15_Zahlungen'!$J:$J,GJ,'15_Zahlungen'!$E:$E,"Personal") | I8: =SUMIFS('15_Zahlungen'!$F:$F,'15_Zahlungen'!$C:$C,"Ausgang",'15_Zahlungen'!$I:$I,8,'15_Zahlungen'!$J:$J,GJ,'15_Zahlungen'!$E:$E,"Personal") | J8: =SUMIFS('15_Zahlungen'!$F:$F,'15_Zahlungen'!$C:$C,"Ausgang",'15_Zahlungen'!$I:$I,9,'15_Zahlungen'!$J:$J,GJ,'15_Zahlungen'!$E:$E,"Personal") | K8: =SUMIFS('15_Zahlungen'!$F:$F,'15_Zahlungen'!$C:$C,"Ausgang",'15_Zahlungen'!$I:$I,10,'15_Zahlungen'!$J:$J,GJ,'15_Zahlungen'!$E:$E,"Personal") | L8: =SUMIFS('15_Zahlungen'!$F:$F,'15_Zahlungen'!$C:$C,"Ausgang",'15_Zahlungen'!$I:$I,11,'15_Zahlungen'!$J:$J,GJ,'15_Zahlungen'!$E:$E,"Personal") | M8: =SUMIFS('15_Zahlungen'!$F:$F,'15_Zahlungen'!$C:$C,"Ausgang",'15_Zahlungen'!$I:$I,12,'15_Zahlungen'!$J:$J,GJ,'15_Zahlungen'!$E:$E,"Personal") | N8: =SUM(B8:M8)
