Workbook
Name Berichtswahrung: '00_Start'!$B$12
Name DD_Stichtag: '00_Start'!$B$8
Name DealImpact: '_Listen'!$L$2:$L$9
Name DokStatus: '_Listen'!$E$2:$E$7
Name JaNeinPruefen: '_Listen'!$D$2:$D$4
Name MassStatus: '_Listen'!$H$2:$H$6
Name Phase: '_Listen'!$C$2:$C$6
Name Prioritaet: '_Listen'!$B$2:$B$5
Name Pruefstatus: '_Listen'!$A$2:$A$7
Name QAStatus: '_Listen'!$I$2:$I$7
Name Reifegrad: '_Listen'!$M$2:$M$6
Name RisikoStatus: '_Listen'!$G$2:$G$6
Name Transaktionstyp: '_Listen'!$K$2:$K$8
Name Transaktionstyp_Auswahl: '00_Start'!$B$6
Name Vertragstyp: '_Listen'!$N$2:$N$11
Name Vertraulichkeit: '_Listen'!$J$2:$J$5
Name Vollstaendigkeit: '_Listen'!$F$2:$F$5
Name Zielunternehmen: '00_Start'!$B$5

Sheet _Listen
A1: Pruefstatus | B1: Prioritaet | C1: Phase | D1: JaNeinPruefen | E1: DokStatus | F1: Vollstaendigkeit | G1: RisikoStatus | H1: MassStatus | I1: QAStatus | J1: Vertraulichkeit | K1: Transaktionstyp | L1: DealImpact | M1: Reifegrad | N1: Vertragstyp
A2: Nicht begonnen | B2: Kritisch | C2: Screening | D2: Ja | E2: Nicht angefordert | F2: Ungeprüft | G2: Zu verifizieren | H2: Nicht gestartet | I2: Entwurf | J2: Normal | K2: Share Deal | L2: Bewertung/Kaufpreis | M2: 0 – Nicht vorhanden | N2: Kunde
A3: In Prüfung | B3: Hoch | C3: Vollprüfung | D3: Nein | E3: Angefordert | F3: Unvollständig | G3: Bestätigt | H3: In Arbeit | I3: Gesendet | J3: Vertraulich | K3: Asset Deal | L3: SPA/Haftung | M3: 1 – Ad hoc | N3: Lieferant
A4: Rückfrage | B4: Mittel | C4: Signing | D4: Zu prüfen | E4: Teilweise | F4: Plausibel | G4: Entkräftet | H4: Blockiert | I4: Teilbeantwortet | J4: Streng vertraulich | K4: Beteiligung | L4: Closing-Bedingung | M4: 2 – Definiert | N4: Finanzierung
A5: Blockiert | B5: Niedrig | C5: Closing | E5: Vollständig | F5: Verifiziert | G5: Mitigiert | H5: Erledigt | I5: Beantwortet | J5: Clean Team | K5: Carve-out | L5: Finanzierung | M5: 3 – Implementiert | N5: Miete
A6: Abgeschlossen | C6: Post-Closing | E6: Nicht verfügbar | G6: Akzeptiert | H6: Verworfen | I6: Nachfrage | K6: IPO | L6: Integration/100-Tage-Plan | M6: 4 – Gemessen/optimiert | N6: Lizenz
A7: Nicht anwendbar | E7: Nicht anwendbar | I7: Geschlossen | K7: Refinanzierung | L7: Abbruch/No-go | N7: IT/Cloud
K8: Sonstige | L8: Kein direkter | N8: Distribution
L9: Zu prüfen | N9: Kooperation/JV
N10: Versicherung
N11: Sonstige

Sheet 00_Start
A1: Due-Diligence-Arbeitsmappe
A2: Branchenneutrale, risikoorientierte Arbeitsvorlage. Gelbe Zellen sind Eingaben, blaue Zellen enthalten Formeln. Alle Vorschläge sind auf den konkreten Deal anzupassen.
A4: Projektparameter
A5: Zielunternehmen | D5: Empfohlener Ablauf
A6: Transaktionstyp | B6: Share Deal | D6: 1. Scope & Hypothesen | E6: Perimeter, Materialität, No-go-Kriterien und Workstreams freigeben.
A7: Käufer / Investor | D7: 2. Datenraum & Q&A | E7: Dokumente anfordern, Versionen kontrollieren, Lücken und Widersprüche eskalieren.
A8: DD-Stichtag | D8: 3. Analyse & Triangulation | E8: Management-Daten mit Verträgen, Hauptbuch, externen Quellen und Stichproben belegen.
A9: Projektleitung | D9: 4. Findings & Quantifizierung | E9: Sachverhalt, Evidenz, Ursache, Eintritt, Auswirkung und Exposure trennen.
A10: Version | B10: 1.0 | D10: 5. Deal-Entscheidung | E10: Preis, SPA-Schutz, Closing-Bedingungen, Finanzierung und No-go bewerten.
A11: Vertraulichkeit | B11: Streng vertraulich | D11: 6. Maßnahmen & Übergabe | E11: Owner, Frist, Budget, KPI sowie Day-1-/100-Tage-Plan festlegen.
A12: Berichtswährung | B12: EUR
A13: Materialitätsschwelle (€)
A15: Risiko-Scoring
A16: Wert | B16: Eintrittswahrscheinlichkeit | C16: Auswirkung | D16: Orientierung | E16: Risikoklasse = Eintritt × Auswirkung
A17: 1 | B17: Sehr gering | C17: Unwesentlich | D17: Kein relevanter Einfluss; normale Steuerung
A18: 2 | B18: Gering | C18: Begrenzt | D18: Unter Materialität; lokale Korrektur | E18: 1–4 | F18: Niedrig | G18: Dokumentieren / regulär überwachen
A19: 3 | B19: Möglich | C19: Wesentlich | D19: Management Attention; quantifizieren | E19: 5–9 | F19: Mittel | G19: Maßnahme mit Owner und Frist
A20: 4 | B20: Wahrscheinlich | C20: Schwerwiegend | D20: Deal-/SPA-relevant; IC-Eskalation | E20: 10–16 | F20: Hoch | G20: Quantifizieren und Deal-Schutz entscheiden
A21: 5 | B21: Sehr wahrscheinlich | C21: Existenz-/Deal-kritisch | D21: No-go oder zwingende Vorbedingung | E21: 17–25 | F21: Kritisch | G21: Sofort eskalieren; No-go/CP/Freistellung prüfen
A23: Nutzungshinweise
A24: • Prüfpunkte sind Hypothesen und keine Feststellungen. Findings erst nach belegbarer Evidenz eintragen.
A25: • Risikoscore nicht ausfüllen, bevor Eintritt und Auswirkung begründet sind. Exposure (Low/Base/High) separat quantifizieren.
A26: • Kaufpreisanpassung, Freistellung und operative Maßnahme dürfen dasselbe Risiko nicht unbemerkt doppelt erfassen.
A27: • Personenbezogene Daten minimieren; sensible HR-, Gesundheits- und Kundendaten nur über geeignete Clean-Team-Prozesse verarbeiten.
A28: • Die Vorlage ersetzt keine Rechts-, Steuer-, Wirtschaftsprüfungs-, Cyber- oder Umweltberatung. Rechtslage und Standards zum Transaktionszeitpunkt prüfen.

Sheet 00_Ausfüllhilfe
A1: Ausfüllhilfe & Feldhandbuch
A2: Startpunkt für die Bearbeitung: Tabellen filtern, gewünschtes Arbeitsblatt öffnen und Hinweise in den kommentierten Spaltenköpfen beachten.
A4: Schnellstart
A5: 1 | B5: Im Blatt 00_Start Zielunternehmen, Deal-Typ, Stichtag, Projektleitung, Währung und Materialität festlegen.
A6: 2 | B6: In 03_Dokumente die Request List versenden, Owner und Fristen setzen; Datenqualität und VDR-Pfade laufend pflegen.
A7: 3 | B7: In 02_Checkliste Status, Evidenz und Analyse dokumentieren. Ein Finding erst nach nachvollziehbarer Primärevidenz erfassen.
A8: 4 | B8: Bestätigte Risiken nach 04_Risiken übertragen bzw. dort bewerten: Eintritt, Auswirkung und Exposure Low/Base/High getrennt bestimmen.
A9: 5 | B9: In 05_Maßnahmen nur passende Vorschläge aktivieren; genau einen Owner, Termin, Budget, KPI und ein messbares Abnahmekriterium festlegen.
A10: 6 | B10: Dashboard und Entscheidungs-Gates vor Signing/Closing reviewen; Preis-, SPA-, Finanzierungs- und Integrationsfolgen beschließen.
A12: Farben und Bedienung
A13: Gelb | B13: Eingabe oder aktiv zu bestätigende Auswahl
A14: Hellblau | B14: Automatische Formel – nicht überschreiben
A15: Rot/Orange | B15: Eskalation, hohe Priorität oder überfälliger Punkt
A16: Kommentarindikator | B16: Spaltenkopf oder Feld auswählen/überfahren, um die kontextbezogene Ausfüllhilfe zu lesen
A18: Blattnavigation und Bearbeitungsreihenfolge
A19: Arbeitsblatt | B19: Zweck | C19: Wer füllt aus? | D19: Wann? | E19: Hauptausgabe
A20: 00_Start | B20: Projektparameter, Scoring und Grundregeln festlegen | C20: M&A-Projektleitung | D20: Projektstart / Scope-Änderung | E20: Freigegebene Projektbasis
A21: 00_Ausfüllhilfe | B21: Felddefinitionen, Beispiele und Qualitätsregeln nachschlagen | C21: Alle Bearbeiter | D21: Vor und während jeder Eingabe | E21: Einheitliche Datenerfassung
A22: 01_Dashboard | B22: Fortschritt und Entscheidungsreife überwachen | C22: PMO / Deal Lead | D22: Wöchentlich und vor Gates | E22: Management- und IC-Übersicht
A23: 02_Checkliste | B23: Alle Prüfhypothesen bearbeiten und Findings dokumentieren | C23: Workstream Leads | D23: Laufend | E23: Vollständiger DD-Status
A24: 03_Dokumente | B24: VDR-Anforderungen, Fristen und Datenqualität steuern | C24: PMO / Zielunternehmen | D24: Ab Scope-Freigabe | E24: Vollständige Request List
A25: 04_Risiken | B25: Bestätigte Risiken bewerten, quantifizieren und entscheiden | C25: Workstream Leads / Deal Lead | D25: Nach Evidenz | E25: Priorisiertes Risikoregister
A26: 05_Maßnahmen | B26: Mitigation, Deal-Schutz und Umsetzung nachhalten | C26: Maßnahmen-Owner | D26: Nach Finding / bis Closing | E26: Verbindlicher Aktionsplan
A27: 06_Q&A | B27: Offene Fragen und schriftliche Antworten steuern | C27: Prüfer / Management | D27: Während der Analyse | E27: Nachvollziehbarer Q&A-Audit-Trail
A28: 07_Finanzanalyse | B28: Historische Entwicklung, Cash Conversion und Bilanzkennzahlen analysieren | C28: Financial-DD-Team | D28: Nach Datenlieferung | E28: Normalisierte Finanzbasis
A29: 08_QoE | B29: EBITDA-Normalisierungen einzeln belegen und entscheiden | C29: Financial-DD-Team | D29: Nach GuV-/Kontenanalyse | E29: Reported-to-normalized Bridge
A30: 09_NWC_NetDebt | B30: NWC-Peg und Net-Debt-/Debt-like-Definition vorbereiten | C30: Finance / Legal | D30: Vor SPA-Verhandlung | E30: Closing-Mechanik
... A36: 15_Quellen | B36: Methodische und rechtliche Ausgangsquellen nachvollziehen | C36: Alle Workstreams | D36: Bei Methodik-/Rechtsfragen | E36: Quellenverzeichnis
A38: Detaillierte Feldhilfe – nach Arbeitsblatt oder Feld filtern
A39: Arbeitsblatt | B39: Feld / Spalte | C39: Bearbeitung | D39: Pflichtgrad | E39: Was eintragen? | F39: Beispiel | G39: Format | H39: Quelle / Nachweis | I39: Qualitätsregel / typischer Fehler
A40: 00_Start | B40: Zielunternehmen | C40: Eingabe | D40: Pflicht | E40: Vollständige rechtliche Firma des Prüfungsobjekts eintragen. | F40: Muster GmbH | G40: Text | H40: Handelsregister / Term Sheet | I40: Bei Carve-outs den exakten Perimeter ergänzen.
A41: 00_Start | B41: Transaktionstyp | C41: Eingabe | D41: Pflicht | E41: Geplante rechtliche bzw. wirtschaftliche Transaktionsform auswählen. | F41: Share Deal | G41: Dropdown | H41: Term Sheet / Strukturmemorandum | I41: Bei Mischformen die primäre Struktur auswählen und Details kommentieren.
A42: 00_Start | B42: Käufer / Investor | C42: Eingabe | D42: Pflicht | E42: Erwerbende Gesellschaft bzw. Investorengruppe nennen. | F42: Investor Holding GmbH | G42: Text | H42: Term Sheet | I42: Nicht nur den Projektnamen verwenden.
A43: 00_Start | B43: DD-Stichtag | C43: Eingabe | D43: Pflicht | E43: Informations- bzw. Bewertungsstichtag der Prüfung eintragen. | F43: 30.09.2026 | G43: Datum TT.MM.JJJJ | H43: Projektauftrag | I43: Nicht mit Signing- oder Closing-Datum verwechseln.
A44: 00_Start | B44: Projektleitung | C44: Eingabe | D44: Pflicht | E44: Gesamtverantwortliche Person mit Rolle nennen. | F44: Max Beispiel, M&A Director | G44: Text | H44: Projekt-RACI | I44: Genau eine Gesamtverantwortung festlegen.
A45: 00_Start | B45: Version | C45: Eingabe | D45: Pflicht | E45: Freigabestand der Arbeitsmappe führen. | F45: 1.1 | G45: Versionsnummer | H45: Dokumentenlenkung | I45: Bei materiellen Änderungen Version erhöhen.
A46: 00_Start | B46: Vertraulichkeit | C46: Eingabe | D46: Pflicht | E46: Höchste Schutzstufe für die gesamte Arbeitsmappe auswählen. | F46: Streng vertraulich | G46: Dropdown | H46: NDA / Clean-Team-Regeln | I46: Einzelblätter können eine höhere Schutzstufe benötigen.
A47: 00_Start | B47: Berichtswährung | C47: Eingabe | D47: Pflicht | E47: Einheitliche Währung für alle monetären Eingaben festlegen. | F47: EUR | G47: ISO-Währungscode | H47: Investment Case | I47: Fremdwährungsumrechnung und Stichtagskurs separat dokumentieren.
A48: 00_Start | B48: Materialitätsschwelle (€) | C48: Eingabe | D48: Pflicht | E48: Vom Deal-Team genehmigte quantitative Basisschwelle eintragen. | F48: 100000 | G48: Betrag in Berichtswährung | H48: DD-Scope / Risikotoleranz | I48: Qualitative No-go-Themen bleiben unabhängig vom Betrag wesentlich.
A49: 02_Checkliste | B49: ID | C49: Vorbelegt | D49: Automatisch | E49: Eindeutige Kennung beibehalten; nur beim Ergänzen neuer Zeilen fortlaufend vergeben. | F49: R-014 | G49: Text, eindeutig | H49: Arbeitsmappe | I49: Keine ID doppelt vergeben oder nachträglich umnummerieren.
...

Sheet 01_Dashboard
A1: Due-Diligence-Dashboard
A2: Automatische Übersicht aus Checkliste, Dokumenten-, Risiko- und Maßnahmenregistern. Excel berechnet die Kennzahlen beim Öffnen neu.
A3: Zielunternehmen | B3: =Zielunternehmen | E3: Transaktion | F3: =Transaktionstyp_Auswahl -> Share Deal | I3: Stichtag | J3: =DD_Stichtag | L3: Checklistenpunkte | M3: 156
A5: Prüfpunkte gesamt | E5: Abgeschlossen | I5: Fortschritt | M5: Risiko unbewertet
A6: =COUNTA('02_Checkliste'!$A$5:$A$1000) -> 156 | E6: =COUNTIF('02_Checkliste'!$J$5:$J$1000,"Abgeschlossen") -> 0 | I6: =IFERROR(COUNTIF('02_Checkliste'!$J$5:$J$1000,"Abgeschlossen")/COUNTA('02_Checkliste'!$A$5:$A$1000),0) -> 0 | M6: =COUNTIFS('02_Checkliste'!$A$5:$A$1000,"<>",'02_Checkliste'!$P$5:$P$1000,"") -> 156
A9: Hoch / kritisch | E9: Kritische Doks offen | I9: Maßnahmen überfällig | M9: Exposure Base
A10: =COUNTIF('02_Checkliste'!$P$5:$P$1000,"Hoch")+COUNTIF('02_Checkliste'!$P$5:$P$1000,"Kritisch") -> 0 | E10: =COUNTIFS('03_Dokumente'!$F$5:$F$1000,"Kritisch",'03_Dokumente'!$L$5:$L$1000,"<>Vollständig") -> 89 | I10: =COUNTIFS('05_Maßnahmen'!$L$5:$L$500,"<"&TODAY(),'05_Maßnahmen'!$L$5:$L$500,"<>",'05_Maßnahmen'!$M$5:$M$500,"<>Erledigt") -> 0 | M10: =SUM('04_Risiken'!$M$5:$M$500) -> 0
A13: Fortschritt nach Prüfbereich
A14: Prüfbereich | B14: Umfang | C14: Abgeschlossen | D14: Fortschritt | E14: Unbewertet | F14: Hoch/kritisch
A15: Transaktion & Scope | B15: =COUNTIF('02_Checkliste'!$B$5:$B$1000,"Transaktion & Scope") -> 8 | C15: =COUNTIFS('02_Checkliste'!$B$5:$B$1000,"Transaktion & Scope",'02_Checkliste'!$J$5:$J$1000,"Abgeschlossen") -> 0 | D15: =IFERROR(C15/B15,0) -> 0 | E15: =COUNTIFS('02_Checkliste'!$B$5:$B$1000,"Transaktion & Scope",'02_Checkliste'!$P$5:$P$1000,"") -> 8 | F15: =COUNTIFS('02_Checkliste'!$B$5:$B$1000,"Transaktion & Scope",'02_Checkliste'!$P$5:$P$1000,"Hoch")+COUNTIFS('02_Checkliste'!$B$5:$B$1000,"Transaktion & Scope",'02_Checkliste'!$P$5:$P$1000,"Kritisch") -> 0
A16: Corporate & Governance | B16: =COUNTIF('02_Checkliste'!$B$5:$B$1000,"Corporate & Governance") -> 9 | C16: =COUNTIFS('02_Checkliste'!$B$5:$B$1000,"Corporate & Governance",'02_Checkliste'!$J$5:$J$1000,"Abgeschlossen") -> 0 | D16: =IFERROR(C16/B16,0) -> 0 | E16: =COUNTIFS('02_Checkliste'!$B$5:$B$1000,"Corporate & Governance",'02_Checkliste'!$P$5:$P$1000,"") -> 9 | F16: =COUNTIFS('02_Checkliste'!$B$5:$B$1000,"Corporate & Governance",'02_Checkliste'!$P$5:$P$1000,"Hoch")+COUNTIFS('02_Checkliste'!$B$5:$B$1000,"Corporate & Governance",'02_Checkliste'!$P$5:$P$1000,"Kritisch") -> 0
A17: Financial | B17: =COUNTIF('02_Checkliste'!$B$5:$B$1000,"Financial") -> 16 | C17: =COUNTIFS('02_Checkliste'!$B$5:$B$1000,"Financial",'02_Checkliste'!$J$5:$J$1000,"Abgeschlossen") -> 0 | D17: =IFERROR(C17/B17,0) -> 0 | E17: =COUNTIFS('02_Checkliste'!$B$5:$B$1000,"Financial",'02_Checkliste'!$P$5:$P$1000,"") -> 16 | F17: =COUNTIFS('02_Checkliste'!$B$5:$B$1000,"Financial",'02_Checkliste'!$P$5:$P$1000,"Hoch")+COUNTIFS('02_Checkliste'!$B$5:$B$1000,"Financial",'02_Checkliste'!$P$5:$P$1000,"Kritisch") -> 0
A18: Commercial | B18: =COUNTIF('02_Checkliste'!$B$5:$B$1000,"Commercial") -> 10 | C18: =COUNTIFS('02_Checkliste'!$B$5:$B$1000,"Commercial",'02_Checkliste'!$J$5:$J$1000,"Abgeschlossen") -> 0 | D18: =IFERROR(C18/B18,0) -> 0 | E18: =COUNTIFS('02_Checkliste'!$B$5:$B$1000,"Commercial",'02_Checkliste'!$P$5:$P$1000,"") -> 10 | F18: =COUNTIFS('02_Checkliste'!$B$5:$B$1000,"Commercial",'02_Checkliste'!$P$5:$P$1000,"Hoch")+COUNTIFS('02_Checkliste'!$B$5:$B$1000,"Commercial",'02_Checkliste'!$P$5:$P$1000,"Kritisch") -> 0
A19: Tax | B19: =COUNTIF('02_Checkliste'!$B$5:$B$1000,"Tax") -> 11 | C19: =COUNTIFS('02_Checkliste'!$B$5:$B$1000,"Tax",'02_Checkliste'!$J$5:$J$1000,"Abgeschlossen") -> 0 | D19: =IFERROR(C19/B19,0) -> 0 | E19: =COUNTIFS('02_Checkliste'!$B$5:$B$1000,"Tax",'02_Checkliste'!$P$5:$P$1000,"") -> 11 | F19: =COUNTIFS('02_Checkliste'!$B$5:$B$1000,"Tax",'02_Checkliste'!$P$5:$P$1000,"Hoch")+COUNTIFS('02_Checkliste'!$B$5:$B$1000,"Tax",'02_Checkliste'!$P$5:$P$1000,"Kritisch") -> 0
A20: Legal | B20: =COUNTIF('02_Checkliste'!$B$5:$B$1000,"Legal") -> 13 | C20: =COUNTIFS('02_Checkliste'!$B$5:$B$1000,"Legal",'02_Checkliste'!$J$5:$J$1000,"Abgeschlossen") -> 0 | D20: =IFERROR(C20/B20,0) -> 0 | E20: =COUNTIFS('02_Checkliste'!$B$5:$B$1000,"Legal",'02_Checkliste'!$P$5:$P$1000,"") -> 13 | F20: =COUNTIFS('02_Checkliste'!$B$5:$B$1000,"Legal",'02_Checkliste'!$P$5:$P$1000,"Hoch")+COUNTIFS('02_Checkliste'!$B$5:$B$1000,"Legal",'02_Checkliste'!$P$5:$P$1000,"Kritisch") -> 0
A21: Operations | B21: =COUNTIF('02_Checkliste'!$B$5:$B$1000,"Operations") -> 9 | C21: =COUNTIFS('02_Checkliste'!$B$5:$B$1000,"Operations",'02_Checkliste'!$J$5:$J$1000,"Abgeschlossen") -> 0 | D21: =IFERROR(C21/B21,0) -> 0 | E21: =COUNTIFS('02_Checkliste'!$B$5:$B$1000,"Operations",'02_Checkliste'!$P$5:$P$1000,"") -> 9 | F21: =COUNTIFS('02_Checkliste'!$B$5:$B$1000,"Operations",'02_Checkliste'!$P$5:$P$1000,"Hoch")+COUNTIFS('02_Checkliste'!$B$5:$B$1000,"Operations",'02_Checkliste'!$P$5:$P$1000,"Kritisch") -> 0
A22: Supply Chain | B22: =COUNTIF('02_Checkliste'!$B$5:$B$1000,"Supply Chain") -> 7 | C22: =COUNTIFS('02_Checkliste'!$B$5:$B$1000,"Supply Chain",'02_Checkliste'!$J$5:$J$1000,"Abgeschlossen") -> 0 | D22: =IFERROR(C22/B22,0) -> 0 | E22: =COUNTIFS('02_Checkliste'!$B$5:$B$1000,"Supply Chain",'02_Checkliste'!$P$5:$P$1000,"") -> 7 | F22: =COUNTIFS('02_Checkliste'!$B$5:$B$1000,"Supply Chain",'02_Checkliste'!$P$5:$P$1000,"Hoch")+COUNTIFS('02_Checkliste'!$B$5:$B$1000,"Supply Chain",'02_Checkliste'!$P$5:$P$1000,"Kritisch") -> 0
A23: IT & Cyber | B23: =COUNTIF('02_Checkliste'!$B$5:$B$1000,"IT & Cyber") -> 12 | C23: =COUNTIFS('02_Checkliste'!$B$5:$B$1000,"IT & Cyber",'02_Checkliste'!$J$5:$J$1000,"Abgeschlossen") -> 0 | D23: =IFERROR(C23/B23,0) -> 0 | E23: =COUNTIFS('02_Checkliste'!$B$5:$B$1000,"IT & Cyber",'02_Checkliste'!$P$5:$P$1000,"") -> 12 | F23: =COUNTIFS('02_Checkliste'!$B$5:$B$1000,"IT & Cyber",'02_Checkliste'!$P$5:$P$1000,"Hoch")+COUNTIFS('02_Checkliste'!$B$5:$B$1000,"IT & Cyber",'02_Checkliste'!$P$5:$P$1000,"Kritisch") -> 0
A24: Datenschutz | B24: =COUNTIF('02_Checkliste'!$B$5:$B$1000,"Datenschutz") -> 7 | C24: =COUNTIFS('02_Checkliste'!$B$5:$B$1000,"Datenschutz",'02_Checkliste'!$J$5:$J$1000,"Abgeschlossen") -> 0 | D24: =IFERROR(C24/B24,0) -> 0 | E24: =COUNTIFS('02_Checkliste'!$B$5:$B$1000,"Datenschutz",'02_Checkliste'!$P$5:$P$1000,"") -> 7 | F24: =COUNTIFS('02_Checkliste'!$B$5:$B$1000,"Datenschutz",'02_Checkliste'!$P$5:$P$1000,"Hoch")+COUNTIFS('02_Checkliste'!$B$5:$B$1000,"Datenschutz",'02_Checkliste'!$P$5:$P$1000,"Kritisch") -> 0
A25: HR & Pensions | B25: =COUNTIF('02_Checkliste'!$B$5:$B$1000,"HR & Pensions") -> 10 | C25: =COUNTIFS('02_Checkliste'!$B$5:$B$1000,"HR & Pensions",'02_Checkliste'!$J$5:$J$1000,"Abgeschlossen") -> 0 | D25: =IFERROR(C25/B25,0) -> 0 | E25: =COUNTIFS('02_Checkliste'!$B$5:$B$1000,"HR & Pensions",'02_Checkliste'!$P$5:$P$1000,"") -> 10 | F25: =COUNTIFS('02_Checkliste'!$B$5:$B$1000,"HR & Pensions",'02_Checkliste'!$P$5:$P$1000,"Hoch")+COUNTIFS('02_Checkliste'!$B$5:$B$1000,"HR & Pensions",'02_Checkliste'!$P$5:$P$1000,"Kritisch") -> 0
A26: Intellectual Property | B26: =COUNTIF('02_Checkliste'!$B$5:$B$1000,"Intellectual Property") -> 7 | C26: =COUNTIFS('02_Checkliste'!$B$5:$B$1000,"Intellectual Property",'02_Checkliste'!$J$5:$J$1000,"Abgeschlossen") -> 0 | D26: =IFERROR(C26/B26,0) -> 0 | E26: =COUNTIFS('02_Checkliste'!$B$5:$B$1000,"Intellectual Property",'02_Checkliste'!$P$5:$P$1000,"") -> 7 | F26: =COUNTIFS('02_Checkliste'!$B$5:$B$1000,"Intellectual Property",'02_Checkliste'!$P$5:$P$1000,"Hoch")+COUNTIFS('02_Checkliste'!$B$5:$B$1000,"Intellectual Property",'02_Checkliste'!$P$5:$P$1000,"Kritisch") -> 0
A27: ESG, EHS & Produkt | B27: =COUNTIF('02_Checkliste'!$B$5:$B$1000,"ESG, EHS & Produkt") -> 9 | C27: =COUNTIFS('02_Checkliste'!$B$5:$B$1000,"ESG, EHS & Produkt",'02_Checkliste'!$J$5:$J$1000,"Abgeschlossen") -> 0 | D27: =IFERROR(C27/B27,0) -> 0 | E27: =COUNTIFS('02_Checkliste'!$B$5:$B$1000,"ESG, EHS & Produkt",'02_Checkliste'!$P$5:$P$1000,"") -> 9 | F27: =COUNTIFS('02_Checkliste'!$B$5:$B$1000,"ESG, EHS & Produkt",'02_Checkliste'!$P$5:$P$1000,"Hoch")+COUNTIFS('02_Checkliste'!$B$5:$B$1000,"ESG, EHS & Produkt",'02_Checkliste'!$P$5:$P$1000,"Kritisch") -> 0
A28: Real Estate & Assets | B28: =COUNTIF('02_Checkliste'!$B$5:$B$1000,"Real Estate & Assets") -> 5 | C28: =COUNTIFS('02_Checkliste'!$B$5:$B$1000,"Real Estate & Assets",'02_Checkliste'!$J$5:$J$1000,"Abgeschlossen") -> 0 | D28: =IFERROR(C28/B28,0) -> 0 | E28: =COUNTIFS('02_Checkliste'!$B$5:$B$1000,"Real Estate & Assets",'02_Checkliste'!$P$5:$P$1000,"") -> 5 | F28: =COUNTIFS('02_Checkliste'!$B$5:$B$1000,"Real Estate & Assets",'02_Checkliste'!$P$5:$P$1000,"Hoch")+COUNTIFS('02_Checkliste'!$B$5:$B$1000,"Real Estate & Assets",'02_Checkliste'!$P$5:$P$1000,"Kritisch") -> 0
A29: Insurance | B29: =COUNTIF('02_Checkliste'!$B$5:$B$1000,"Insurance") -> 5 | C29: =COUNTIFS('02_Checkliste'!$B$5:$B$1000,"Insurance",'02_Checkliste'!$J$5:$J$1000,"Abgeschlossen") -> 0 | D29: =IFERROR(C29/B29,0) -> 0 | E29: =COUNTIFS('02_Checkliste'!$B$5:$B$1000,"Insurance",'02_Checkliste'!$P$5:$P$1000,"") -> 5 | F29: =COUNTIFS('02_Checkliste'!$B$5:$B$1000,"Insurance",'02_Checkliste'!$P$5:$P$1000,"Hoch")+COUNTIFS('02_Checkliste'!$B$5:$B$1000,"Insurance",'02_Checkliste'!$P$5:$P$1000,"Kritisch") -> 0
A30: Compliance, AML & Sanctions | B30: =COUNTIF('02_Checkliste'!$B$5:$B$1000,"Compliance, AML & Sanctions") -> 9 | C30: =COUNTIFS('02_Checkliste'!$B$5:$B$1000,"Compliance, AML & Sanctions",'02_Checkliste'!$J$5:$J$1000,"Abgeschlossen") -> 0 | D30: =IFERROR(C30/B30,0) -> 0 | E30: =COUNTIFS('02_Checkliste'!$B$5:$B$1000,"Compliance, AML & Sanctions",'02_Checkliste'!$P$5:$P$1000,"") -> 9 | F30: =COUNTIFS('02_Checkliste'!$B$5:$B$1000,"Compliance, AML & Sanctions",'02_Checkliste'!$P$5:$P$1000,"Hoch")+COUNTIFS('02_Checkliste'!$B$5:$B$1000,"Compliance, AML & Sanctions",'02_Checkliste'!$P$5:$P$1000,"Kritisch") -> 0
A31: Carve-out & Integration | B31: =COUNTIF('02_Checkliste'!$B$5:$B$1000,"Carve-out & Integration") -> 9 | C31: =COUNTIFS('02_Checkliste'!$B$5:$B$1000,"Carve-out & Integration",'02_Checkliste'!$J$5:$J$1000,"Abgeschlossen") -> 0 | D31: =IFERROR(C31/B31,0) -> 0 | E31: =COUNTIFS('02_Checkliste'!$B$5:$B$1000,"Carve-out & Integration",'02_Checkliste'!$P$5:$P$1000,"") -> 9 | F31: =COUNTIFS('02_Checkliste'!$B$5:$B$1000,"Carve-out & Integration",'02_Checkliste'!$P$5:$P$1000,"Hoch")+COUNTIFS('02_Checkliste'!$B$5:$B$1000,"Carve-out & Integration",'02_Checkliste'!$P$5:$P$1000,"Kritisch") -> 0
A34: Entscheidungs-Gates
A35: Gate | B35: Leitfrage | C35: Status | D35: Owner | E35: Entscheidung / Kommentar
A36: G1 | B36: Sind Deal Perimeter und Eigentum zweifelsfrei? | C36: Offen
A37: G2 | B37: Sind normalisiertes EBITDA, Net Debt und NWC belastbar? | C37: Offen
A38: G3 | B38: Sind Genehmigungen, Consents und Finanzierung auf kritischem Pfad gesichert? | C38: Offen
A39: G4 | B39: Sind wesentliche Legal-, Tax-, Compliance-, Cyber- und ESG-Risiken mitigiert? | C39: Offen
A40: G5 | B40: Sind Day 1, TSA und Schlüsselpersonen einsatzbereit? | C40: Offen
A41: G6 | B41: Ist der verbleibende Downside innerhalb der genehmigten Risikotoleranz? | C41: Offen

Sheet 02_Checkliste
A1: Master-Checkliste
A2: 156 risikoorientierte Prüfpunkte. Vorschläge sind Hypothesen; tatsächliche Feststellungen benötigen Evidenz.
A4: ID | B4: Prüfbereich | C4: Unterbereich | D4: Prüfziel / Prüffrage | E4: Benötigte Unterlagen / Daten | F4: Empfohlene Analyse | G4: Typische Red Flags | H4: Priorität | I4: Phase | J4: Status | K4: Verantwortlich | L4: Fälligkeit | M4: Eintritt (1–5) | N4: Auswirkung (1–5) | O4: Risikoscore | P4: Risikoklasse | Q4: Feststellung / Evidenz | R4: Maßnahmenvorschlag | S4: Deal-Implikation | T4: Kaufpreiseffekt (€) | U4: SPA-/Schutzmechanismus | V4: Dokument-/Q&A-Referenz | W4: Quelle | X4: Letzte Aktualisierung | Y4: Reviewer
A5: TRX-01 | B5: Transaktion & Scope | C5: Deal Perimeter | D5: Sind Zielgesellschaften, Vermögenswerte, Schulden und ausgenommene Positionen eindeutig abgegrenzt? | E5: Strukturdiagramm, Term Sheet, Perimeter-Liste, Asset- und Beteiligungsverzeichnis | F5: Perimeter mit Abschlüssen, Verträgen und Bewertungsmodell abstimmen; Lückenliste erstellen. | G5: Nicht konsolidierte Einheiten, nicht übertragbare Assets, unklare Haftungszuordnung | H5: Kritisch | I5: Screening | J5: Nicht begonnen | O5: =IF(OR(M5="",N5=""),"",M5*N5) | P5: =IF(O5="","",IF(O5>=17,"Kritisch",IF(O5>=10,"Hoch",IF(O5>=5,"Mittel","Niedrig")))) | R5: Perimeter verbindlich festlegen und Abweichungen im SPA sowie Kaufpreismodell abbilden. | S5: Bewertung/Kaufpreis | U5: Definitionen, Closing Accounts, Freistellung | W5: S03
A6: TRX-02 | B6: Transaktion & Scope | C6: Transaktionsstruktur | D6: Ist Share Deal, Asset Deal oder Mischform wirtschaftlich, rechtlich und steuerlich belastbar? | E6: Term Sheet, Strukturmemorandum, Steuer- und Rechtsgutachten | F6: Alternativen nach Steuern, Haftungsübergang, Übertragbarkeit und Umsetzungsrisiko vergleichen. | G6: Struktur nur steuergetrieben, unerforderliche Zustimmungen, ungeklärte Gesamtrechtsnachfolge | H6: Kritisch | I6: Screening | J6: Nicht begonnen | O6: =IF(OR(M6="",N6=""),"",M6*N6) | P6: =IF(O6="","",IF(O6>=17,"Kritisch",IF(O6>=10,"Hoch",IF(O6>=5,"Mittel","Niedrig")))) | R6: Strukturoptionen mit Entscheidungsmatrix dokumentieren und bevorzugte Struktur freigeben. | S6: Abbruch/No-go | U6: Closing-Bedingung, Struktur-Covenant | W6: S03
A7: TRX-03 | B7: Transaktion & Scope | C7: Materialität | D7: Sind Materialitätsschwellen je Prüfungsbereich definiert und konsistent? | E7: DD-Scope, Bewertungsmodell, Risikotoleranz, Finanzierungsvorgaben | F7: Quantitative und qualitative Schwellen einschließlich No-go-Kriterien festlegen. | G7: Beliebige Einzelfallentscheidungen, kleine wiederkehrende Fehler werden unterschätzt | H7: Hoch | I7: Screening | J7: Nicht begonnen | O7: =IF(OR(M7="",N7=""),"",M7*N7) | P7: =IF(O7="","",IF(O7>=17,"Kritisch",IF(O7>=10,"Hoch",IF(O7>=5,"Mittel","Niedrig")))) | R7: Materialitätsmatrix mit Eskalations- und Genehmigungsstufen beschließen. | S7: Integration/100-Tage-Plan | U7: Reporting-Covenant | W7: S01
A8: TRX-04 | B8: Transaktion & Scope | C8: Stichtag & Zeitraum | D8: Decken Prüfungszeitraum und Stichtag die Werttreiber und aktuelle Entwicklung angemessen ab? | E8: Jahresabschlüsse, Monatsreporting, LTM-Daten, Ereignisse nach Stichtag | F8: Historie, LTM und aktuelle Monatsdaten überleiten; Subsequent Events prüfen. | G8: Veraltete Daten, starke Abweichung nach Stichtag, fehlende Monatsabschlüsse | H8: Hoch | I8: Vollprüfung | J8: Nicht begonnen | O8: =IF(OR(M8="",N8=""),"",M8*N8) | P8: =IF(O8="","",IF(O8>=17,"Kritisch",IF(O8>=10,"Hoch",IF(O8>=5,"Mittel","Niedrig")))) | R8: Bring-down-Daten und Aktualisierung vor Signing/Closing vertraglich verlangen. | S8: SPA/Haftung | U8: Bring-down, Closing-Bedingung | W8: S05
A9: TRX-05 | B9: Transaktion & Scope | C9: Datenraumqualität | D9: Sind Datenraum, Index, Versionierung und Vollständigkeit prüfbar? | E9: VDR-Index, Upload-Log, Berechtigungsmatrix, Vollständigkeitserklärung | F9: Index gegen Request List abgleichen; Dubletten, fehlende Versionen und späte Uploads markieren. | G9: Massen-Uploads kurz vor Deadline, widersprüchliche Versionen, gelöschte Dateien | H9: Kritisch | I9: Vollprüfung | J9: Nicht begonnen | O9: =IF(OR(M9="",N9=""),"",M9*N9) | P9: =IF(O9="","",IF(O9>=17,"Kritisch",IF(O9>=10,"Hoch",IF(O9>=5,"Mittel","Niedrig")))) | R9: VDR-Governance, Cut-off und finale Datenraum-DVD/Archiv vereinbaren. | S9: SPA/Haftung | U9: Disclosure-Regeln, Vollständigkeitserklärung | W9: S02
A10: TRX-06 | B10: Transaktion & Scope | C10: Management-Auskünfte | D10: Sind Management-Aussagen dokumentiert, konsistent und evidenzbasiert? | E10: Q&A-Protokolle, Management-Präsentation, Datenquellen, Representation Letter | F10: Aussagen triangulieren und wesentliche mündliche Zusagen schriftlich bestätigen lassen. | G10: Ausweichende Antworten, häufige Korrekturen, fehlende Evidenz | H10: Hoch | I10: Vollprüfung | J10: Nicht begonnen | O10: =IF(OR(M10="",N10=""),"",M10*N10) | P10: =IF(O10="","",IF(O10>=17,"Kritisch",IF(O10>=10,"Hoch",IF(O10>=5,"Mittel","Niedrig")))) | R10: Offene Aussagen in Q&A nachverfolgen und als Garantie oder Closing Deliverable absichern. | S10: SPA/Haftung | U10: Garantie, Covenant, Closing Deliverable | W10: S03
A11: TRX-07 | B11: Transaktion & Scope | C11: Interessenkonflikte | D11: Sind Management-Incentives, Verkäuferinteressen und Beraterabhängigkeiten transparent? | E11: Bonuspläne, MIP, Beraterverträge, Related-Party-Liste | F11: Anreize auf mögliche Ergebnissteuerung, Retention und Deal-Abhängigkeit analysieren. | G11: Transaktionsbonus nur bei hohem Kaufpreis, undisclosed related parties | H11: Hoch | I11: Screening | J11: Nicht begonnen | O11: =IF(OR(M11="",N11=""),"",M11*N11) | P11: =IF(O11="","",IF(O11>=17,"Kritisch",IF(O11>=10,"Hoch",IF(O11>=5,"Mittel","Niedrig")))) | R11: Konflikte offenlegen, unabhängige Validierung und angepasste Incentives vorsehen. | S11: Bewertung/Kaufpreis | U11: Disclosure, Retention-Vereinbarung | W11: S01
A12: TRX-08 | B12: Transaktion & Scope | C12: Regulatorischer Pfad | D12: Sind erforderliche Fusionskontroll-, Investitionskontroll- und Branchenfreigaben identifiziert? | E12: Umsatzdaten nach Land, Eigentümerstruktur, Lizenzen, Regulatory Memo | F12: Schwellenwerte, Zuständigkeiten, Long-stop Date und Vollzugsrisiko prüfen. | G12: Gun jumping, übersehene Anmeldung, kritische ausländische Beteiligung | H12: Kritisch | I12: Screening | J12: Nicht begonnen | O12: =IF(OR(M12="",N12=""),"",M12*N12) | P12: =IF(O12="","",IF(O12>=17,"Kritisch",IF(O12>=10,"Hoch",IF(O12>=5,"Mittel","Niedrig")))) | R12: Anmeldestrategie, Verantwortlichkeiten und Long-stop-/Termination-Regelung festlegen. | S12: Closing-Bedingung | U12: Condition precedent, Long-stop Date | W12: S03
A13: COR-01 | B13: Corporate & Governance | C13: Existenz & Vertretung | D13: Sind Gesellschaften wirksam errichtet und Vertretungsbefugnisse aktuell? | E13: Registerauszüge, Satzungen, Geschäftsführerlisten, Vollmachten | F13: Registerdaten mit internen Unterlagen und Signaturrechten abgleichen. | G13: Abweichende Geschäftsführer, abgelaufene Vollmachten, fehlende Eintragung | H13: Kritisch | I13: Vollprüfung | J13: Nicht begonnen | O13: =IF(OR(M13="",N13=""),"",M13*N13) | P13: =IF(O13="","",IF(O13>=17,"Kritisch",IF(O13>=10,"Hoch",IF(O13>=5,"Mittel","Niedrig")))) | R13: Register und Vollmachten vor Closing bereinigen. | S13: Closing-Bedingung | U13: Closing Deliverable, Garantie | W13: S03
A14: COR-02 | B14: Corporate & Governance | C14: Cap Table | D14: Ist die Eigentümerstruktur vollständig verwässert und frei von unbekannten Rechten? | E14: Gesellschafterliste, Aktienbuch, Optionen, Wandeldarlehen, VSOP/ESOP | F14: Fully diluted Cap Table rechnen und auf Abschlüsse sowie Verträge abstimmen. | G14: Nicht erfasste Optionen, Side Letters, strittige Anteile | H14: Kritisch | I14: Vollprüfung | J14: Nicht begonnen | O14: =IF(OR(M14="",N14=""),"",M14*N14) | P14: =IF(O14="","",IF(O14>=17,"Kritisch",IF(O14>=10,"Hoch",IF(O14>=5,"Mittel","Niedrig")))) | R14: Alle Rechte ablösen oder in Kaufpreis und Closing-Mechanik integrieren. | S14: Bewertung/Kaufpreis | U14: Closing-Bedingung, Freistellung | W14: S03
A15: COR-03 | B15: Corporate & Governance | C15: Belastungen | D15: Sind Anteile und wesentliche Assets frei von Pfandrechten oder sonstigen Belastungen? | E15: Pfandverträge, Register, Sicherheitenverzeichnis, Bankbestätigungen | F15: Sicherheiten auf Eigentümer, Rang, Freigabebedingung und Vollständigkeit prüfen. | G15: Nicht freigabefähige Sicherheiten, Cross-Collateral, negative pledge | H15: Kritisch | I15: Vollprüfung | J15: Nicht begonnen | O15: =IF(OR(M15="",N15=""),"",M15*N15) | P15: =IF(O15="","",IF(O15>=17,"Kritisch",IF(O15>=10,"Hoch",IF(O15>=5,"Mittel","Niedrig")))) | R15: Payoff Letter und Freigaben als Closing Deliverables verlangen. | S15: Finanzierung | U15: Debt payoff, Release Condition | W15: S03
A16: COR-04 | B16: Corporate & Governance | C16: Beschlusslage | D16: Sind wesentliche Organbeschlüsse und Transaktionen ordnungsgemäß genehmigt? | E16: Protokolle der letzten fünf Jahre, Geschäftsordnungen, Zustimmungslisten | F16: Beschlüsse auf Form, Quorum, Interessenkonflikte und Folgepflichten prüfen. | G16: Fehlende Genehmigung, rückdatierte Protokolle, dauerhafte Kompetenzverstöße | H16: Hoch | I16: Vollprüfung | J16: Nicht begonnen | O16: =IF(OR(M16="",N16=""),"",M16*N16) | P16: =IF(O16="","",IF(O16>=17,"Kritisch",IF(O16>=10,"Hoch",IF(O16>=5,"Mittel","Niedrig")))) | R16: Heilungsbeschlüsse und aktualisierte Geschäftsordnung umsetzen. | S16: SPA/Haftung | U16: Garantie, Closing Deliverable | W16: S03
... A160: INT-09 | B160: Carve-out & Integration | C160: Integration Governance | D160: Gibt es klare Entscheidungsrechte, Baselines und Benefit Tracking? | E160: IMO-Charter, RACI, Workstreams, KPI, Risiko-/Entscheidungslog | F160: Governance gegen Deal Thesis und kritischen Pfad prüfen. | G160: Kein Baseline Owner, Entscheidungen ohne Eskalationsweg | H160: Hoch | I160: Closing | J160: Nicht begonnen | O160: =IF(OR(M160="",N160=""),"",M160*N160) | P160: =IF(O160="","",IF(O160>=17,"Kritisch",IF(O160>=10,"Hoch",IF(O160>=5,"Mittel","Niedrig")))) | R160: IMO/SteerCo mit KPI, Cadence und Eskalation vor Day 1 aktivieren. | S160: Integration/100-Tage-Plan | U160: Covenant | W160: S03

Sheet 03_Dokumente
A1: Dokumentenanforderung / VDR-Tracker
A2: Aus der Master-Checkliste abgeleitete Request List. Eine Zeile kann bei Bedarf in einzelne Dateien/Datenpakete aufgeteilt werden.
A4: Dok-ID | B4: Prüfbereich | C4: Unterlage / Datensatz | D4: Zeitraum / Scope | E4: Analysezweck | F4: Priorität | G4: Pflicht? | H4: Owner Zielunternehmen | I4: Angefordert am | J4: Fällig am | K4: Erhalten am | L4: Status | M4: Vollständigkeit | N4: Vertraulichkeit | O4: VDR-Pfad / Link | P4: Checklisten-Ref. | Q4: Offene Punkte | R4: Tage überfällig | S4: Reviewer
A5: DOC-001 | B5: Transaktion & Scope | C5: Strukturdiagramm, Term Sheet, Perimeter-Liste, Asset- und Beteiligungsverzeichnis | D5: Aktuell; historische Fälle soweit relevant | E5: Sind Zielgesellschaften, Vermögenswerte, Schulden und ausgenommene Positionen eindeutig abgegrenzt? | F5: Kritisch | G5: Ja | H5: M&A / Legal | L5: Nicht angefordert | M5: Ungeprüft | N5: Vertraulich | P5: TRX-01 | R5: =IF(OR(J5="",L5="Vollständig",L5="Nicht anwendbar"),"",MAX(0,TODAY()-J5))
A6: DOC-002 | B6: Transaktion & Scope | C6: Term Sheet, Strukturmemorandum, Steuer- und Rechtsgutachten | D6: Aktuell; historische Fälle soweit relevant | E6: Ist Share Deal, Asset Deal oder Mischform wirtschaftlich, rechtlich und steuerlich belastbar? | F6: Kritisch | G6: Ja | H6: M&A / Legal | L6: Nicht angefordert | M6: Ungeprüft | N6: Vertraulich | P6: TRX-02 | R6: =IF(OR(J6="",L6="Vollständig",L6="Nicht anwendbar"),"",MAX(0,TODAY()-J6))
A7: DOC-003 | B7: Transaktion & Scope | C7: DD-Scope, Bewertungsmodell, Risikotoleranz, Finanzierungsvorgaben | D7: Aktuell; historische Fälle soweit relevant | E7: Sind Materialitätsschwellen je Prüfungsbereich definiert und konsistent? | F7: Hoch | G7: Ja | H7: M&A / Legal | L7: Nicht angefordert | M7: Ungeprüft | N7: Vertraulich | P7: TRX-03 | R7: =IF(OR(J7="",L7="Vollständig",L7="Nicht anwendbar"),"",MAX(0,TODAY()-J7))
A8: DOC-004 | B8: Transaktion & Scope | C8: Jahresabschlüsse, Monatsreporting, LTM-Daten, Ereignisse nach Stichtag | D8: Aktuell; historische Fälle soweit relevant | E8: Decken Prüfungszeitraum und Stichtag die Werttreiber und aktuelle Entwicklung angemessen ab? | F8: Hoch | G8: Ja | H8: M&A / Legal | L8: Nicht angefordert | M8: Ungeprüft | N8: Vertraulich | P8: TRX-04 | R8: =IF(OR(J8="",L8="Vollständig",L8="Nicht anwendbar"),"",MAX(0,TODAY()-J8))
A9: DOC-005 | B9: Transaktion & Scope | C9: VDR-Index, Upload-Log, Berechtigungsmatrix, Vollständigkeitserklärung | D9: Aktuell; historische Fälle soweit relevant | E9: Sind Datenraum, Index, Versionierung und Vollständigkeit prüfbar? | F9: Kritisch | G9: Ja | H9: M&A / Legal | L9: Nicht angefordert | M9: Ungeprüft | N9: Vertraulich | P9: TRX-05 | R9: =IF(OR(J9="",L9="Vollständig",L9="Nicht anwendbar"),"",MAX(0,TODAY()-J9))
A10: DOC-006 | B10: Transaktion & Scope | C10: Q&A-Protokolle, Management-Präsentation, Datenquellen, Representation Letter | D10: Aktuell; historische Fälle soweit relevant | E10: Sind Management-Aussagen dokumentiert, konsistent und evidenzbasiert? | F10: Hoch | G10: Ja | H10: M&A / Legal | L10: Nicht angefordert | M10: Ungeprüft | N10: Vertraulich | P10: TRX-06 | R10: =IF(OR(J10="",L10="Vollständig",L10="Nicht anwendbar"),"",MAX(0,TODAY()-J10))
A11: DOC-007 | B11: Transaktion & Scope | C11: Bonuspläne, MIP, Beraterverträge, Related-Party-Liste | D11: Aktuell; historische Fälle soweit relevant | E11: Sind Management-Incentives, Verkäuferinteressen und Beraterabhängigkeiten transparent? | F11: Hoch | G11: Ja | H11: M&A / Legal | L11: Nicht angefordert | M11: Ungeprüft | N11: Vertraulich | P11: TRX-07 | R11: =IF(OR(J11="",L11="Vollständig",L11="Nicht anwendbar"),"",MAX(0,TODAY()-J11))
A12: DOC-008 | B12: Transaktion & Scope | C12: Umsatzdaten nach Land, Eigentümerstruktur, Lizenzen, Regulatory Memo | D12: Aktuell; historische Fälle soweit relevant | E12: Sind erforderliche Fusionskontroll-, Investitionskontroll- und Branchenfreigaben identifiziert? | F12: Kritisch | G12: Ja | H12: M&A / Legal | L12: Nicht angefordert | M12: Ungeprüft | N12: Vertraulich | P12: TRX-08 | R12: =IF(OR(J12="",L12="Vollständig",L12="Nicht anwendbar"),"",MAX(0,TODAY()-J12))
A13: DOC-009 | B13: Corporate & Governance | C13: Registerauszüge, Satzungen, Geschäftsführerlisten, Vollmachten | D13: Aktuell; historische Fälle soweit relevant | E13: Sind Gesellschaften wirksam errichtet und Vertretungsbefugnisse aktuell? | F13: Kritisch | G13: Ja | H13: Legal / Corporate | L13: Nicht angefordert | M13: Ungeprüft | N13: Vertraulich | P13: COR-01 | R13: =IF(OR(J13="",L13="Vollständig",L13="Nicht anwendbar"),"",MAX(0,TODAY()-J13))
A14: DOC-010 | B14: Corporate & Governance | C14: Gesellschafterliste, Aktienbuch, Optionen, Wandeldarlehen, VSOP/ESOP | D14: Aktuell; historische Fälle soweit relevant | E14: Ist die Eigentümerstruktur vollständig verwässert und frei von unbekannten Rechten? | F14: Kritisch | G14: Ja | H14: Legal / Corporate | L14: Nicht angefordert | M14: Ungeprüft | N14: Vertraulich | P14: COR-02 | R14: =IF(OR(J14="",L14="Vollständig",L14="Nicht anwendbar"),"",MAX(0,TODAY()-J14))
A15: DOC-011 | B15: Corporate & Governance | C15: Pfandverträge, Register, Sicherheitenverzeichnis, Bankbestätigungen | D15: Aktuell; historische Fälle soweit relevant | E15: Sind Anteile und wesentliche Assets frei von Pfandrechten oder sonstigen Belastungen? | F15: Kritisch | G15: Ja | H15: Legal / Corporate | L15: Nicht angefordert | M15: Ungeprüft | N15: Vertraulich | P15: COR-03 | R15: =IF(OR(J15="",L15="Vollständig",L15="Nicht anwendbar"),"",MAX(0,TODAY()-J15))
A16: DOC-012 | B16: Corporate & Governance | C16: Protokolle der letzten fünf Jahre, Geschäftsordnungen, Zustimmungslisten | D16: Aktuell; historische Fälle soweit relevant | E16: Sind wesentliche Organbeschlüsse und Transaktionen ordnungsgemäß genehmigt? | F16: Hoch | G16: Ja | H16: Legal / Corporate | L16: Nicht angefordert | M16: Ungeprüft | N16: Vertraulich | P16: COR-04 | R16: =IF(OR(J16="",L16="Vollständig",L16="Nicht anwendbar"),"",MAX(0,TODAY()-J16))
... A160: DOC-156 | B160: Carve-out & Integration | C160: IMO-Charter, RACI, Workstreams, KPI, Risiko-/Entscheidungslog | D160: Aktuell; historische Fälle soweit relevant | E160: Gibt es klare Entscheidungsrechte, Baselines und Benefit Tracking? | F160: Hoch | G160: Ja | H160: PMO / Separation | L160: Nicht angefordert | M160: Ungeprüft | N160: Vertraulich | P160: INT-09 | R160: =IF(OR(J160="",L160="Vollständig",L160="Nicht anwendbar"),"",MAX(0,TODAY()-J160))

Sheet 04_Risiken
A1: Risikoregister
A2: Vorausgefüllte Prüfhypothesen – ausdrücklich keine bestätigten Findings. Eintritt, Auswirkung und Exposure erst nach Evidenz bewerten.
A4: Risiko-ID | B4: Prüfbereich | C4: Prüfhypothese / Szenario | D4: Indikatoren / benötigte Evidenz | E4: Analyse / Test | F4: Bewertungsstatus | G4: Feststellung / Evidenz | H4: Eintritt (1–5) | I4: Auswirkung (1–5) | J4: Score | K4: Klasse | L4: Exposure Low (€) | M4: Exposure Base (€) | N4: Exposure High (€) | O4: Gegenmaßnahme | P4: Owner | Q4: Fälligkeit | R4: Maßnahmenstatus | S4: Transaktionsfolge | T4: Checklisten-Ref. | U4: Resteintritt | V4: Restauswirkung | W4: Restscore | X4: Restklasse | Y4: Entscheidung / Kommentar | Z4: Reviewer
A5: R-001 | B5: Transaktion & Scope | C5: Nicht konsolidierte Einheiten, nicht übertragbare Assets, unklare Haftungszuordnung | D5: Strukturdiagramm, Term Sheet, Perimeter-Liste, Asset- und Beteiligungsverzeichnis | E5: Perimeter mit Abschlüssen, Verträgen und Bewertungsmodell abstimmen; Lückenliste erstellen. | F5: Zu verifizieren | J5: =IF(OR(H5="",I5=""),"",H5*I5) | K5: =IF(J5="","",IF(J5>=17,"Kritisch",IF(J5>=10,"Hoch",IF(J5>=5,"Mittel","Niedrig")))) | O5: Perimeter verbindlich festlegen und Abweichungen im SPA sowie Kaufpreismodell abbilden. | R5: Nicht gestartet | S5: Bewertung/Kaufpreis | T5: TRX-01 | W5: =IF(OR(U5="",V5=""),"",U5*V5) | X5: =IF(W5="","",IF(W5>=17,"Kritisch",IF(W5>=10,"Hoch",IF(W5>=5,"Mittel","Niedrig"))))
A6: R-002 | B6: Transaktion & Scope | C6: Struktur nur steuergetrieben, unerforderliche Zustimmungen, ungeklärte Gesamtrechtsnachfolge | D6: Term Sheet, Strukturmemorandum, Steuer- und Rechtsgutachten | E6: Alternativen nach Steuern, Haftungsübergang, Übertragbarkeit und Umsetzungsrisiko vergleichen. | F6: Zu verifizieren | J6: =IF(OR(H6="",I6=""),"",H6*I6) | K6: =IF(J6="","",IF(J6>=17,"Kritisch",IF(J6>=10,"Hoch",IF(J6>=5,"Mittel","Niedrig")))) | O6: Strukturoptionen mit Entscheidungsmatrix dokumentieren und bevorzugte Struktur freigeben. | R6: Nicht gestartet | S6: Abbruch/No-go | T6: TRX-02 | W6: =IF(OR(U6="",V6=""),"",U6*V6) | X6: =IF(W6="","",IF(W6>=17,"Kritisch",IF(W6>=10,"Hoch",IF(W6>=5,"Mittel","Niedrig"))))
A7: R-003 | B7: Transaktion & Scope | C7: Massen-Uploads kurz vor Deadline, widersprüchliche Versionen, gelöschte Dateien | D7: VDR-Index, Upload-Log, Berechtigungsmatrix, Vollständigkeitserklärung | E7: Index gegen Request List abgleichen; Dubletten, fehlende Versionen und späte Uploads markieren. | F7: Zu verifizieren | J7: =IF(OR(H7="",I7=""),"",H7*I7) | K7: =IF(J7="","",IF(J7>=17,"Kritisch",IF(J7>=10,"Hoch",IF(J7>=5,"Mittel","Niedrig")))) | O7: VDR-Governance, Cut-off und finale Datenraum-DVD/Archiv vereinbaren. | R7: Nicht gestartet | S7: SPA/Haftung | T7: TRX-05 | W7: =IF(OR(U7="",V7=""),"",U7*V7) | X7: =IF(W7="","",IF(W7>=17,"Kritisch",IF(W7>=10,"Hoch",IF(W7>=5,"Mittel","Niedrig"))))
A8: R-004 | B8: Transaktion & Scope | C8: Gun jumping, übersehene Anmeldung, kritische ausländische Beteiligung | D8: Umsatzdaten nach Land, Eigentümerstruktur, Lizenzen, Regulatory Memo | E8: Schwellenwerte, Zuständigkeiten, Long-stop Date und Vollzugsrisiko prüfen. | F8: Zu verifizieren | J8: =IF(OR(H8="",I8=""),"",H8*I8) | K8: =IF(J8="","",IF(J8>=17,"Kritisch",IF(J8>=10,"Hoch",IF(J8>=5,"Mittel","Niedrig")))) | O8: Anmeldestrategie, Verantwortlichkeiten und Long-stop-/Termination-Regelung festlegen. | R8: Nicht gestartet | S8: Closing-Bedingung | T8: TRX-08 | W8: =IF(OR(U8="",V8=""),"",U8*V8) | X8: =IF(W8="","",IF(W8>=17,"Kritisch",IF(W8>=10,"Hoch",IF(W8>=5,"Mittel","Niedrig"))))
A9: R-005 | B9: Corporate & Governance | C9: Abweichende Geschäftsführer, abgelaufene Vollmachten, fehlende Eintragung | D9: Registerauszüge, Satzungen, Geschäftsführerlisten, Vollmachten | E9: Registerdaten mit internen Unterlagen und Signaturrechten abgleichen. | F9: Zu verifizieren | J9: =IF(OR(H9="",I9=""),"",H9*I9) | K9: =IF(J9="","",IF(J9>=17,"Kritisch",IF(J9>=10,"Hoch",IF(J9>=5,"Mittel","Niedrig")))) | O9: Register und Vollmachten vor Closing bereinigen. | R9: Nicht gestartet | S9: Closing-Bedingung | T9: COR-01 | W9: =IF(OR(U9="",V9=""),"",U9*V9) | X9: =IF(W9="","",IF(W9>=17,"Kritisch",IF(W9>=10,"Hoch",IF(W9>=5,"Mittel","Niedrig"))))
A10: R-006 | B10: Corporate & Governance | C10: Nicht erfasste Optionen, Side Letters, strittige Anteile | D10: Gesellschafterliste, Aktienbuch, Optionen, Wandeldarlehen, VSOP/ESOP | E10: Fully diluted Cap Table rechnen und auf Abschlüsse sowie Verträge abstimmen. | F10: Zu verifizieren | J10: =IF(OR(H10="",I10=""),"",H10*I10) | K10: =IF(J10="","",IF(J10>=17,"Kritisch",IF(J10>=10,"Hoch",IF(J10>=5,"Mittel","Niedrig")))) | O10: Alle Rechte ablösen oder in Kaufpreis und Closing-Mechanik integrieren. | R10: Nicht gestartet | S10: Bewertung/Kaufpreis | T10: COR-02 | W10: =IF(OR(U10="",V10=""),"",U10*V10) | X10: =IF(W10="","",IF(W10>=17,"Kritisch",IF(W10>=10,"Hoch",IF(W10>=5,"Mittel","Niedrig"))))
A11: R-007 | B11: Corporate & Governance | C11: Nicht freigabefähige Sicherheiten, Cross-Collateral, negative pledge | D11: Pfandverträge, Register, Sicherheitenverzeichnis, Bankbestätigungen | E11: Sicherheiten auf Eigentümer, Rang, Freigabebedingung und Vollständigkeit prüfen. | F11: Zu verifizieren | J11: =IF(OR(H11="",I11=""),"",H11*I11) | K11: =IF(J11="","",IF(J11>=17,"Kritisch",IF(J11>=10,"Hoch",IF(J11>=5,"Mittel","Niedrig")))) | O11: Payoff Letter und Freigaben als Closing Deliverables verlangen. | R11: Nicht gestartet | S11: Finanzierung | T11: COR-03 | W11: =IF(OR(U11="",V11=""),"",U11*V11) | X11: =IF(W11="","",IF(W11>=17,"Kritisch",IF(W11>=10,"Hoch",IF(W11>=5,"Mittel","Niedrig"))))
A12: R-008 | B12: Corporate & Governance | C12: Unkündbare Vetorechte, fehlende Drag-Ausübung, Zustimmung Dritter | D12: Gesellschaftervereinbarungen, Side Letters, Beteiligungsverträge | E12: Rechte je Transaktionsschritt und benötigte Waiver dokumentieren. | F12: Zu verifizieren | J12: =IF(OR(H12="",I12=""),"",H12*I12) | K12: =IF(J12="","",IF(J12>=17,"Kritisch",IF(J12>=10,"Hoch",IF(J12>=5,"Mittel","Niedrig")))) | O12: Waiver/Zustimmungen vor Signing oder als Closing-Bedingung beschaffen. | R12: Nicht gestartet | S12: Closing-Bedingung | T12: COR-05 | W12: =IF(OR(U12="",V12=""),"",U12*V12) | X12: =IF(W12="","",IF(W12>=17,"Kritisch",IF(W12>=10,"Hoch",IF(W12>=5,"Mittel","Niedrig"))))
A13: R-009 | B13: Corporate & Governance | C13: Kostenlose Leistungen, sofortige Kündigung, unklare IP-Nutzung | D13: Service-, Darlehens-, Cash-Pool-, Lizenz- und Steuerumlageverträge | E13: Leistungsumfang, Preis, Laufzeit, Kündigung und Stand-alone-Kosten prüfen. | F13: Zu verifizieren | J13: =IF(OR(H13="",I13=""),"",H13*I13) | K13: =IF(J13="","",IF(J13>=17,"Kritisch",IF(J13>=10,"Hoch",IF(J13>=5,"Mittel","Niedrig")))) | O13: TSA oder neue Stand-alone-Verträge mit marktgerechten Konditionen vereinbaren. | R13: Nicht gestartet | S13: Integration/100-Tage-Plan | T13: COR-07 | W13: =IF(OR(U13="",V13=""),"",U13*V13) | X13: =IF(W13="","",IF(W13>=17,"Kritisch",IF(W13>=10,"Hoch",IF(W13>=5,"Mittel","Niedrig"))))
A14: R-010 | B14: Financial | C14: Ungeklärte Überleitungsdifferenzen, häufige Nachbuchungen, eingeschränkter Bestätigungsvermerk | D14: Abschlüsse 3–5 Jahre, Prüfungsberichte, Summen-/Saldenlisten, Kontenpläne | E14: Trial Balance zu Abschluss und Management Reporting überleiten; Differenzen erklären. | F14: Zu verifizieren | J14: =IF(OR(H14="",I14=""),"",H14*I14) | K14: =IF(J14="","",IF(J14>=17,"Kritisch",IF(J14>=10,"Hoch",IF(J14>=5,"Mittel","Niedrig")))) | O14: Datenbereinigung, Abschlussgarantie und belastbare Closing Accounts verlangen. | R14: Nicht gestartet | S14: Bewertung/Kaufpreis | T14: FIN-01 | W14: =IF(OR(U14="",V14=""),"",U14*V14) | X14: =IF(W14="","",IF(W14>=17,"Kritisch",IF(W14>=10,"Hoch",IF(W14>=5,"Mittel","Niedrig"))))
A15: R-011 | B15: Financial | C15: Bill-and-hold, Side Letters, vorgezogener Umsatz, hohe Stornos | D15: Top-Rechnungen, Verträge, Lieferscheine, Gutschriften nach Stichtag | E15: Stichproben um Periodenende; Vertragsbedingungen und nachträgliche Gutschriften prüfen. | F15: Zu verifizieren | J15: =IF(OR(H15="",I15=""),"",H15*I15) | K15: =IF(J15="","",IF(J15>=17,"Kritisch",IF(J15>=10,"Hoch",IF(J15>=5,"Mittel","Niedrig")))) | O15: Umsatz/EBITDA normalisieren und Garantie bzw. Escrow für Fehlbuchungen vereinbaren. | R15: Nicht gestartet | S15: Bewertung/Kaufpreis | T15: FIN-03 | W15: =IF(OR(U15="",V15=""),"",U15*V15) | X15: =IF(W15="","",IF(W15>=17,"Kritisch",IF(W15>=10,"Hoch",IF(W15>=5,"Mittel","Niedrig"))))
A16: R-012 | B16: Financial | C16: Synergien als Ist-EBITDA, wiederkehrende 'Einmaleffekte', unbelegte Adjustments | D16: GuV monatlich, Kontendetails, Einmaleffekte, Management Adjustments | E16: Reported-to-adjusted EBITDA Bridge; Wiederkehr, Cash-Wirkung und Run-rate einzeln belegen. | F16: Zu verifizieren | J16: =IF(OR(H16="",I16=""),"",H16*I16) | K16: =IF(J16="","",IF(J16>=17,"Kritisch",IF(J16>=10,"Hoch",IF(J16>=5,"Mittel","Niedrig")))) | O16: Nur belegte, nachhaltige Adjustments akzeptieren und Bewertungsbasis anpassen. | R16: Nicht gestartet | S16: Bewertung/Kaufpreis | T16: FIN-04 | W16: =IF(OR(U16="",V16=""),"",U16*V16) | X16: =IF(W16="","",IF(W16>=17,"Kritisch",IF(W16>=10,"Hoch",IF(W16>=5,"Mittel","Niedrig"))))
... A64: R-060 | B64: HR & Pensions | C64: Unterlassene Konsultation, nachwirkende Vereinbarung, Streikrisiko | D64: Betriebsvereinbarungen, Tarifverträge, Gremien, Verhandlungsstatus | E64: Transaktions- und Integrationsschritte gegen Pflichten/Fristen planen. | F64: Zu verifizieren | J64: =IF(OR(H64="",I64=""),"",H64*I64) | K64: =IF(J64="","",IF(J64>=17,"Kritisch",IF(J64>=10,"Hoch",IF(J64>=5,"Mittel","Niedrig")))) | O64: Mitbestimmungsfahrplan und Kommunikationsplan als kritischen Pfad führen. | R64: Nicht gestartet | S64: Closing-Bedingung | T64: HR-06 | W64: =IF(OR(U64="",V64=""),"",U64*V64) | X64: =IF(W64="","",IF(W64>=17,"Kritisch",IF(W64>=10,"Hoch",IF(W64>=5,"Mittel","Niedrig"))))

Sheet 05_Maßnahmen
A1: Maßnahmenplan
A2: Vorschläge werden erst nach Bestätigung eines Findings aktiviert. Jede aktive Maßnahme benötigt Owner, Termin und messbares Abnahmekriterium.
A4: Maßnahmen-ID | B4: Aktivieren? | C4: Risiko-/Finding-Ref. | D4: Phase | E4: Prüfbereich | F4: Maßnahmenvorschlag | G4: Ergebnis / Abnahmekriterium | H4: Priorität | I4: Owner | J4: Support | K4: Start | L4: Fällig | M4: Status | N4: Fortschritt | O4: Abhängigkeit | P4: Budget (€) | Q4: Erwartete Wirkung | R4: KPI / Nachweis | S4: Eskalationstrigger | T4: Deal-Mechanismus | U4: Kommentar
A5: M-001 | B5: Zu prüfen | C5: R-001 / TRX-01 | D5: SPA / Signing | E5: Transaktion & Scope | F5: Perimeter verbindlich festlegen und Abweichungen im SPA sowie Kaufpreismodell abbilden. | G5: Maßnahme für TRX-01 dokumentiert, fachlich abgenommen und durch belastbare Evidenz geschlossen. | H5: Kritisch | M5: Nicht gestartet | N5: 0 | Q5: Bewertung/Kaufpreis | R5: Evidenz im VDR; Reviewer-Freigabe | S5: Fristüberschreitung oder Score ≥17 | T5: Definitionen, Closing Accounts, Freistellung
A6: M-002 | B6: Zu prüfen | C6: R-002 / TRX-02 | D6: Pre-Signing | E6: Transaktion & Scope | F6: Strukturoptionen mit Entscheidungsmatrix dokumentieren und bevorzugte Struktur freigeben. | G6: Maßnahme für TRX-02 dokumentiert, fachlich abgenommen und durch belastbare Evidenz geschlossen. | H6: Kritisch | M6: Nicht gestartet | N6: 0 | Q6: Abbruch/No-go | R6: Evidenz im VDR; Reviewer-Freigabe | S6: Fristüberschreitung oder Score ≥17 | T6: Closing-Bedingung, Struktur-Covenant
A7: M-003 | B7: Zu prüfen | C7: R-003 / TRX-05 | D7: SPA / Signing | E7: Transaktion & Scope | F7: VDR-Governance, Cut-off und finale Datenraum-DVD/Archiv vereinbaren. | G7: Maßnahme für TRX-05 dokumentiert, fachlich abgenommen und durch belastbare Evidenz geschlossen. | H7: Kritisch | M7: Nicht gestartet | N7: 0 | Q7: SPA/Haftung | R7: Evidenz im VDR; Reviewer-Freigabe | S7: Fristüberschreitung oder Score ≥17 | T7: Disclosure-Regeln, Vollständigkeitserklärung
A8: M-004 | B8: Zu prüfen | C8: R-004 / TRX-08 | D8: Pre-Signing | E8: Transaktion & Scope | F8: Anmeldestrategie, Verantwortlichkeiten und Long-stop-/Termination-Regelung festlegen. | G8: Maßnahme für TRX-08 dokumentiert, fachlich abgenommen und durch belastbare Evidenz geschlossen. | H8: Kritisch | M8: Nicht gestartet | N8: 0 | Q8: Closing-Bedingung | R8: Evidenz im VDR; Reviewer-Freigabe | S8: Fristüberschreitung oder Score ≥17 | T8: Condition precedent, Long-stop Date
A9: M-005 | B9: Zu prüfen | C9: R-005 / COR-01 | D9: Pre-Signing | E9: Corporate & Governance | F9: Register und Vollmachten vor Closing bereinigen. | G9: Maßnahme für COR-01 dokumentiert, fachlich abgenommen und durch belastbare Evidenz geschlossen. | H9: Kritisch | M9: Nicht gestartet | N9: 0 | Q9: Closing-Bedingung | R9: Evidenz im VDR; Reviewer-Freigabe | S9: Fristüberschreitung oder Score ≥17 | T9: Closing Deliverable, Garantie
A10: M-006 | B10: Zu prüfen | C10: R-006 / COR-02 | D10: SPA / Signing | E10: Corporate & Governance | F10: Alle Rechte ablösen oder in Kaufpreis und Closing-Mechanik integrieren. | G10: Maßnahme für COR-02 dokumentiert, fachlich abgenommen und durch belastbare Evidenz geschlossen. | H10: Kritisch | M10: Nicht gestartet | N10: 0 | Q10: Bewertung/Kaufpreis | R10: Evidenz im VDR; Reviewer-Freigabe | S10: Fristüberschreitung oder Score ≥17 | T10: Closing-Bedingung, Freistellung
A11: M-007 | B11: Zu prüfen | C11: R-007 / COR-03 | D11: SPA / Signing | E11: Corporate & Governance | F11: Payoff Letter und Freigaben als Closing Deliverables verlangen. | G11: Maßnahme für COR-03 dokumentiert, fachlich abgenommen und durch belastbare Evidenz geschlossen. | H11: Kritisch | M11: Nicht gestartet | N11: 0 | Q11: Finanzierung | R11: Evidenz im VDR; Reviewer-Freigabe | S11: Fristüberschreitung oder Score ≥17 | T11: Debt payoff, Release Condition
A12: M-008 | B12: Zu prüfen | C12: R-008 / COR-05 | D12: Pre-Signing | E12: Corporate & Governance | F12: Waiver/Zustimmungen vor Signing oder als Closing-Bedingung beschaffen. | G12: Maßnahme für COR-05 dokumentiert, fachlich abgenommen und durch belastbare Evidenz geschlossen. | H12: Kritisch | M12: Nicht gestartet | N12: 0 | Q12: Closing-Bedingung | R12: Evidenz im VDR; Reviewer-Freigabe | S12: Fristüberschreitung oder Score ≥17 | T12: Consent Condition
A13: M-009 | B13: Zu prüfen | C13: R-009 / COR-07 | D13: Day 1 / 100 Tage | E13: Corporate & Governance | F13: TSA oder neue Stand-alone-Verträge mit marktgerechten Konditionen vereinbaren. | G13: Maßnahme für COR-07 dokumentiert, fachlich abgenommen und durch belastbare Evidenz geschlossen. | H13: Kritisch | M13: Nicht gestartet | N13: 0 | Q13: Integration/100-Tage-Plan | R13: Evidenz im VDR; Reviewer-Freigabe | S13: Fristüberschreitung oder Score ≥17 | T13: TSA, Covenant
A14: M-010 | B14: Zu prüfen | C14: R-010 / FIN-01 | D14: SPA / Signing | E14: Financial | F14: Datenbereinigung, Abschlussgarantie und belastbare Closing Accounts verlangen. | G14: Maßnahme für FIN-01 dokumentiert, fachlich abgenommen und durch belastbare Evidenz geschlossen. | H14: Kritisch | M14: Nicht gestartet | N14: 0 | Q14: Bewertung/Kaufpreis | R14: Evidenz im VDR; Reviewer-Freigabe | S14: Fristüberschreitung oder Score ≥17 | T14: Closing Accounts, Garantie
A15: M-011 | B15: Zu prüfen | C15: R-011 / FIN-03 | D15: SPA / Signing | E15: Financial | F15: Umsatz/EBITDA normalisieren und Garantie bzw. Escrow für Fehlbuchungen vereinbaren. | G15: Maßnahme für FIN-03 dokumentiert, fachlich abgenommen und durch belastbare Evidenz geschlossen. | H15: Kritisch | M15: Nicht gestartet | N15: 0 | Q15: Bewertung/Kaufpreis | R15: Evidenz im VDR; Reviewer-Freigabe | S15: Fristüberschreitung oder Score ≥17 | T15: Kaufpreisanpassung, Garantie
A16: M-012 | B16: Zu prüfen | C16: R-012 / FIN-04 | D16: SPA / Signing | E16: Financial | F16: Nur belegte, nachhaltige Adjustments akzeptieren und Bewertungsbasis anpassen. | G16: Maßnahme für FIN-04 dokumentiert, fachlich abgenommen und durch belastbare Evidenz geschlossen. | H16: Kritisch | M16: Nicht gestartet | N16: 0 | Q16: Bewertung/Kaufpreis | R16: Evidenz im VDR; Reviewer-Freigabe | S16: Fristüberschreitung oder Score ≥17 | T16: Preisformel, Earn-out
... A64: M-060 | B64: Zu prüfen | C64: R-060 / HR-06 | D64: Pre-Signing | E64: HR & Pensions | F64: Mitbestimmungsfahrplan und Kommunikationsplan als kritischen Pfad führen. | G64: Maßnahme für HR-06 dokumentiert, fachlich abgenommen und durch belastbare Evidenz geschlossen. | H64: Kritisch | M64: Nicht gestartet | N64: 0 | Q64: Closing-Bedingung | R64: Evidenz im VDR; Reviewer-Freigabe | S64: Fristüberschreitung oder Score ≥17 | T64: Covenant

Sheet 06_Q&A
A1: Q&A-Tracker
A2: Fragen konkret, neutral und entscheidungsorientiert formulieren. Mündliche Antworten schriftlich bestätigen und mit Evidenz verknüpfen.
A4: Q&A-ID | B4: Erstellt am | C4: Prüfbereich | D4: Check-/Dok-Ref. | E4: Frage | F4: Begründung / Entscheidungskontext | G4: Priorität | H4: Empfänger | I4: Fragesteller | J4: Fällig | K4: Antwort am | L4: Status | M4: Antwort | N4: Evidenz / VDR-Link | O4: Nachfrage / Next Step | P4: Alter (Tage) | Q4: Überfällig? | R4: Reviewer
A5: Q-001 | L5: Entwurf | P5: =IF(B5="","",IF(K5<>"",K5-B5,TODAY()-B5)) | Q5: =IF(OR(J5="",L5="Beantwortet",L5="Geschlossen"),"",IF(TODAY()>J5,"Ja","Nein"))
A6: Q-002 | L6: Entwurf | P6: =IF(B6="","",IF(K6<>"",K6-B6,TODAY()-B6)) | Q6: =IF(OR(J6="",L6="Beantwortet",L6="Geschlossen"),"",IF(TODAY()>J6,"Ja","Nein"))
A7: Q-003 | L7: Entwurf | P7: =IF(B7="","",IF(K7<>"",K7-B7,TODAY()-B7)) | Q7: =IF(OR(J7="",L7="Beantwortet",L7="Geschlossen"),"",IF(TODAY()>J7,"Ja","Nein"))
A8: Q-004 | L8: Entwurf | P8: =IF(B8="","",IF(K8<>"",K8-B8,TODAY()-B8)) | Q8: =IF(OR(J8="",L8="Beantwortet",L8="Geschlossen"),"",IF(TODAY()>J8,"Ja","Nein"))
A9: Q-005 | L9: Entwurf | P9: =IF(B9="","",IF(K9<>"",K9-B9,TODAY()-B9)) | Q9: =IF(OR(J9="",L9="Beantwortet",L9="Geschlossen"),"",IF(TODAY()>J9,"Ja","Nein"))
A10: Q-006 | L10: Entwurf | P10: =IF(B10="","",IF(K10<>"",K10-B10,TODAY()-B10)) | Q10: =IF(OR(J10="",L10="Beantwortet",L10="Geschlossen"),"",IF(TODAY()>J10,"Ja","Nein"))
A11: Q-007 | L11: Entwurf | P11: =IF(B11="","",IF(K11<>"",K11-B11,TODAY()-B11)) | Q11: =IF(OR(J11="",L11="Beantwortet",L11="Geschlossen"),"",IF(TODAY()>J11,"Ja","Nein"))
A12: Q-008 | L12: Entwurf | P12: =IF(B12="","",IF(K12<>"",K12-B12,TODAY()-B12)) | Q12: =IF(OR(J12="",L12="Beantwortet",L12="Geschlossen"),"",IF(TODAY()>J12,"Ja","Nein"))
A13: Q-009 | L13: Entwurf | P13: =IF(B13="","",IF(K13<>"",K13-B13,TODAY()-B13)) | Q13: =IF(OR(J13="",L13="Beantwortet",L13="Geschlossen"),"",IF(TODAY()>J13,"Ja","Nein"))
A14: Q-010 | L14: Entwurf | P14: =IF(B14="","",IF(K14<>"",K14-B14,TODAY()-B14)) | Q14: =IF(OR(J14="",L14="Beantwortet",L14="Geschlossen"),"",IF(TODAY()>J14,"Ja","Nein"))
A15: Q-011 | L15: Entwurf | P15: =IF(B15="","",IF(K15<>"",K15-B15,TODAY()-B15)) | Q15: =IF(OR(J15="",L15="Beantwortet",L15="Geschlossen"),"",IF(TODAY()>J15,"Ja","Nein"))
A16: Q-012 | L16: Entwurf | P16: =IF(B16="","",IF(K16<>"",K16-B16,TODAY()-B16)) | Q16: =IF(OR(J16="",L16="Beantwortet",L16="Geschlossen"),"",IF(TODAY()>J16,"Ja","Nein"))
... A104: Q-100 | L104: Entwurf | P104: =IF(B104="","",IF(K104<>"",K104-B104,TODAY()-B104)) | Q104: =IF(OR(J104="",L104="Beantwortet",L104="Geschlossen"),"",IF(TODAY()>J104,"Ja","Nein"))

Sheet 07_Finanzanalyse
A1: Finanzanalyse
A2: Eingaben positiv erfassen (auch Aufwendungen und Schulden); Formeln ziehen Kosten ab. Periodenbezeichnungen können überschrieben werden.
A4: Kennzahl | B4: 2022A | C4: 2023A | D4: 2024A | E4: LTM / aktuell | F4: Budget | G4: Δ LTM vs. 2024 | H4: Δ LTM vs. Budget | I4: Kommentar / Quelle
A5: Umsatz | G5: =IFERROR(E5/D5-1,"") | H5: =IFERROR(E5/F5-1,"")
A6: Umsatzkosten (COGS) | G6: =IFERROR(E6/D6-1,"") | H6: =IFERROR(E6/F6-1,"")
A7: Bruttoergebnis | B7: =B5-B6 -> 0 | C7: =C5-C6 -> 0 | D7: =D5-D6 -> 0 | E7: =E5-E6 -> 0 | F7: =F5-F6 -> 0 | G7: =IFERROR(E7/D7-1,"") | H7: =IFERROR(E7/F7-1,"")
A8: Bruttomarge | B8: =IFERROR(B7/B5,"") | C8: =IFERROR(C7/C5,"") | D8: =IFERROR(D7/D5,"") | E8: =IFERROR(E7/E5,"") | F8: =IFERROR(F7/F5,"") | G8: =IFERROR(E8/D8-1,"") | H8: =IFERROR(E8/F8-1,"")
A9: Personalaufwand | G9: =IFERROR(E9/D9-1,"") | H9: =IFERROR(E9/F9-1,"")
A10: Sonstige Opex | G10: =IFERROR(E10/D10-1,"") | H10: =IFERROR(E10/F10-1,"")
A11: EBITDA berichtet | G11: =IFERROR(E11/D11-1,"") | H11: =IFERROR(E11/F11-1,"")
A12: QoE-Anpassungen (netto) | G12: =IFERROR(E12/D12-1,"") | H12: =IFERROR(E12/F12-1,"")
