Workbook

Sheet Uebersicht
A1: TVF ALTWERT – gerettete Zahlen
A3: Quelle | B3: Inhalt | C3: Zeilen
A4: database.sql | B4: projekte | C4: 153
A5: database.sql | B5: kostenarten | C5: 108
A6: database.sql | B6: buchungen (aggregiert) | C6: 10509
A7: database.sql | B7: buchungen_agg_auftrag_periode | C7: 685
A8: database.sql | B8: buchungen_agg_periode | C8: 8
A9: Excel-Dateien | B9: Blätter exportiert | C9: 19
A12: Hinweis: Buchungen sind auf Auftrag×Periode und Kostenart summiert (keine 10.509 Einzelzeilen im Excel).
A13: Vollständige Belege bleiben in db/database.sql. CSVs liegen unter zahlen/.

Sheet Projekte
A1: projekt_nr | B1: projektname | C1: projektart | D1: status | E1: budget_umsatz | F1: budget_kosten
A2: P4102157208 | B2: Waggonverschrottung | C2: RECYCLING
A3: P4102157411 | B3: ARGE RB Chemiepark Krefeld | C3: SONSTIGES
A4: P4102157414 | B4: Krandemontage | C4: SONSTIGES
A5: P4102157420 | B5: ARGE RB GWA+SGA 4 | C5: SONSTIGES
A6: P4102157429 | B6: Covestro - Rückbau LEV O13 | C6: BAU
A7: P4102157431 | B7: RB drei Sandfilter | C7: SONSTIGES
A8: P4102157436 | B8: Sanierung Kompensatoren | C8: BAU
A9: P4102157439 | B9: RB Sperrmüllschereefeld | C9: SONSTIGES
A10: P4102157440 | B10: tkse RB 2025 | C10: SONSTIGES
A11: P4102157442 | B11: RB Leitstand Flämmaschine | C11: SONSTIGES
A12: P4102157443 | B12: Medice Arzneim. RB 2 Tanks | C12: SONSTIGES
A13: P4102157445 | B13: RB 2 Stahlwände Lüra Halle | C13: SONSTIGES
... A154: W4102654947 | B154: CB-TV 200 Hr. Adil | C154: SONSTIGES

Sheet Kostenarten
A1: kostenart_nr | B1: bezeichnung | C1: klr_typ | D1: db_stufe | E1: guv_gruppe
A2: 201000.0 | B2: Sonstige periodenfremde Aufwendungen | C2: AUTO | D2: 3
A3: 340050.0 | B3: Fremdleistungen Wartung/Pflege | C3: AUTO | D3: 1
A4: 392000.0 | B4: Bestandsveränderungen unfertige Erzeugni | C4: AUTO | D4: 3
A5: 830510.0 | B5: Erlöse Abrisse/Demontagen | C5: AUTO | D5: 1
A6: 7611200.0 | B6: Lohnverr. Gruppe 2 | C6: AUTO | D6: 1
A7: 7612000.0 | B7: Verrechnung Geräte | C7: AUTO | D7: 3
A8: 7801020.0 | B8: Gemeinkostenzuschläge 12 % TVF Altwert | C8: AUTO | D8: 3
A9: 330900.0 | B9: Erhaltene Skonti | C9: AUTO | D9: 3
A10: 401000.0 | B10: Aufwand Diesel | C10: AUTO | D10: 1
A11: 7611100.0 | B11: Lohnverr. Gruppe1 | C11: AUTO | D11: 1
A12: 430120.0 | B12: Sonstige Versicherungen | C12: AUTO | D12: 3
A13: 411100.0 | B13: Arbeitskleidung und Arbeitschutzbedarf | C13: AUTO | D13: 3
... A109: 400010.0 | B109: Instandhaltung Lastkraftwagen | C109: AUTO | D109: 3

Sheet Buch_Periode
A1: geschaeftsjahr | B1: periode | C1: summe_wert | D1: anzahl
C2: -361720.87 | D2: 1
A3: 2026 | B3: 1 | C3: 3400.72 | D3: 1114
A4: 2026 | B4: 2 | C4: -102745.45 | D4: 1452
A5: 2026 | B5: 3 | C5: -26736.68 | D5: 1667
A6: 2026 | B6: 4 | C6: -121673.39 | D6: 1618
A7: 2026 | B7: 5 | C7: 60196.64 | D7: 1481
A8: 2026 | B8: 6 | C8: -40137.29 | D8: 1607
A9: 2026 | B9: 7 | C9: -134025.42 | D9: 1569

Sheet Buch_Projekt
A1: auftrag | B1: summe_wert | C1: anzahl
A2: W4102154411 | B2: -471490.44 | C2: 599
B3: -361720.87 | C3: 1
A4: P4102307433 | B4: -340000 | C4: 381
A5: W4102504222 | B5: 330945.91 | C5: 448
A6: W4102604411 | B6: -311659.58 | C6: 388
A7: P4102157453 | B7: 310103.49 | C7: 321
A8: W4102304411 | B8: -239877.66 | C8: 459
A9: W4102504951 | B9: 101941.74 | C9: 28
A10: P4102608263 | B10: -69639.61 | C10: 296
A11: P4102307444 | B11: -66000 | C11: 103
A12: P4102658225 | B12: 63000 | C12: 9
A13: W4102304611 | B13: 60077.82 | C13: 212
A14: W4102504262 | B14: 56472.63 | C14: 119
A15: W4102654411 | B15: -50206.3 | C15: 232
... A155: W4102607081 | B155: 0 | C155: 28

Sheet Buch_Kostenart
A1: kostenart | B1: summe_wert | C1: anzahl
A2: 7801020.0 | B2: -1366941.2 | C2: 884
A3: 830510.0 | B3: -392267.57 | C3: 858
B4: -361720.87 | C4: 1
A5: 392000.0 | B5: 310103.49 | C5: 243
A6: 470020.0 | B6: 81996 | C6: 67
A7: 410130.0 | B7: 67438 | C7: 38
A8: 400122.0 | B8: 64936.13 | C8: 126
A9: 431010.0 | B9: 63951.15 | C9: 70
A10: 201000.0 | B10: 55572.04 | C10: 61
A11: 470025.0 | B11: 54022.7 | C11: 7
A12: 220000.0 | B12: 51592 | C12: 2
A13: 430020.0 | B13: 47216 | C13: 22
A14: 400030.0 | B14: 46967.97 | C14: 4
A15: 274200.0 | B15: -46186.04 | C15: 2
A16: 430120.0 | B16: 40917.11 | C16: 140
... A110: 265900.0 | B110: 0 | C110: 2

Sheet Buch_AuftragPeriode
A1: geschaeftsjahr | B1: periode | C1: auftrag | D1: summe_wert | E1: anzahl
D2: -361720.87 | E2: 1
A3: 2026 | B3: 1 | C3: P4102157208 | D3: 0 | E3: 6
A4: 2026 | B4: 1 | C4: P4102157414 | D4: 0 | E4: 6
A5: 2026 | B5: 1 | C5: P4102157420 | D5: 0 | E5: 8
A6: 2026 | B6: 1 | C6: P4102157429 | D6: 0 | E6: 16
A7: 2026 | B7: 1 | C7: P4102157440 | D7: 0 | E7: 6
A8: 2026 | B8: 1 | C8: P4102157443 | D8: 0 | E8: 4
A9: 2026 | B9: 1 | C9: P4102157447 | D9: 0 | E9: 2
A10: 2026 | B10: 1 | C10: P4102157449 | D10: 0 | E10: 37
A11: 2026 | B11: 1 | C11: P4102157451 | D11: 0 | E11: 50
A12: 2026 | B12: 1 | C12: P4102157453 | D12: 0 | E12: 44
A13: 2026 | B13: 1 | C13: P4102157455 | D13: 0 | E13: 13
A14: 2026 | B14: 1 | C14: P4102157457 | D14: 0 | E14: 4
... A686: 2026 | B686: 7 | C686: W4102654947 | D686: 350.27 | E686: 2

Sheet Import Monatsdaten_Import Monat
C2: Importierte Monats-GuV
C3: Befüllung über TVF_Import.ts. Eine Zeile je Jahr und Monat. Vorhandene Monate werden gezielt ersetzt. Originalquellen bleiben erhalten.
C6: Jahr | D6: Monat | E6: Umsatz | F6: Bestand | G6: Sonstige_Ertraege | H6: Materialaufwand | I6: Personalaufwand | J6: Sonstiger_Aufwand | K6: Abschreibungen | L6: Finanzergebnis | M6: Neutrales_Ergebnis
C63: SharePoint-Verknüpfungen (Dateien im selben Ordner)
C64: Diese Datei | D64: Import Monatsdaten.xlsx

Sheet GuV_GuV
C2: GuV und EBITDA
C3: Importierte Monatsdaten haben Vorrang vor dem Originalexport. Quelle je Monat in Zeile 23. Aufwendungen negativ, Beträge in EUR.
C5: Position | F5: 1 | G5: 2 | H5: 3 | I5: 4 | J5: 5 | K5: 6 | L5: 7 | M5: 8 | N5: 9 | O5: 10 | P5: 11 | Q5: 12
C6: Position | D6: YTD | E6: Anteil | F6: Jan | G6: Feb | H6: Mär | I6: Apr | J6: Mai | K6: Jun | L6: Jul | M6: Aug | N6: Sep | O6: Okt | P6: Nov | Q6: Dez
C7: Umsatzerlöse | D7: =SUMIFS(F7:Q7,$F$5:$Q$5,"<="&'[Steuerung.xlsx]Steuerung'!$F$7) | E7: =IF($D$9=0,"n.a.",D7/$D$9) | F7: =IF(COUNTIFS('[Import Monatsdaten.xlsx]Import Monatsdaten'!$C$7:$C$8,'[Steuerung.xlsx]Steuerung'!$F$6,'[Import Monatsdaten.xlsx]Import Monatsdaten'!$D$7:$D$8,1)>0,SUMIFS('[Import Monatsdaten.xlsx]Import Monatsdaten'!$E$7:$E$8,'[Import Monatsdaten.xlsx]Import Monatsdaten'!$C$7:$C$8,'[Steuerung.xlsx]Steuerung'!$F$6,'[Import Monatsdaten.xlsx]Import Monatsdaten'!$D$7:$D$8,1),IF(COUNTIFS('[D Finanzen.xlsx]D Finanzen'!$A$45:$A$115,'[Steuerung.xlsx]Steuerung'!$F$6,'[D Finanzen.xlsx]D Finanzen'!$B$45:$B$115,F$5)=0,"",SUMIFS('[D Finanzen.xlsx]D Finanzen'!$E$45:$E$115,'[D Finanzen.xlsx]D Finanzen'!$A$45:$A$115,'[Steuerung.xlsx]Steuerung'!$F$6,'[D Finanzen.xlsx]D Finanzen'!$B$45:$B$115,F$5,'[D Finanzen.xlsx]D Finanzen'!$C$45:$C$115,10))) | G7: =IF(COUNTIFS('[Import Monatsdaten.xlsx]Import Monatsdaten'!$C$7:$C$8,'[Steuerung.xlsx]Steuerung'!$F$6,'[Import Monatsdaten.xlsx]Import Monatsdaten'!$D$7:$D$8,2)>0,SUMIFS('[Import Monatsdaten.xlsx]Import Monatsdaten'!$E$7:$E$8,'[Import Monatsdaten.xlsx]Import Monatsdaten'!$C$7:$C$8,'[Steuerung.xlsx]Steuerung'!$F$6,'[Import Monatsdaten.xlsx]Import Monatsdaten'!$D$7:$D$8,2),IF(COUNTIFS('[D Finanzen.xlsx]D Finanzen'!$A$45:$A$115,'[Steuerung.xlsx]Steuerung'!$F$6,'[D Finanzen.xlsx]D Finanzen'!$B$45:$B$115,G$5)=0,"",SUMIFS('[D Finanzen.xlsx]D Finanzen'!$E$45:$E$115,'[D Finanzen.xlsx]D Finanzen'!$A$45:$A$115,'[Steuerung.xlsx]Steuerung'!$F$6,'[D Finanzen.xlsx]D Finanzen'!$B$45:$B$115,G$5,'[D Finanzen.xlsx]D Finanzen'!$C$45:$C$115,10))) | H7: =IF(COUNTIFS('[Import Monatsdaten.xlsx]Import Monatsdaten'!$C$7:$C$8,'[Steuerung.xlsx]Steuerung'!$F$6,'[Import Monatsdaten.xlsx]Import Monatsdaten'!$D$7:$D$8,3)>0,SUMIFS('[Import Monatsdaten.xlsx]Import Monatsdaten'!$E$7:$E$8,'[Import Monatsdaten.xlsx]Import Monatsdaten'!$C$7:$C$8,'[Steuerung.xlsx]Steuerung'!$F$6,'[Import Monatsdaten.xlsx]Import Monatsdaten'!$D$7:$D$8,3),IF(COUNTIFS('[D Finanzen.xlsx]D Finanzen'!$A$45:$A$115,'[Steuerung.xlsx]Steuerung'!$F$6,'[D Finanzen.xlsx]D Finanzen'!$B$45:$B$115,H$5)=0,"",SUMIFS('[D Finanzen.xlsx]D Finanzen'!$E$45:$E$115,'[D Finanzen.xlsx]D Finanzen'!$A$45:$A$115,'[Steuerung.xlsx]Steuerung'!$F$6,'[D Finanzen.xlsx]D Finanzen'!$B$45:$B$115,H$5,'[D Finanzen.xlsx]D Finanzen'!$C$45:$C$115,10))) | I7: =IF(COUNTIFS('[Import Monatsdaten.xlsx]Import Monatsdaten'!$C$7:$C$8,'[Steuerung.xlsx]Steuerung'!$F$6,'[Import Monatsdaten.xlsx]Import Monatsdaten'!$D$7:$D$8,4)>0,SUMIFS('[Import Monatsdaten.xlsx]Import Monatsdaten'!$E$7:$E$8,'[Import Monatsdaten.xlsx]Import Monatsdaten'!$C$7:$C$8,'[Steuerung.xlsx]Steuerung'!$F$6,'[Import Monatsdaten.xlsx]Import Monatsdaten'!$D$7:$D$8,4),IF(COUNTIFS('[D Finanzen.xlsx]D Finanzen'!$A$45:$A$115,'[Steuerung.xlsx]Steuerung'!$F$6,'[D Finanzen.xlsx]D Finanzen'!$B$45:$B$115,I$5)=0,"",SUMIFS('[D Finanzen.xlsx]D Finanzen'!$E$45:$E$115,'[D Finanzen.xlsx]D Finanzen'!$A$45:$A$115,'[Steuerung.xlsx]Steuerung'!$F$6,'[D Finanzen.xlsx]D Finanzen'!$B$45:$B$115,I$5,'[D Finanzen.xlsx]D Finanzen'!$C$45:$C$115,10))) | J7: =IF(COUNTIFS('[Import Monatsdaten.xlsx]Import Monatsdaten'!$C$7:$C$8,'[Steuerung.xlsx]Steuerung'!$F$6,'[Import Monatsdaten.xlsx]Import Monatsdaten'!$D$7:$D$8,5)>0,SUMIFS('[Import Monatsdaten.xlsx]Import Monatsdaten'!$E$7:$E$8,'[Import Monatsdaten.xlsx]Import Monatsdaten'!$C$7:$C$8,'[Steuerung.xlsx]Steuerung'!$F$6,'[Import Monatsdaten.xlsx]Import Monatsdaten'!$D$7:$D$8,5),IF(COUNTIFS('[D Finanzen.xlsx]D Finanzen'!$A$45:$A$115,'[Steuerung.xlsx]Steuerung'!$F$6,'[D Finanzen.xlsx]D Finanzen'!$B$45:$B$115,J$5)=0,"",SUMIFS('[D Finanzen.xlsx]D Finanzen'!$E$45:$E$115,'[D Finanzen.xlsx]D Finanzen'!$A$45:$A$115,'[Steuerung.xlsx]Steuerung'!$F$6,'[D Finanzen.xlsx]D Finanzen'!$B$45:$B$115,J$5,'[D Finanzen.xlsx]D Finanzen'!$C$45:$C$115,10))) | K7: =IF(COUNTIFS('[Import Monatsdaten.xlsx]Import Monatsdaten'!$C$7:$C$8,'[Steuerung.xlsx]Steuerung'!$F$6,'[Import Monatsdaten.xlsx]Import Monatsdaten'!$D$7:$D$8,6)>0,SUMIFS('[Import Monatsdaten.xlsx]Import Monatsdaten'!$E$7:$E$8,'[Import Monatsdaten.xlsx]Import Monatsdaten'!$C$7:$C$8,'[Steuerung.xlsx]Steuerung'!$F$6,'[Import Monatsdaten.xlsx]Import Monatsdaten'!$D$7:$D$8,6),IF(COUNTIFS('[D Finanzen.xlsx]D Finanzen'!$A$45:$A$115,'[Steuerung.xlsx]Steuerung'!$F$6,'[D Finanzen.xlsx]D Finanzen'!$B$45:$B$115,K$5)=0,"",SUMIFS('[D Finanzen.xlsx]D Finanzen'!$E$45:$E$115,'[D Finanzen.xlsx]D Finanzen'!$A$45:$A$115,'[Steuerung.xlsx]Steuerung'!$F$6,'[D Finanzen.xlsx]D Finanzen'!$B$45:$B$115,K$5,'[D Finanzen.xlsx]D Finanzen'!$C$45:$C$115,10))) | L7: =IF(COUNTIFS('[Import Monatsdaten.xlsx]Import Monatsdaten'!$C$7:$C$8,'[Steuerung.xlsx]Steuerung'!$F$6,'[Import Monatsdaten.xlsx]Import Monatsdaten'!$D$7:$D$8,7)>0,SUMIFS('[Import Monatsdaten.xlsx]Import Monatsdaten'!$E$7:$E$8,'[Import Monatsdaten.xlsx]Import Monatsdaten'!$C$7:$C$8,'[Steuerung.xlsx]Steuerung'!$F$6,'[Import Monatsdaten.xlsx]Import Monatsdaten'!$D$7:$D$8,7),IF(COUNTIFS('[D Finanzen.xlsx]D Finanzen'!$A$45:$A$115,'[Steuerung.xlsx]Steuerung'!$F$6,'[D Finanzen.xlsx]D Finanzen'!$B$45:$B$115,L$5)=0,"",SUMIFS('[D Finanzen.xlsx]D Finanzen'!$E$45:$E$115,'[D Finanzen.xlsx]D Finanzen'!$A$45:$A$115,'[Steuerung.xlsx]Steuerung'!$F$6,'[D Finanzen.xlsx]D Finanzen'!$B$45:$B$115,L$5,'[D Finanzen.xlsx]D Finanzen'!$C$45:$C$115,10))) | M7: =IF(COUNTIFS('[Import Monatsdaten.xlsx]Import Monatsdaten'!$C$7:$C$8,'[Steuerung.xlsx]Steuerung'!$F$6,'[Import Monatsdaten.xlsx]Import Monatsdaten'!$D$7:$D$8,8)>0,SUMIFS('[Import Monatsdaten.xlsx]Import Monatsdaten'!$E$7:$E$8,'[Import Monatsdaten.xlsx]Import Monatsdaten'!$C$7:$C$8,'[Steuerung.xlsx]Steuerung'!$F$6,'[Import Monatsdaten.xlsx]Import Monatsdaten'!$D$7:$D$8,8),IF(COUNTIFS('[D Finanzen.xlsx]D Finanzen'!$A$45:$A$115,'[Steuerung.xlsx]Steuerung'!$F$6,'[D Finanzen.xlsx]D Finanzen'!$B$45:$B$115,M$5)=0,"",SUMIFS('[D Finanzen.xlsx]D Finanzen'!$E$45:$E$115,'[D Finanzen.xlsx]D Finanzen'!$A$45:$A$115,'[Steuerung.xlsx]Steuerung'!$F$6,'[D Finanzen.xlsx]D Finanzen'!$B$45:$B$115,M$5,'[D Finanzen.xlsx]D Finanzen'!$C$45:$C$115,10))) | N7: =IF(COUNTIFS('[Import Monatsdaten.xlsx]Import Monatsdaten'!$C$7:$C$8,'[Steuerung.xlsx]Steuerung'!$F$6,'[Import Monatsdaten.xlsx]Import Monatsdaten'!$D$7:$D$8,9)>0,SUMIFS('[Import Monatsdaten.xlsx]Import Monatsdaten'!$E$7:$E$8,'[Import Monatsdaten.xlsx]Import Monatsdaten'!$C$7:$C$8,'[Steuerung.xlsx]Steuerung'!$F$6,'[Import Monatsdaten.xlsx]Import Monatsdaten'!$D$7:$D$8,9),IF(COUNTIFS('[D Finanzen.xlsx]D Finanzen'!$A$45:$A$115,'[Steuerung.xlsx]Steuerung'!$F$6,'[D Finanzen.xlsx]D Finanzen'!$B$45:$B$115,N$5)=0,"",SUMIFS('[D Finanzen.xlsx]D Finanzen'!$E$45:$E$115,'[D Finanzen.xlsx]D Finanzen'!$A$45:$A$115,'[Steuerung.xlsx]Steuerung'!$F$6,'[D Finanzen.xlsx]D Finanzen'!$B$45:$B$115,N$5,'[D Finanzen.xlsx]D Finanzen'!$C$45:$C$115,10))) | O7: =IF(COUNTIFS('[Import Monatsdaten.xlsx]Import Monatsdaten'!$C$7:$C$8,'[Steuerung.xlsx]Steuerung'!$F$6,'[Import Monatsdaten.xlsx]Import Monatsdaten'!$D$7:$D$8,10)>0,SUMIFS('[Import Monatsdaten.xlsx]Import Monatsdaten'!$E$7:$E$8,'[Import Monatsdaten.xlsx]Import Monatsdaten'!$C$7:$C$8,'[Steuerung.xlsx]Steuerung'!$F$6,'[Import Monatsdaten.xlsx]Import Monatsdaten'!$D$7:$D$8,10),IF(COUNTIFS('[D Finanzen.xlsx]D Finanzen'!$A$45:$A$115,'[Steuerung.xlsx]Steuerung'!$F$6,'[D Finanzen.xlsx]D Finanzen'!$B$45:$B$115,O$5)=0,"",SUMIFS('[D Finanzen.xlsx]D Finanzen'!$E$45:$E$115,'[D Finanzen.xlsx]D Finanzen'!$A$45:$A$115,'[Steuerung.xlsx]Steuerung'!$F$6,'[D Finanzen.xlsx]D Finanzen'!$B$45:$B$115,O$5,'[D Finanzen.xlsx]D Finanzen'!$C$45:$C$115,10))) | P7: =IF(COUNTIFS('[Import Monatsdaten.xlsx]Import Monatsdaten'!$C$7:$C$8,'[Steuerung.xlsx]Steuerung'!$F$6,'[Import Monatsdaten.xlsx]Import Monatsdaten'!$D$7:$D$8,11)>0,SUMIFS('[Import Monatsdaten.xlsx]Import Monatsdaten'!$E$7:$E$8,'[Import Monatsdaten.xlsx]Import Monatsdaten'!$C$7:$C$8,'[Steuerung.xlsx]Steuerung'!$F$6,'[Import Monatsdaten.xlsx]Import Monatsdaten'!$D$7:$D$8,11),IF(COUNTIFS('[D Finanzen.xlsx]D Finanzen'!$A$45:$A$115,'[Steuerung.xlsx]Steuerung'!$F$6,'[D Finanzen.xlsx]D Finanzen'!$B$45:$B$115,P$5)=0,"",SUMIFS('[D Finanzen.xlsx]D Finanzen'!$E$45:$E$115,'[D Finanzen.xlsx]D Finanzen'!$A$45:$A$115,'[Steuerung.xlsx]Steuerung'!$F$6,'[D Finanzen.xlsx]D Finanzen'!$B$45:$B$115,P$5,'[D Finanzen.xlsx]D Finanzen'!$C$45:$C$115,10))) | Q7: =IF(COUNTIFS('[Import Monatsdaten.xlsx]Import Monatsdaten'!$C$7:$C$8,'[Steuerung.xlsx]Steuerung'!$F$6,'[Import Monatsdaten.xlsx]Import Monatsdaten'!$D$7:$D$8,12)>0,SUMIFS('[Import Monatsdaten.xlsx]Import Monatsdaten'!$E$7:$E$8,'[Import Monatsdaten.xlsx]Import Monatsdaten'!$C$7:$C$8,'[Steuerung.xlsx]Steuerung'!$F$6,'[Import Monatsdaten.xlsx]Import Monatsdaten'!$D$7:$D$8,12),IF(COUNTIFS('[D Finanzen.xlsx]D Finanzen'!$A$45:$A$115,'[Steuerung.xlsx]Steuerung'!$F$6,'[D Finanzen.xlsx]D Finanzen'!$B$45:$B$115,Q$5)=0,"",SUMIFS('[D Finanzen.xlsx]D Finanzen'!$E$45:$E$115,'[D Finanzen.xlsx]D Finanzen'!$A$45:$A$115,'[Steuerung.xlsx]Steuerung'!$F$6,'[D Finanzen.xlsx]D Finanzen'!$B$45:$B$115,Q$5,'[D Finanzen.xlsx]D Finanzen'!$C$45:$C$115,10)))
C8: Bestandsveränderungen | D8: =SUMIFS(F8:Q8,$F$5:$Q$5,"<="&'[Steuerung.xlsx]Steuerung'!$F$7) | E8: =IF($D$9=0,"n.a.",D8/$D$9) | F8: =IF(COUNTIFS('[Import Monatsdaten.xlsx]Import Monatsdaten'!$C$7:$C$8,'[Steuerung.xlsx]Steuerung'!$F$6,'[Import Monatsdaten.xlsx]Import Monatsdaten'!$D$7:$D$8,1)>0,SUMIFS('[Import Monatsdaten.xlsx]Import Monatsdaten'!$F$7:$F$8,'[Import Monatsdaten.xlsx]Import Monatsdaten'!$C$7:$C$8,'[Steuerung.xlsx]Steuerung'!$F$6,'[Import Monatsdaten.xlsx]Import Monatsdaten'!$D$7:$D$8,1),IF(COUNTIFS('[D Finanzen.xlsx]D Finanzen'!$A$45:$A$115,'[Steuerung.xlsx]Steuerung'!$F$6,'[D Finanzen.xlsx]D Finanzen'!$B$45:$B$115,F$5)=0,"",SUMIFS('[D Finanzen.xlsx]D Finanzen'!$E$45:$E$115,'[D Finanzen.xlsx]D Finanzen'!$A$45:$A$115,'[Steuerung.xlsx]Steuerung'!$F$6,'[D Finanzen.xlsx]D Finanzen'!$B$45:$B$115,F$5,'[D Finanzen.xlsx]D Finanzen'!$C$45:$C$115,20))) | G8: =IF(COUNTIFS('[Import Monatsdaten.xlsx]Import Monatsdaten'!$C$7:$C$8,'[Steuerung.xlsx]Steuerung'!$F$6,'[Import Monatsdaten.xlsx]Import Monatsdaten'!$D$7:$D$8,2)>0,SUMIFS('[Import Monatsdaten.xlsx]Import Monatsdaten'!$F$7:$F$8,'[Import Monatsdaten.xlsx]Import Monatsdaten'!$C$7:$C$8,'[Steuerung.xlsx]Steuerung'!$F$6,'[Import Monatsdaten.xlsx]Import Monatsdaten'!$D$7:$D$8,2),IF(COUNTIFS('[D Finanzen.xlsx]D Finanzen'!$A$45:$A$115,'[Steuerung.xlsx]Steuerung'!$F$6,'[D Finanzen.xlsx]D Finanzen'!$B$45:$B$115,G$5)=0,"",SUMIFS('[D Finanzen.xlsx]D Finanzen'!$E$45:$E$115,'[D Finanzen.xlsx]D Finanzen'!$A$45:$A$115,'[Steuerung.xlsx]Steuerung'!$F$6,'[D Finanzen.xlsx]D Finanzen'!$B$45:$B$115,G$5,'[D Finanzen.xlsx]D Finanzen'!$C$45:$C$115,20))) | H8: =IF(COUNTIFS('[Import Monatsdaten.xlsx]Import Monatsdaten'!$C$7:$C$8,'[Steuerung.xlsx]Steuerung'!$F$6,'[Import Monatsdaten.xlsx]Import Monatsdaten'!$D$7:$D$8,3)>0,SUMIFS('[Import Monatsdaten.xlsx]Import Monatsdaten'!$F$7:$F$8,'[Import Monatsdaten.xlsx]Import Monatsdaten'!$C$7:$C$8,'[Steuerung.xlsx]Steuerung'!$F$6,'[Import Monatsdaten.xlsx]Import Monatsdaten'!$D$7:$D$8,3),IF(COUNTIFS('[D Finanzen.xlsx]D Finanzen'!$A$45:$A$115,'[Steuerung.xlsx]Steuerung'!$F$6,'[D Finanzen.xlsx]D Finanzen'!$B$45:$B$115,H$5)=0,"",SUMIFS('[D Finanzen.xlsx]D Finanzen'!$E$45:$E$115,'[D Finanzen.xlsx]D Finanzen'!$A$45:$A$115,'[Steuerung.xlsx]Steuerung'!$F$6,'[D Finanzen.xlsx]D Finanzen'!$B$45:$B$115,H$5,'[D Finanzen.xlsx]D Finanzen'!$C$45:$C$115,20))) | I8: =IF(COUNTIFS('[Import Monatsdaten.xlsx]Import Monatsdaten'!$C$7:$C$8,'[Steuerung.xlsx]Steuerung'!$F$6,'[Import Monatsdaten.xlsx]Import Monatsdaten'!$D$7:$D$8,4)>0,SUMIFS('[Import Monatsdaten.xlsx]Import Monatsdaten'!$F$7:$F$8,'[Import Monatsdaten.xlsx]Import Monatsdaten'!$C$7:$C$8,'[Steuerung.xlsx]Steuerung'!$F$6,'[Import Monatsdaten.xlsx]Import Monatsdaten'!$D$7:$D$8,4),IF(COUNTIFS('[D Finanzen.xlsx]D Finanzen'!$A$45:$A$115,'[Steuerung.xlsx]Steuerung'!$F$6,'[D Finanzen.xlsx]D Finanzen'!$B$45:$B$115,I$5)=0,"",SUMIFS('[D Finanzen.xlsx]D Finanzen'!$E$45:$E$115,'[D Finanzen.xlsx]D Finanzen'!$A$45:$A$115,'[Steuerung.xlsx]Steuerung'!$F$6,'[D Finanzen.xlsx]D Finanzen'!$B$45:$B$115,I$5,'[D Finanzen.xlsx]D Finanzen'!$C$45:$C$115,20))) | J8: =IF(COUNTIFS('[Import Monatsdaten.xlsx]Import Monatsdaten'!$C$7:$C$8,'[Steuerung.xlsx]Steuerung'!$F$6,'[Import Monatsdaten.xlsx]Import Monatsdaten'!$D$7:$D$8,5)>0,SUMIFS('[Import Monatsdaten.xlsx]Import Monatsdaten'!$F$7:$F$8,'[Import Monatsdaten.xlsx]Import Monatsdaten'!$C$7:$C$8,'[Steuerung.xlsx]Steuerung'!$F$6,'[Import Monatsdaten.xlsx]Import Monatsdaten'!$D$7:$D$8,5),IF(COUNTIFS('[D Finanzen.xlsx]D Finanzen'!$A$45:$A$115,'[Steuerung.xlsx]Steuerung'!$F$6,'[D Finanzen.xlsx]D Finanzen'!$B$45:$B$115,J$5)=0,"",SUMIFS('[D Finanzen.xlsx]D Finanzen'!$E$45:$E$115,'[D Finanzen.xlsx]D Finanzen'!$A$45:$A$115,'[Steuerung.xlsx]Steuerung'!$F$6,'[D Finanzen.xlsx]D Finanzen'!$B$45:$B$115,J$5,'[D Finanzen.xlsx]D Finanzen'!$C$45:$C$115,20))) | K8: =IF(COUNTIFS('[Import Monatsdaten.xlsx]Import Monatsdaten'!$C$7:$C$8,'[Steuerung.xlsx]Steuerung'!$F$6,'[Import Monatsdaten.xlsx]Import Monatsdaten'!$D$7:$D$8,6)>0,SUMIFS('[Import Monatsdaten.xlsx]Import Monatsdaten'!$F$7:$F$8,'[Import Monatsdaten.xlsx]Import Monatsdaten'!$C$7:$C$8,'[Steuerung.xlsx]Steuerung'!$F$6,'[Import Monatsdaten.xlsx]Import Monatsdaten'!$D$7:$D$8,6),IF(COUNTIFS('[D Finanzen.xlsx]D Finanzen'!$A$45:$A$115,'[Steuerung.xlsx]Steuerung'!$F$6,'[D Finanzen.xlsx]D Finanzen'!$B$45:$B$115,K$5)=0,"",SUMIFS('[D Finanzen.xlsx]D Finanzen'!$E$45:$E$115,'[D Finanzen.xlsx]D Finanzen'!$A$45:$A$115,'[Steuerung.xlsx]Steuerung'!$F$6,'[D Finanzen.xlsx]D Finanzen'!$B$45:$B$115,K$5,'[D Finanzen.xlsx]D Finanzen'!$C$45:$C$115,20))) | L8: =IF(COUNTIFS('[Import Monatsdaten.xlsx]Import Monatsdaten'!$C$7:$C$8,'[Steuerung.xlsx]Steuerung'!$F$6,'[Import Monatsdaten.xlsx]Import Monatsdaten'!$D$7:$D$8,7)>0,SUMIFS('[Import Monatsdaten.xlsx]Import Monatsdaten'!$F$7:$F$8,'[Import Monatsdaten.xlsx]Import Monatsdaten'!$C$7:$C$8,'[Steuerung.xlsx]Steuerung'!$F$6,'[Import Monatsdaten.xlsx]Import Monatsdaten'!$D$7:$D$8,7),IF(COUNTIFS('[D Finanzen.xlsx]D Finanzen'!$A$45:$A$115,'[Steuerung.xlsx]Steuerung'!$F$6,'[D Finanzen.xlsx]D Finanzen'!$B$45:$B$115,L$5)=0,"",SUMIFS('[D Finanzen.xlsx]D Finanzen'!$E$45:$E$115,'[D Finanzen.xlsx]D Finanzen'!$A$45:$A$115,'[Steuerung.xlsx]Steuerung'!$F$6,'[D Finanzen.xlsx]D Finanzen'!$B$45:$B$115,L$5,'[D Finanzen.xlsx]D Finanzen'!$C$45:$C$115,20))) | M8: =IF(COUNTIFS('[Import Monatsdaten.xlsx]Import Monatsdaten'!$C$7:$C$8,'[Steuerung.xlsx]Steuerung'!$F$6,'[Import Monatsdaten.xlsx]Import Monatsdaten'!$D$7:$D$8,8)>0,SUMIFS('[Import Monatsdaten.xlsx]Import Monatsdaten'!$F$7:$F$8,'[Import Monatsdaten.xlsx]Import Monatsdaten'!$C$7:$C$8,'[Steuerung.xlsx]Steuerung'!$F$6,'[Import Monatsdaten.xlsx]Import Monatsdaten'!$D$7:$D$8,8),IF(COUNTIFS('[D Finanzen.xlsx]D Finanzen'!$A$45:$A$115,'[Steuerung.xlsx]Steuerung'!$F$6,'[D Finanzen.xlsx]D Finanzen'!$B$45:$B$115,M$5)=0,"",SUMIFS('[D Finanzen.xlsx]D Finanzen'!$E$45:$E$115,'[D Finanzen.xlsx]D Finanzen'!$A$45:$A$115,'[Steuerung.xlsx]Steuerung'!$F$6,'[D Finanzen.xlsx]D Finanzen'!$B$45:$B$115,M$5,'[D Finanzen.xlsx]D Finanzen'!$C$45:$C$115,20))) | N8: =IF(COUNTIFS('[Import Monatsdaten.xlsx]Import Monatsdaten'!$C$7:$C$8,'[Steuerung.xlsx]Steuerung'!$F$6,'[Import Monatsdaten.xlsx]Import Monatsdaten'!$D$7:$D$8,9)>0,SUMIFS('[Import Monatsdaten.xlsx]Import Monatsdaten'!$F$7:$F$8,'[Import Monatsdaten.xlsx]Import Monatsdaten'!$C$7:$C$8,'[Steuerung.xlsx]Steuerung'!$F$6,'[Import Monatsdaten.xlsx]Import Monatsdaten'!$D$7:$D$8,9),IF(COUNTIFS('[D Finanzen.xlsx]D Finanzen'!$A$45:$A$115,'[Steuerung.xlsx]Steuerung'!$F$6,'[D Finanzen.xlsx]D Finanzen'!$B$45:$B$115,N$5)=0,"",SUMIFS('[D Finanzen.xlsx]D Finanzen'!$E$45:$E$115,'[D Finanzen.xlsx]D Finanzen'!$A$45:$A$115,'[Steuerung.xlsx]Steuerung'!$F$6,'[D Finanzen.xlsx]D Finanzen'!$B$45:$B$115,N$5,'[D Finanzen.xlsx]D Finanzen'!$C$45:$C$115,20))) | O8: =IF(COUNTIFS('[Import Monatsdaten.xlsx]Import Monatsdaten'!$C$7:$C$8,'[Steuerung.xlsx]Steuerung'!$F$6,'[Import Monatsdaten.xlsx]Import Monatsdaten'!$D$7:$D$8,10)>0,SUMIFS('[Import Monatsdaten.xlsx]Import Monatsdaten'!$F$7:$F$8,'[Import Monatsdaten.xlsx]Import Monatsdaten'!$C$7:$C$8,'[Steuerung.xlsx]Steuerung'!$F$6,'[Import Monatsdaten.xlsx]Import Monatsdaten'!$D$7:$D$8,10),IF(COUNTIFS('[D Finanzen.xlsx]D Finanzen'!$A$45:$A$115,'[Steuerung.xlsx]Steuerung'!$F$6,'[D Finanzen.xlsx]D Finanzen'!$B$45:$B$115,O$5)=0,"",SUMIFS('[D Finanzen.xlsx]D Finanzen'!$E$45:$E$115,'[D Finanzen.xlsx]D Finanzen'!$A$45:$A$115,'[Steuerung.xlsx]Steuerung'!$F$6,'[D Finanzen.xlsx]D Finanzen'!$B$45:$B$115,O$5,'[D Finanzen.xlsx]D Finanzen'!$C$45:$C$115,20))) | P8: =IF(COUNTIFS('[Import Monatsdaten.xlsx]Import Monatsdaten'!$C$7:$C$8,'[Steuerung.xlsx]Steuerung'!$F$6,'[Import Monatsdaten.xlsx]Import Monatsdaten'!$D$7:$D$8,11)>0,SUMIFS('[Import Monatsdaten.xlsx]Import Monatsdaten'!$F$7:$F$8,'[Import Monatsdaten.xlsx]Import Monatsdaten'!$C$7:$C$8,'[Steuerung.xlsx]Steuerung'!$F$6,'[Import Monatsdaten.xlsx]Import Monatsdaten'!$D$7:$D$8,11),IF(COUNTIFS('[D Finanzen.xlsx]D Finanzen'!$A$45:$A$115,'[Steuerung.xlsx]Steuerung'!$F$6,'[D Finanzen.xlsx]D Finanzen'!$B$45:$B$115,P$5)=0,"",SUMIFS('[D Finanzen.xlsx]D Finanzen'!$E$45:$E$115,'[D Finanzen.xlsx]D Finanzen'!$A$45:$A$115,'[Steuerung.xlsx]Steuerung'!$F$6,'[D Finanzen.xlsx]D Finanzen'!$B$45:$B$115,P$5,'[D Finanzen.xlsx]D Finanzen'!$C$45:$C$115,20))) | Q8: =IF(COUNTIFS('[Import Monatsdaten.xlsx]Import Monatsdaten'!$C$7:$C$8,'[Steuerung.xlsx]Steuerung'!$F$6,'[Import Monatsdaten.xlsx]Import Monatsdaten'!$D$7:$D$8,12)>0,SUMIFS('[Import Monatsdaten.xlsx]Import Monatsdaten'!$F$7:$F$8,'[Import Monatsdaten.xlsx]Import Monatsdaten'!$C$7:$C$8,'[Steuerung.xlsx]Steuerung'!$F$6,'[Import Monatsdaten.xlsx]Import Monatsdaten'!$D$7:$D$8,12),IF(COUNTIFS('[D Finanzen.xlsx]D Finanzen'!$A$45:$A$115,'[Steuerung.xlsx]Steuerung'!$F$6,'[D Finanzen.xlsx]D Finanzen'!$B$45:$B$115,Q$5)=0,"",SUMIFS('[D Finanzen.xlsx]D Finanzen'!$E$45:$E$115,'[D Finanzen.xlsx]D Finanzen'!$A$45:$A$115,'[Steuerung.xlsx]Steuerung'!$F$6,'[D Finanzen.xlsx]D Finanzen'!$B$45:$B$115,Q$5,'[D Finanzen.xlsx]D Finanzen'!$C$45:$C$115,20)))
C9: Gesamtleistung | D9: =SUMIFS(F9:Q9,$F$5:$Q$5,"<="&'[Steuerung.xlsx]Steuerung'!$F$7) | E9: =IF($D$9=0,"n.a.",D9/$D$9) | F9: =IF(F7="","",SUM(F7:F8)) | G9: =IF(G7="","",SUM(G7:G8)) | H9: =IF(H7="","",SUM(H7:H8)) | I9: =IF(I7="","",SUM(I7:I8)) | J9: =IF(J7="","",SUM(J7:J8)) | K9: =IF(K7="","",SUM(K7:K8)) | L9: =IF(L7="","",SUM(L7:L8)) | M9: =IF(M7="","",SUM(M7:M8)) | ... Q9: =IF(Q7="","",SUM(Q7:Q8))
C10: Sonstige betriebliche Erträge | D10: =SUMIFS(F10:Q10,$F$5:$Q$5,"<="&'[Steuerung.xlsx]Steuerung'!$F$7) | E10: =IF($D$9=0,"n.a.",D10/$D$9) | F10: =IF(COUNTIFS('[Import Monatsdaten.xlsx]Import Monatsdaten'!$C$7:$C$8,'[Steuerung.xlsx]Steuerung'!$F$6,'[Import Monatsdaten.xlsx]Import Monatsdaten'!$D$7:$D$8,1)>0,SUMIFS('[Import Monatsdaten.xlsx]Import Monatsdaten'!$G$7:$G$8,'[Import Monatsdaten.xlsx]Import Monatsdaten'!$C$7:$C$8,'[Steuerung.xlsx]Steuerung'!$F$6,'[Import Monatsdaten.xlsx]Import Monatsdaten'!$D$7:$D$8,1),IF(COUNTIFS('[D Finanzen.xlsx]D Finanzen'!$A$45:$A$115,'[Steuerung.xlsx]Steuerung'!$F$6,'[D Finanzen.xlsx]D Finanzen'!$B$45:$B$115,F$5)=0,"",SUMIFS('[D Finanzen.xlsx]D Finanzen'!$E$45:$E$115,'[D Finanzen.xlsx]D Finanzen'!$A$45:$A$115,'[Steuerung.xlsx]Steuerung'!$F$6,'[D Finanzen.xlsx]D Finanzen'!$B$45:$B$115,F$5,'[D Finanzen.xlsx]D Finanzen'!$C$45:$C$115,30))) | G10: =IF(COUNTIFS('[Import Monatsdaten.xlsx]Import Monatsdaten'!$C$7:$C$8,'[Steuerung.xlsx]Steuerung'!$F$6,'[Import Monatsdaten.xlsx]Import Monatsdaten'!$D$7:$D$8,2)>0,SUMIFS('[Import Monatsdaten.xlsx]Import Monatsdaten'!$G$7:$G$8,'[Import Monatsdaten.xlsx]Import Monatsdaten'!$C$7:$C$8,'[Steuerung.xlsx]Steuerung'!$F$6,'[Import Monatsdaten.xlsx]Import Monatsdaten'!$D$7:$D$8,2),IF(COUNTIFS('[D Finanzen.xlsx]D Finanzen'!$A$45:$A$115,'[Steuerung.xlsx]Steuerung'!$F$6,'[D Finanzen.xlsx]D Finanzen'!$B$45:$B$115,G$5)=0,"",SUMIFS('[D Finanzen.xlsx]D Finanzen'!$E$45:$E$115,'[D Finanzen.xlsx]D Finanzen'!$A$45:$A$115,'[Steuerung.xlsx]Steuerung'!$F$6,'[D Finanzen.xlsx]D Finanzen'!$B$45:$B$115,G$5,'[D Finanzen.xlsx]D Finanzen'!$C$45:$C$115,30))) | H10: =IF(COUNTIFS('[Import Monatsdaten.xlsx]Import Monatsdaten'!$C$7:$C$8,'[Steuerung.xlsx]Steuerung'!$F$6,'[Import Monatsdaten.xlsx]Import Monatsdaten'!$D$7:$D$8,3)>0,SUMIFS('[Import Monatsdaten.xlsx]Import Monatsdaten'!$G$7:$G$8,'[Import Monatsdaten.xlsx]Import Monatsdaten'!$C$7:$C$8,'[Steuerung.xlsx]Steuerung'!$F$6,'[Import Monatsdaten.xlsx]Import Monatsdaten'!$D$7:$D$8,3),IF(COUNTIFS('[D Finanzen.xlsx]D Finanzen'!$A$45:$A$115,'[Steuerung.xlsx]Steuerung'!$F$6,'[D Finanzen.xlsx]D Finanzen'!$B$45:$B$115,H$5)=0,"",SUMIFS('[D Finanzen.xlsx]D Finanzen'!$E$45:$E$115,'[D Finanzen.xlsx]D Finanzen'!$A$45:$A$115,'[Steuerung.xlsx]Steuerung'!$F$6,'[D Finanzen.xlsx]D Finanzen'!$B$45:$B$115,H$5,'[D Finanzen.xlsx]D Finanzen'!$C$45:$C$115,30))) | I10: =IF(COUNTIFS('[Import Monatsdaten.xlsx]Import Monatsdaten'!$C$7:$C$8,'[Steuerung.xlsx]Steuerung'!$F$6,'[Import Monatsdaten.xlsx]Import Monatsdaten'!$D$7:$D$8,4)>0,SUMIFS('[Import Monatsdaten.xlsx]Import Monatsdaten'!$G$7:$G$8,'[Import Monatsdaten.xlsx]Import Monatsdaten'!$C$7:$C$8,'[Steuerung.xlsx]Steuerung'!$F$6,'[Import Monatsdaten.xlsx]Import Monatsdaten'!$D$7:$D$8,4),IF(COUNTIFS('[D Finanzen.xlsx]D Finanzen'!$A$45:$A$115,'[Steuerung.xlsx]Steuerung'!$F$6,'[D Finanzen.xlsx]D Finanzen'!$B$45:$B$115,I$5)=0,"",SUMIFS('[D Finanzen.xlsx]D Finanzen'!$E$45:$E$115,'[D Finanzen.xlsx]D Finanzen'!$A$45:$A$115,'[Steuerung.xlsx]Steuerung'!$F$6,'[D Finanzen.xlsx]D Finanzen'!$B$45:$B$115,I$5,'[D Finanzen.xlsx]D Finanzen'!$C$45:$C$115,30))) | J10: =IF(COUNTIFS('[Import Monatsdaten.xlsx]Import Monatsdaten'!$C$7:$C$8,'[Steuerung.xlsx]Steuerung'!$F$6,'[Import Monatsdaten.xlsx]Import Monatsdaten'!$D$7:$D$8,5)>0,SUMIFS('[Import Monatsdaten.xlsx]Import Monatsdaten'!$G$7:$G$8,'[Import Monatsdaten.xlsx]Import Monatsdaten'!$C$7:$C$8,'[Steuerung.xlsx]Steuerung'!$F$6,'[Import Monatsdaten.xlsx]Import Monatsdaten'!$D$7:$D$8,5),IF(COUNTIFS('[D Finanzen.xlsx]D Finanzen'!$A$45:$A$115,'[Steuerung.xlsx]Steuerung'!$F$6,'[D Finanzen.xlsx]D Finanzen'!$B$45:$B$115,J$5)=0,"",SUMIFS('[D Finanzen.xlsx]D Finanzen'!$E$45:$E$115,'[D Finanzen.xlsx]D Finanzen'!$A$45:$A$115,'[Steuerung.xlsx]Steuerung'!$F$6,'[D Finanzen.xlsx]D Finanzen'!$B$45:$B$115,J$5,'[D Finanzen.xlsx]D Finanzen'!$C$45:$C$115,30))) | K10: =IF(COUNTIFS('[Import Monatsdaten.xlsx]Import Monatsdaten'!$C$7:$C$8,'[Steuerung.xlsx]Steuerung'!$F$6,'[Import Monatsdaten.xlsx]Import Monatsdaten'!$D$7:$D$8,6)>0,SUMIFS('[Import Monatsdaten.xlsx]Import Monatsdaten'!$G$7:$G$8,'[Import Monatsdaten.xlsx]Import Monatsdaten'!$C$7:$C$8,'[Steuerung.xlsx]Steuerung'!$F$6,'[Import Monatsdaten.xlsx]Import Monatsdaten'!$D$7:$D$8,6),IF(COUNTIFS('[D Finanzen.xlsx]D Finanzen'!$A$45:$A$115,'[Steuerung.xlsx]Steuerung'!$F$6,'[D Finanzen.xlsx]D Finanzen'!$B$45:$B$115,K$5)=0,"",SUMIFS('[D Finanzen.xlsx]D Finanzen'!$E$45:$E$115,'[D Finanzen.xlsx]D Finanzen'!$A$45:$A$115,'[Steuerung.xlsx]Steuerung'!$F$6,'[D Finanzen.xlsx]D Finanzen'!$B$45:$B$115,K$5,'[D Finanzen.xlsx]D Finanzen'!$C$45:$C$115,30))) | L10: =IF(COUNTIFS('[Import Monatsdaten.xlsx]Import Monatsdaten'!$C$7:$C$8,'[Steuerung.xlsx]Steuerung'!$F$6,'[Import Monatsdaten.xlsx]Import Monatsdaten'!$D$7:$D$8,7)>0,SUMIFS('[Import Monatsdaten.xlsx]Import Monatsdaten'!$G$7:$G$8,'[Import Monatsdaten.xlsx]Import Monatsdaten'!$C$7:$C$8,'[Steuerung.xlsx]Steuerung'!$F$6,'[Import Monatsdaten.xlsx]Import Monatsdaten'!$D$7:$D$8,7),IF(COUNTIFS('[D Finanzen.xlsx]D Finanzen'!$A$45:$A$115,'[Steuerung.xlsx]Steuerung'!$F$6,'[D Finanzen.xlsx]D Finanzen'!$B$45:$B$115,L$5)=0,"",SUMIFS('[D Finanzen.xlsx]D Finanzen'!$E$45:$E$115,'[D Finanzen.xlsx]D Finanzen'!$A$45:$A$115,'[Steuerung.xlsx]Steuerung'!$F$6,'[D Finanzen.xlsx]D Finanzen'!$B$45:$B$115,L$5,'[D Finanzen.xlsx]D Finanzen'!$C$45:$C$115,30))) | M10: =IF(COUNTIFS('[Import Monatsdaten.xlsx]Import Monatsdaten'!$C$7:$C$8,'[Steuerung.xlsx]Steuerung'!$F$6,'[Import Monatsdaten.xlsx]Import Monatsdaten'!$D$7:$D$8,8)>0,SUMIFS('[Import Monatsdaten.xlsx]Import Monatsdaten'!$G$7:$G$8,'[Import Monatsdaten.xlsx]Import Monatsdaten'!$C$7:$C$8,'[Steuerung.xlsx]Steuerung'!$F$6,'[Import Monatsdaten.xlsx]Import Monatsdaten'!$D$7:$D$8,8),IF(COUNTIFS('[D Finanzen.xlsx]D Finanzen'!$A$45:$A$115,'[Steuerung.xlsx]Steuerung'!$F$6,'[D Finanzen.xlsx]D Finanzen'!$B$45:$B$115,M$5)=0,"",SUMIFS('[D Finanzen.xlsx]D Finanzen'!$E$45:$E$115,'[D Finanzen.xlsx]D Finanzen'!$A$45:$A$115,'[Steuerung.xlsx]Steuerung'!$F$6,'[D Finanzen.xlsx]D Finanzen'!$B$45:$B$115,M$5,'[D Finanzen.xlsx]D Finanzen'!$C$45:$C$115,30))) | N10: =IF(COUNTIFS('[Import Monatsdaten.xlsx]Import Monatsdaten'!$C$7:$C$8,'[Steuerung.xlsx]Steuerung'!$F$6,'[Import Monatsdaten.xlsx]Import Monatsdaten'!$D$7:$D$8,9)>0,SUMIFS('[Import Monatsdaten.xlsx]Import Monatsdaten'!$G$7:$G$8,'[Import Monatsdaten.xlsx]Import Monatsdaten'!$C$7:$C$8,'[Steuerung.xlsx]Steuerung'!$F$6,'[Import Monatsdaten.xlsx]Import Monatsdaten'!$D$7:$D$8,9),IF(COUNTIFS('[D Finanzen.xlsx]D Finanzen'!$A$45:$A$115,'[Steuerung.xlsx]Steuerung'!$F$6,'[D Finanzen.xlsx]D Finanzen'!$B$45:$B$115,N$5)=0,"",SUMIFS('[D Finanzen.xlsx]D Finanzen'!$E$45:$E$115,'[D Finanzen.xlsx]D Finanzen'!$A$45:$A$115,'[Steuerung.xlsx]Steuerung'!$F$6,'[D Finanzen.xlsx]D Finanzen'!$B$45:$B$115,N$5,'[D Finanzen.xlsx]D Finanzen'!$C$45:$C$115,30))) | O10: =IF(COUNTIFS('[Import Monatsdaten.xlsx]Import Monatsdaten'!$C$7:$C$8,'[Steuerung.xlsx]Steuerung'!$F$6,'[Import Monatsdaten.xlsx]Import Monatsdaten'!$D$7:$D$8,10)>0,SUMIFS('[Import Monatsdaten.xlsx]Import Monatsdaten'!$G$7:$G$8,'[Import Monatsdaten.xlsx]Import Monatsdaten'!$C$7:$C$8,'[Steuerung.xlsx]Steuerung'!$F$6,'[Import Monatsdaten.xlsx]Import Monatsdaten'!$D$7:$D$8,10),IF(COUNTIFS('[D Finanzen.xlsx]D Finanzen'!$A$45:$A$115,'[Steuerung.xlsx]Steuerung'!$F$6,'[D Finanzen.xlsx]D Finanzen'!$B$45:$B$115,O$5)=0,"",SUMIFS('[D Finanzen.xlsx]D Finanzen'!$E$45:$E$115,'[D Finanzen.xlsx]D Finanzen'!$A$45:$A$115,'[Steuerung.xlsx]Steuerung'!$F$6,'[D Finanzen.xlsx]D Finanzen'!$B$45:$B$115,O$5,'[D Finanzen.xlsx]D Finanzen'!$C$45:$C$115,30))) | P10: =IF(COUNTIFS('[Import Monatsdaten.xlsx]Import Monatsdaten'!$C$7:$C$8,'[Steuerung.xlsx]Steuerung'!$F$6,'[Import Monatsdaten.xlsx]Import Monatsdaten'!$D$7:$D$8,11)>0,SUMIFS('[Import Monatsdaten.xlsx]Import Monatsdaten'!$G$7:$G$8,'[Import Monatsdaten.xlsx]Import Monatsdaten'!$C$7:$C$8,'[Steuerung.xlsx]Steuerung'!$F$6,'[Import Monatsdaten.xlsx]Import Monatsdaten'!$D$7:$D$8,11),IF(COUNTIFS('[D Finanzen.xlsx]D Finanzen'!$A$45:$A$115,'[Steuerung.xlsx]Steuerung'!$F$6,'[D Finanzen.xlsx]D Finanzen'!$B$45:$B$115,P$5)=0,"",SUMIFS('[D Finanzen.xlsx]D Finanzen'!$E$45:$E$115,'[D Finanzen.xlsx]D Finanzen'!$A$45:$A$115,'[Steuerung.xlsx]Steuerung'!$F$6,'[D Finanzen.xlsx]D Finanzen'!$B$45:$B$115,P$5,'[D Finanzen.xlsx]D Finanzen'!$C$45:$C$115,30))) | Q10: =IF(COUNTIFS('[Import Monatsdaten.xlsx]Import Monatsdaten'!$C$7:$C$8,'[Steuerung.xlsx]Steuerung'!$F$6,'[Import Monatsdaten.xlsx]Import Monatsdaten'!$D$7:$D$8,12)>0,SUMIFS('[Import Monatsdaten.xlsx]Import Monatsdaten'!$G$7:$G$8,'[Import Monatsdaten.xlsx]Import Monatsdaten'!$C$7:$C$8,'[Steuerung.xlsx]Steuerung'!$F$6,'[Import Monatsdaten.xlsx]Import Monatsdaten'!$D$7:$D$8,12),IF(COUNTIFS('[D Finanzen.xlsx]D Finanzen'!$A$45:$A$115,'[Steuerung.xlsx]Steuerung'!$F$6,'[D Finanzen.xlsx]D Finanzen'!$B$45:$B$115,Q$5)=0,"",SUMIFS('[D Finanzen.xlsx]D Finanzen'!$E$45:$E$115,'[D Finanzen.xlsx]D Finanzen'!$A$45:$A$115,'[Steuerung.xlsx]Steuerung'!$F$6,'[D Finanzen.xlsx]D Finanzen'!$B$45:$B$115,Q$5,'[D Finanzen.xlsx]D Finanzen'!$C$45:$C$115,30)))
C11: Materialaufwand | D11: =SUMIFS(F11:Q11,$F$5:$Q$5,"<="&'[Steuerung.xlsx]Steuerung'!$F$7) | E11: =IF($D$9=0,"n.a.",D11/$D$9) | F11: =IF(COUNTIFS('[Import Monatsdaten.xlsx]Import Monatsdaten'!$C$7:$C$8,'[Steuerung.xlsx]Steuerung'!$F$6,'[Import Monatsdaten.xlsx]Import Monatsdaten'!$D$7:$D$8,1)>0,SUMIFS('[Import Monatsdaten.xlsx]Import Monatsdaten'!$H$7:$H$8,'[Import Monatsdaten.xlsx]Import Monatsdaten'!$C$7:$C$8,'[Steuerung.xlsx]Steuerung'!$F$6,'[Import Monatsdaten.xlsx]Import Monatsdaten'!$D$7:$D$8,1),IF(COUNTIFS('[D Finanzen.xlsx]D Finanzen'!$A$45:$A$115,'[Steuerung.xlsx]Steuerung'!$F$6,'[D Finanzen.xlsx]D Finanzen'!$B$45:$B$115,F$5)=0,"",SUMIFS('[D Finanzen.xlsx]D Finanzen'!$E$45:$E$115,'[D Finanzen.xlsx]D Finanzen'!$A$45:$A$115,'[Steuerung.xlsx]Steuerung'!$F$6,'[D Finanzen.xlsx]D Finanzen'!$B$45:$B$115,F$5,'[D Finanzen.xlsx]D Finanzen'!$C$45:$C$115,40))) | G11: =IF(COUNTIFS('[Import Monatsdaten.xlsx]Import Monatsdaten'!$C$7:$C$8,'[Steuerung.xlsx]Steuerung'!$F$6,'[Import Monatsdaten.xlsx]Import Monatsdaten'!$D$7:$D$8,2)>0,SUMIFS('[Import Monatsdaten.xlsx]Import Monatsdaten'!$H$7:$H$8,'[Import Monatsdaten.xlsx]Import Monatsdaten'!$C$7:$C$8,'[Steuerung.xlsx]Steuerung'!$F$6,'[Import Monatsdaten.xlsx]Import Monatsdaten'!$D$7:$D$8,2),IF(COUNTIFS('[D Finanzen.xlsx]D Finanzen'!$A$45:$A$115,'[Steuerung.xlsx]Steuerung'!$F$6,'[D Finanzen.xlsx]D Finanzen'!$B$45:$B$115,G$5)=0,"",SUMIFS('[D Finanzen.xlsx]D Finanzen'!$E$45:$E$115,'[D Finanzen.xlsx]D Finanzen'!$A$45:$A$115,'[Steuerung.xlsx]Steuerung'!$F$6,'[D Finanzen.xlsx]D Finanzen'!$B$45:$B$115,G$5,'[D Finanzen.xlsx]D Finanzen'!$C$45:$C$115,40))) | H11: =IF(COUNTIFS('[Import Monatsdaten.xlsx]Import Monatsdaten'!$C$7:$C$8,'[Steuerung.xlsx]Steuerung'!$F$6,'[Import Monatsdaten.xlsx]Import Monatsdaten'!$D$7:$D$8,3)>0,SUMIFS('[Import Monatsdaten.xlsx]Import Monatsdaten'!$H$7:$H$8,'[Import Monatsdaten.xlsx]Import Monatsdaten'!$C$7:$C$8,'[Steuerung.xlsx]Steuerung'!$F$6,'[Import Monatsdaten.xlsx]Import Monatsdaten'!$D$7:$D$8,3),IF(COUNTIFS('[D Finanzen.xlsx]D Finanzen'!$A$45:$A$115,'[Steuerung.xlsx]Steuerung'!$F$6,'[D Finanzen.xlsx]D Finanzen'!$B$45:$B$115,H$5)=0,"",SUMIFS('[D Finanzen.xlsx]D Finanzen'!$E$45:$E$115,'[D Finanzen.xlsx]D Finanzen'!$A$45:$A$115,'[Steuerung.xlsx]Steuerung'!$F$6,'[D Finanzen.xlsx]D Finanzen'!$B$45:$B$115,H$5,'[D Finanzen.xlsx]D Finanzen'!$C$45:$C$115,40))) | I11: =IF(COUNTIFS('[Import Monatsdaten.xlsx]Import Monatsdaten'!$C$7:$C$8,'[Steuerung.xlsx]Steuerung'!$F$6,'[Import Monatsdaten.xlsx]Import Monatsdaten'!$D$7:$D$8,4)>0,SUMIFS('[Import Monatsdaten.xlsx]Import Monatsdaten'!$H$7:$H$8,'[Import Monatsdaten.xlsx]Import Monatsdaten'!$C$7:$C$8,'[Steuerung.xlsx]Steuerung'!$F$6,'[Import Monatsdaten.xlsx]Import Monatsdaten'!$D$7:$D$8,4),IF(COUNTIFS('[D Finanzen.xlsx]D Finanzen'!$A$45:$A$115,'[Steuerung.xlsx]Steuerung'!$F$6,'[D Finanzen.xlsx]D Finanzen'!$B$45:$B$115,I$5)=0,"",SUMIFS('[D Finanzen.xlsx]D Finanzen'!$E$45:$E$115,'[D Finanzen.xlsx]D Finanzen'!$A$45:$A$115,'[Steuerung.xlsx]Steuerung'!$F$6,'[D Finanzen.xlsx]D Finanzen'!$B$45:$B$115,I$5,'[D Finanzen.xlsx]D Finanzen'!$C$45:$C$115,40))) | J11: =IF(COUNTIFS('[Import Monatsdaten.xlsx]Import Monatsdaten'!$C$7:$C$8,'[Steuerung.xlsx]Steuerung'!$F$6,'[Import Monatsdaten.xlsx]Import Monatsdaten'!$D$7:$D$8,5)>0,SUMIFS('[Import Monatsdaten.xlsx]Import Monatsdaten'!$H$7:$H$8,'[Import Monatsdaten.xlsx]Import Monatsdaten'!$C$7:$C$8,'[Steuerung.xlsx]Steuerung'!$F$6,'[Import Monatsdaten.xlsx]Import Monatsdaten'!$D$7:$D$8,5),IF(COUNTIFS('[D Finanzen.xlsx]D Finanzen'!$A$45:$A$115,'[Steuerung.xlsx]Steuerung'!$F$6,'[D Finanzen.xlsx]D Finanzen'!$B$45:$B$115,J$5)=0,"",SUMIFS('[D Finanzen.xlsx]D Finanzen'!$E$45:$E$115,'[D Finanzen.xlsx]D Finanzen'!$A$45:$A$115,'[Steuerung.xlsx]Steuerung'!$F$6,'[D Finanzen.xlsx]D Finanzen'!$B$45:$B$115,J$5,'[D Finanzen.xlsx]D Finanzen'!$C$45:$C$115,40))) | K11: =IF(COUNTIFS('[Import Monatsdaten.xlsx]Import Monatsdaten'!$C$7:$C$8,'[Steuerung.xlsx]Steuerung'!$F$6,'[Import Monatsdaten.xlsx]Import Monatsdaten'!$D$7:$D$8,6)>0,SUMIFS('[Import Monatsdaten.xlsx]Import Monatsdaten'!$H$7:$H$8,'[Import Monatsdaten.xlsx]Import Monatsdaten'!$C$7:$C$8,'[Steuerung.xlsx]Steuerung'!$F$6,'[Import Monatsdaten.xlsx]Import Monatsdaten'!$D$7:$D$8,6),IF(COUNTIFS('[D Finanzen.xlsx]D Finanzen'!$A$45:$A$115,'[Steuerung.xlsx]Steuerung'!$F$6,'[D Finanzen.xlsx]D Finanzen'!$B$45:$B$115,K$5)=0,"",SUMIFS('[D Finanzen.xlsx]D Finanzen'!$E$45:$E$115,'[D Finanzen.xlsx]D Finanzen'!$A$45:$A$115,'[Steuerung.xlsx]Steuerung'!$F$6,'[D Finanzen.xlsx]D Finanzen'!$B$45:$B$115,K$5,'[D Finanzen.xlsx]D Finanzen'!$C$45:$C$115,40))) | L11: =IF(COUNTIFS('[Import Monatsdaten.xlsx]Import Monatsdaten'!$C$7:$C$8,'[Steuerung.xlsx]Steuerung'!$F$6,'[Import Monatsdaten.xlsx]Import Monatsdaten'!$D$7:$D$8,7)>0,SUMIFS('[Import Monatsdaten.xlsx]Import Monatsdaten'!$H$7:$H$8,'[Import Monatsdaten.xlsx]Import Monatsdaten'!$C$7:$C$8,'[Steuerung.xlsx]Steuerung'!$F$6,'[Import Monatsdaten.xlsx]Import Monatsdaten'!$D$7:$D$8,7),IF(COUNTIFS('[D Finanzen.xlsx]D Finanzen'!$A$45:$A$115,'[Steuerung.xlsx]Steuerung'!$F$6,'[D Finanzen.xlsx]D Finanzen'!$B$45:$B$115,L$5)=0,"",SUMIFS('[D Finanzen.xlsx]D Finanzen'!$E$45:$E$115,'[D Finanzen.xlsx]D Finanzen'!$A$45:$A$115,'[Steuerung.xlsx]Steuerung'!$F$6,'[D Finanzen.xlsx]D Finanzen'!$B$45:$B$115,L$5,'[D Finanzen.xlsx]D Finanzen'!$C$45:$C$115,40))) | M11: =IF(COUNTIFS('[Import Monatsdaten.xlsx]Import Monatsdaten'!$C$7:$C$8,'[Steuerung.xlsx]Steuerung'!$F$6,'[Import Monatsdaten.xlsx]Import Monatsdaten'!$D$7:$D$8,8)>0,SUMIFS('[Import Monatsdaten.xlsx]Import Monatsdaten'!$H$7:$H$8,'[Import Monatsdaten.xlsx]Import Monatsdaten'!$C$7:$C$8,'[Steuerung.xlsx]Steuerung'!$F$6,'[Import Monatsdaten.xlsx]Import Monatsdaten'!$D$7:$D$8,8),IF(COUNTIFS('[D Finanzen.xlsx]D Finanzen'!$A$45:$A$115,'[Steuerung.xlsx]Steuerung'!$F$6,'[D Finanzen.xlsx]D Finanzen'!$B$45:$B$115,M$5)=0,"",SUMIFS('[D Finanzen.xlsx]D Finanzen'!$E$45:$E$115,'[D Finanzen.xlsx]D Finanzen'!$A$45:$A$115,'[Steuerung.xlsx]Steuerung'!$F$6,'[D Finanzen.xlsx]D Finanzen'!$B$45:$B$115,M$5,'[D Finanzen.xlsx]D Finanzen'!$C$45:$C$115,40))) | N11: =IF(COUNTIFS('[Import Monatsdaten.xlsx]Import Monatsdaten'!$C$7:$C$8,'[Steuerung.xlsx]Steuerung'!$F$6,'[Import Monatsdaten.xlsx]Import Monatsdaten'!$D$7:$D$8,9)>0,SUMIFS('[Import Monatsdaten.xlsx]Import Monatsdaten'!$H$7:$H$8,'[Import Monatsdaten.xlsx]Import Monatsdaten'!$C$7:$C$8,'[Steuerung.xlsx]Steuerung'!$F$6,'[Import Monatsdaten.xlsx]Import Monatsdaten'!$D$7:$D$8,9),IF(COUNTIFS('[D Finanzen.xlsx]D Finanzen'!$A$45:$A$115,'[Steuerung.xlsx]Steuerung'!$F$6,'[D Finanzen.xlsx]D Finanzen'!$B$45:$B$115,N$5)=0,"",SUMIFS('[D Finanzen.xlsx]D Finanzen'!$E$45:$E$115,'[D Finanzen.xlsx]D Finanzen'!$A$45:$A$115,'[Steuerung.xlsx]Steuerung'!$F$6,'[D Finanzen.xlsx]D Finanzen'!$B$45:$B$115,N$5,'[D Finanzen.xlsx]D Finanzen'!$C$45:$C$115,40))) | O11: =IF(COUNTIFS('[Import Monatsdaten.xlsx]Import Monatsdaten'!$C$7:$C$8,'[Steuerung.xlsx]Steuerung'!$F$6,'[Import Monatsdaten.xlsx]Import Monatsdaten'!$D$7:$D$8,10)>0,SUMIFS('[Import Monatsdaten.xlsx]Import Monatsdaten'!$H$7:$H$8,'[Import Monatsdaten.xlsx]Import Monatsdaten'!$C$7:$C$8,'[Steuerung.xlsx]Steuerung'!$F$6,'[Import Monatsdaten.xlsx]Import Monatsdaten'!$D$7:$D$8,10),IF(COUNTIFS('[D Finanzen.xlsx]D Finanzen'!$A$45:$A$115,'[Steuerung.xlsx]Steuerung'!$F$6,'[D Finanzen.xlsx]D Finanzen'!$B$45:$B$115,O$5)=0,"",SUMIFS('[D Finanzen.xlsx]D Finanzen'!$E$45:$E$115,'[D Finanzen.xlsx]D Finanzen'!$A$45:$A$115,'[Steuerung.xlsx]Steuerung'!$F$6,'[D Finanzen.xlsx]D Finanzen'!$B$45:$B$115,O$5,'[D Finanzen.xlsx]D Finanzen'!$C$45:$C$115,40))) | P11: =IF(COUNTIFS('[Import Monatsdaten.xlsx]Import Monatsdaten'!$C$7:$C$8,'[Steuerung.xlsx]Steuerung'!$F$6,'[Import Monatsdaten.xlsx]Import Monatsdaten'!$D$7:$D$8,11)>0,SUMIFS('[Import Monatsdaten.xlsx]Import Monatsdaten'!$H$7:$H$8,'[Import Monatsdaten.xlsx]Import Monatsdaten'!$C$7:$C$8,'[Steuerung.xlsx]Steuerung'!$F$6,'[Import Monatsdaten.xlsx]Import Monatsdaten'!$D$7:$D$8,11),IF(COUNTIFS('[D Finanzen.xlsx]D Finanzen'!$A$45:$A$115,'[Steuerung.xlsx]Steuerung'!$F$6,'[D Finanzen.xlsx]D Finanzen'!$B$45:$B$115,P$5)=0,"",SUMIFS('[D Finanzen.xlsx]D Finanzen'!$E$45:$E$115,'[D Finanzen.xlsx]D Finanzen'!$A$45:$A$115,'[Steuerung.xlsx]Steuerung'!$F$6,'[D Finanzen.xlsx]D Finanzen'!$B$45:$B$115,P$5,'[D Finanzen.xlsx]D Finanzen'!$C$45:$C$115,40))) | Q11: =IF(COUNTIFS('[Import Monatsdaten.xlsx]Import Monatsdaten'!$C$7:$C$8,'[Steuerung.xlsx]Steuerung'!$F$6,'[Import Monatsdaten.xlsx]Import Monatsdaten'!$D$7:$D$8,12)>0,SUMIFS('[Import Monatsdaten.xlsx]Import Monatsdaten'!$H$7:$H$8,'[Import Monatsdaten.xlsx]Import Monatsdaten'!$C$7:$C$8,'[Steuerung.xlsx]Steuerung'!$F$6,'[Import Monatsdaten.xlsx]Import Monatsdaten'!$D$7:$D$8,12),IF(COUNTIFS('[D Finanzen.xlsx]D Finanzen'!$A$45:$A$115,'[Steuerung.xlsx]Steuerung'!$F$6,'[D Finanzen.xlsx]D Finanzen'!$B$45:$B$115,Q$5)=0,"",SUMIFS('[D Finanzen.xlsx]D Finanzen'!$E$45:$E$115,'[D Finanzen.xlsx]D Finanzen'!$A$45:$A$115,'[Steuerung.xlsx]Steuerung'!$F$6,'[D Finanzen.xlsx]D Finanzen'!$B$45:$B$115,Q$5,'[D Finanzen.xlsx]D Finanzen'!$C$45:$C$115,40)))
C12: Personalaufwand | D12: =SUMIFS(F12:Q12,$F$5:$Q$5,"<="&'[Steuerung.xlsx]Steuerung'!$F$7) | E12: =IF($D$9=0,"n.a.",D12/$D$9) | F12: =IF(COUNTIFS('[Import Monatsdaten.xlsx]Import Monatsdaten'!$C$7:$C$8,'[Steuerung.xlsx]Steuerung'!$F$6,'[Import Monatsdaten.xlsx]Import Monatsdaten'!$D$7:$D$8,1)>0,SUMIFS('[Import Monatsdaten.xlsx]Import Monatsdaten'!$I$7:$I$8,'[Import Monatsdaten.xlsx]Import Monatsdaten'!$C$7:$C$8,'[Steuerung.xlsx]Steuerung'!$F$6,'[Import Monatsdaten.xlsx]Import Monatsdaten'!$D$7:$D$8,1),IF(COUNTIFS('[D Finanzen.xlsx]D Finanzen'!$A$45:$A$115,'[Steuerung.xlsx]Steuerung'!$F$6,'[D Finanzen.xlsx]D Finanzen'!$B$45:$B$115,F$5)=0,"",SUMIFS('[D Finanzen.xlsx]D Finanzen'!$E$45:$E$115,'[D Finanzen.xlsx]D Finanzen'!$A$45:$A$115,'[Steuerung.xlsx]Steuerung'!$F$6,'[D Finanzen.xlsx]D Finanzen'!$B$45:$B$115,F$5,'[D Finanzen.xlsx]D Finanzen'!$C$45:$C$115,50))) | G12: =IF(COUNTIFS('[Import Monatsdaten.xlsx]Import Monatsdaten'!$C$7:$C$8,'[Steuerung.xlsx]Steuerung'!$F$6,'[Import Monatsdaten.xlsx]Import Monatsdaten'!$D$7:$D$8,2)>0,SUMIFS('[Import Monatsdaten.xlsx]Import Monatsdaten'!$I$7:$I$8,'[Import Monatsdaten.xlsx]Import Monatsdaten'!$C$7:$C$8,'[Steuerung.xlsx]Steuerung'!$F$6,'[Import Monatsdaten.xlsx]Import Monatsdaten'!$D$7:$D$8,2),IF(COUNTIFS('[D Finanzen.xlsx]D Finanzen'!$A$45:$A$115,'[Steuerung.xlsx]Steuerung'!$F$6,'[D Finanzen.xlsx]D Finanzen'!$B$45:$B$115,G$5)=0,"",SUMIFS('[D Finanzen.xlsx]D Finanzen'!$E$45:$E$115,'[D Finanzen.xlsx]D Finanzen'!$A$45:$A$115,'[Steuerung.xlsx]Steuerung'!$F$6,'[D Finanzen.xlsx]D Finanzen'!$B$45:$B$115,G$5,'[D Finanzen.xlsx]D Finanzen'!$C$45:$C$115,50))) | H12: =IF(COUNTIFS('[Import Monatsdaten.xlsx]Import Monatsdaten'!$C$7:$C$8,'[Steuerung.xlsx]Steuerung'!$F$6,'[Import Monatsdaten.xlsx]Import Monatsdaten'!$D$7:$D$8,3)>0,SUMIFS('[Import Monatsdaten.xlsx]Import Monatsdaten'!$I$7:$I$8,'[Import Monatsdaten.xlsx]Import Monatsdaten'!$C$7:$C$8,'[Steuerung.xlsx]Steuerung'!$F$6,'[Import Monatsdaten.xlsx]Import Monatsdaten'!$D$7:$D$8,3),IF(COUNTIFS('[D Finanzen.xlsx]D Finanzen'!$A$45:$A$115,'[Steuerung.xlsx]Steuerung'!$F$6,'[D Finanzen.xlsx]D Finanzen'!$B$45:$B$115,H$5)=0,"",SUMIFS('[D Finanzen.xlsx]D Finanzen'!$E$45:$E$115,'[D Finanzen.xlsx]D Finanzen'!$A$45:$A$115,'[Steuerung.xlsx]Steuerung'!$F$6,'[D Finanzen.xlsx]D Finanzen'!$B$45:$B$115,H$5,'[D Finanzen.xlsx]D Finanzen'!$C$45:$C$115,50))) | I12: =IF(COUNTIFS('[Import Monatsdaten.xlsx]Import Monatsdaten'!$C$7:$C$8,'[Steuerung.xlsx]Steuerung'!$F$6,'[Import Monatsdaten.xlsx]Import Monatsdaten'!$D$7:$D$8,4)>0,SUMIFS('[Import Monatsdaten.xlsx]Import Monatsdaten'!$I$7:$I$8,'[Import Monatsdaten.xlsx]Import Monatsdaten'!$C$7:$C$8,'[Steuerung.xlsx]Steuerung'!$F$6,'[Import Monatsdaten.xlsx]Import Monatsdaten'!$D$7:$D$8,4),IF(COUNTIFS('[D Finanzen.xlsx]D Finanzen'!$A$45:$A$115,'[Steuerung.xlsx]Steuerung'!$F$6,'[D Finanzen.xlsx]D Finanzen'!$B$45:$B$115,I$5)=0,"",SUMIFS('[D Finanzen.xlsx]D Finanzen'!$E$45:$E$115,'[D Finanzen.xlsx]D Finanzen'!$A$45:$A$115,'[Steuerung.xlsx]Steuerung'!$F$6,'[D Finanzen.xlsx]D Finanzen'!$B$45:$B$115,I$5,'[D Finanzen.xlsx]D Finanzen'!$C$45:$C$115,50))) | J12: =IF(COUNTIFS('[Import Monatsdaten.xlsx]Import Monatsdaten'!$C$7:$C$8,'[Steuerung.xlsx]Steuerung'!$F$6,'[Import Monatsdaten.xlsx]Import Monatsdaten'!$D$7:$D$8,5)>0,SUMIFS('[Import Monatsdaten.xlsx]Import Monatsdaten'!$I$7:$I$8,'[Import Monatsdaten.xlsx]Import Monatsdaten'!$C$7:$C$8,'[Steuerung.xlsx]Steuerung'!$F$6,'[Import Monatsdaten.xlsx]Import Monatsdaten'!$D$7:$D$8,5),IF(COUNTIFS('[D Finanzen.xlsx]D Finanzen'!$A$45:$A$115,'[Steuerung.xlsx]Steuerung'!$F$6,'[D Finanzen.xlsx]D Finanzen'!$B$45:$B$115,J$5)=0,"",SUMIFS('[D Finanzen.xlsx]D Finanzen'!$E$45:$E$115,'[D Finanzen.xlsx]D Finanzen'!$A$45:$A$115,'[Steuerung.xlsx]Steuerung'!$F$6,'[D Finanzen.xlsx]D Finanzen'!$B$45:$B$115,J$5,'[D Finanzen.xlsx]D Finanzen'!$C$45:$C$115,50))) | K12: =IF(COUNTIFS('[Import Monatsdaten.xlsx]Import Monatsdaten'!$C$7:$C$8,'[Steuerung.xlsx]Steuerung'!$F$6,'[Import Monatsdaten.xlsx]Import Monatsdaten'!$D$7:$D$8,6)>0,SUMIFS('[Import Monatsdaten.xlsx]Import Monatsdaten'!$I$7:$I$8,'[Import Monatsdaten.xlsx]Import Monatsdaten'!$C$7:$C$8,'[Steuerung.xlsx]Steuerung'!$F$6,'[Import Monatsdaten.xlsx]Import Monatsdaten'!$D$7:$D$8,6),IF(COUNTIFS('[D Finanzen.xlsx]D Finanzen'!$A$45:$A$115,'[Steuerung.xlsx]Steuerung'!$F$6,'[D Finanzen.xlsx]D Finanzen'!$B$45:$B$115,K$5)=0,"",SUMIFS('[D Finanzen.xlsx]D Finanzen'!$E$45:$E$115,'[D Finanzen.xlsx]D Finanzen'!$A$45:$A$115,'[Steuerung.xlsx]Steuerung'!$F$6,'[D Finanzen.xlsx]D Finanzen'!$B$45:$B$115,K$5,'[D Finanzen.xlsx]D Finanzen'!$C$45:$C$115,50))) | L12: =IF(COUNTIFS('[Import Monatsdaten.xlsx]Import Monatsdaten'!$C$7:$C$8,'[Steuerung.xlsx]Steuerung'!$F$6,'[Import Monatsdaten.xlsx]Import Monatsdaten'!$D$7:$D$8,7)>0,SUMIFS('[Import Monatsdaten.xlsx]Import Monatsdaten'!$I$7:$I$8,'[Import Monatsdaten.xlsx]Import Monatsdaten'!$C$7:$C$8,'[Steuerung.xlsx]Steuerung'!$F$6,'[Import Monatsdaten.xlsx]Import Monatsdaten'!$D$7:$D$8,7),IF(COUNTIFS('[D Finanzen.xlsx]D Finanzen'!$A$45:$A$115,'[Steuerung.xlsx]Steuerung'!$F$6,'[D Finanzen.xlsx]D Finanzen'!$B$45:$B$115,L$5)=0,"",SUMIFS('[D Finanzen.xlsx]D Finanzen'!$E$45:$E$115,'[D Finanzen.xlsx]D Finanzen'!$A$45:$A$115,'[Steuerung.xlsx]Steuerung'!$F$6,'[D Finanzen.xlsx]D Finanzen'!$B$45:$B$115,L$5,'[D Finanzen.xlsx]D Finanzen'!$C$45:$C$115,50))) | M12: =IF(COUNTIFS('[Import Monatsdaten.xlsx]Import Monatsdaten'!$C$7:$C$8,'[Steuerung.xlsx]Steuerung'!$F$6,'[Import Monatsdaten.xlsx]Import Monatsdaten'!$D$7:$D$8,8)>0,SUMIFS('[Import Monatsdaten.xlsx]Import Monatsdaten'!$I$7:$I$8,'[Import Monatsdaten.xlsx]Import Monatsdaten'!$C$7:$C$8,'[Steuerung.xlsx]Steuerung'!$F$6,'[Import Monatsdaten.xlsx]Import Monatsdaten'!$D$7:$D$8,8),IF(COUNTIFS('[D Finanzen.xlsx]D Finanzen'!$A$45:$A$115,'[Steuerung.xlsx]Steuerung'!$F$6,'[D Finanzen.xlsx]D Finanzen'!$B$45:$B$115,M$5)=0,"",SUMIFS('[D Finanzen.xlsx]D Finanzen'!$E$45:$E$115,'[D Finanzen.xlsx]D Finanzen'!$A$45:$A$115,'[Steuerung.xlsx]Steuerung'!$F$6,'[D Finanzen.xlsx]D Finanzen'!$B$45:$B$115,M$5,'[D Finanzen.xlsx]D Finanzen'!$C$45:$C$115,50))) | N12: =IF(COUNTIFS('[Import Monatsdaten.xlsx]Import Monatsdaten'!$C$7:$C$8,'[Steuerung.xlsx]Steuerung'!$F$6,'[Import Monatsdaten.xlsx]Import Monatsdaten'!$D$7:$D$8,9)>0,SUMIFS('[Import Monatsdaten.xlsx]Import Monatsdaten'!$I$7:$I$8,'[Import Monatsdaten.xlsx]Import Monatsdaten'!$C$7:$C$8,'[Steuerung.xlsx]Steuerung'!$F$6,'[Import Monatsdaten.xlsx]Import Monatsdaten'!$D$7:$D$8,9),IF(COUNTIFS('[D Finanzen.xlsx]D Finanzen'!$A$45:$A$115,'[Steuerung.xlsx]Steuerung'!$F$6,'[D Finanzen.xlsx]D Finanzen'!$B$45:$B$115,N$5)=0,"",SUMIFS('[D Finanzen.xlsx]D Finanzen'!$E$45:$E$115,'[D Finanzen.xlsx]D Finanzen'!$A$45:$A$115,'[Steuerung.xlsx]Steuerung'!$F$6,'[D Finanzen.xlsx]D Finanzen'!$B$45:$B$115,N$5,'[D Finanzen.xlsx]D Finanzen'!$C$45:$C$115,50))) | O12: =IF(COUNTIFS('[Import Monatsdaten.xlsx]Import Monatsdaten'!$C$7:$C$8,'[Steuerung.xlsx]Steuerung'!$F$6,'[Import Monatsdaten.xlsx]Import Monatsdaten'!$D$7:$D$8,10)>0,SUMIFS('[Import Monatsdaten.xlsx]Import Monatsdaten'!$I$7:$I$8,'[Import Monatsdaten.xlsx]Import Monatsdaten'!$C$7:$C$8,'[Steuerung.xlsx]Steuerung'!$F$6,'[Import Monatsdaten.xlsx]Import Monatsdaten'!$D$7:$D$8,10),IF(COUNTIFS('[D Finanzen.xlsx]D Finanzen'!$A$45:$A$115,'[Steuerung.xlsx]Steuerung'!$F$6,'[D Finanzen.xlsx]D Finanzen'!$B$45:$B$115,O$5)=0,"",SUMIFS('[D Finanzen.xlsx]D Finanzen'!$E$45:$E$115,'[D Finanzen.xlsx]D Finanzen'!$A$45:$A$115,'[Steuerung.xlsx]Steuerung'!$F$6,'[D Finanzen.xlsx]D Finanzen'!$B$45:$B$115,O$5,'[D Finanzen.xlsx]D Finanzen'!$C$45:$C$115,50))) | P12: =IF(COUNTIFS('[Import Monatsdaten.xlsx]Import Monatsdaten'!$C$7:$C$8,'[Steuerung.xlsx]Steuerung'!$F$6,'[Import Monatsdaten.xlsx]Import Monatsdaten'!$D$7:$D$8,11)>0,SUMIFS('[Import Monatsdaten.xlsx]Import Monatsdaten'!$I$7:$I$8,'[Import Monatsdaten.xlsx]Import Monatsdaten'!$C$7:$C$8,'[Steuerung.xlsx]Steuerung'!$F$6,'[Import Monatsdaten.xlsx]Import Monatsdaten'!$D$7:$D$8,11),IF(COUNTIFS('[D Finanzen.xlsx]D Finanzen'!$A$45:$A$115,'[Steuerung.xlsx]Steuerung'!$F$6,'[D Finanzen.xlsx]D Finanzen'!$B$45:$B$115,P$5)=0,"",SUMIFS('[D Finanzen.xlsx]D Finanzen'!$E$45:$E$115,'[D Finanzen.xlsx]D Finanzen'!$A$45:$A$115,'[Steuerung.xlsx]Steuerung'!$F$6,'[D Finanzen.xlsx]D Finanzen'!$B$45:$B$115,P$5,'[D Finanzen.xlsx]D Finanzen'!$C$45:$C$115,50))) | Q12: =IF(COUNTIFS('[Import Monatsdaten.xlsx]Import Monatsdaten'!$C$7:$C$8,'[Steuerung.xlsx]Steuerung'!$F$6,'[Import Monatsdaten.xlsx]Import Monatsdaten'!$D$7:$D$8,12)>0,SUMIFS('[Import Monatsdaten.xlsx]Import Monatsdaten'!$I$7:$I$8,'[Import Monatsdaten.xlsx]Import Monatsdaten'!$C$7:$C$8,'[Steuerung.xlsx]Steuerung'!$F$6,'[Import Monatsdaten.xlsx]Import Monatsdaten'!$D$7:$D$8,12),IF(COUNTIFS('[D Finanzen.xlsx]D Finanzen'!$A$45:$A$115,'[Steuerung.xlsx]Steuerung'!$F$6,'[D Finanzen.xlsx]D Finanzen'!$B$45:$B$115,Q$5)=0,"",SUMIFS('[D Finanzen.xlsx]D Finanzen'!$E$45:$E$115,'[D Finanzen.xlsx]D Finanzen'!$A$45:$A$115,'[Steuerung.xlsx]Steuerung'!$F$6,'[D Finanzen.xlsx]D Finanzen'!$B$45:$B$115,Q$5,'[D Finanzen.xlsx]D Finanzen'!$C$45:$C$115,50)))
